<?xml version="1.0" encoding="UTF-8"?>
<!-- Generated by org.testng.reporters.JUnitXMLReporter -->
<testsuite hostname="BIL-PC" name="TestNG Functional Group" tests="166" failures="22" timestamp="31 May 2016 22:34:03 GMT" time="0.19" errors="0">
  <testcase name="testDivPassLong" time="0.001" classname="com.epam.calculator.testCalculator.baseOperations.TestDiv"/>
  <testcase name="testDivPassLong" time="0.002" classname="com.epam.calculator.testCalculator.baseOperations.TestDiv"/>
  <testcase name="testDivPassLong" time="0.002" classname="com.epam.calculator.testCalculator.baseOperations.TestDiv"/>
  <testcase name="testDivPassLong" time="0.002" classname="com.epam.calculator.testCalculator.baseOperations.TestDiv"/>
  <testcase name="testSumFailLong" time="0.002" classname="com.epam.calculator.testCalculator.baseOperations.TestSum"/>
  <testcase name="testIsPositiveFailLong" time="0.0" classname="com.epam.calculator.testCalculator.sign.TestIsPositive"/>
  <testcase name="testIsNegativePassLong" time="0.0" classname="com.epam.calculator.testCalculator.sign.TestIsNegative"/>
  <testcase name="testDivPassLong" time="0.0" classname="com.epam.calculator.testCalculator.baseOperations.TestDiv"/>
  <testcase name="testSumExceptionIsThrown" time="0.001" classname="com.epam.calculator.testCalculator.baseOperations.TestSum">
    <failure type="org.testng.TestException" message="
Expected exception java.lang.Exception but got org.testng.TestException: 
Method TestSum.testSumExceptionIsThrown(long, long)[pri:0, instance:com.epam.calculator.testCalculator.baseOperations.TestSum@50a6f6] should have thrown an exception of class java.lang.Exception">
      <![CDATA[org.testng.TestException: 
Method TestSum.testSumExceptionIsThrown(long, long)[pri:0, instance:com.epam.calculator.testCalculator.baseOperations.TestSum@50a6f6] should have thrown an exception of class java.lang.Exception
	at java.util.concurrent.FutureTask.run(FutureTask.java:266)
	at java.util.concurrent.Executors$RunnableAdapter.call(Executors.java:511)
	at java.util.concurrent.FutureTask.run(FutureTask.java:266)
	at java.util.concurrent.ThreadPoolExecutor.runWorker(ThreadPoolExecutor.java:1142)
	at java.util.concurrent.ThreadPoolExecutor$Worker.run(ThreadPoolExecutor.java:617)
	at java.lang.Thread.run(Thread.java:745)
Method TestSum.testSumExceptionIsThrown(long, long)[pri:0, instance:com.epam.calculator.testCalculator.baseOperations.TestSum@50a6f6] should have thrown an exception of class java.lang.Exception
	... 7 more
... Removed 9 stack frames]]>
    </failure>
  </testcase> <!-- testSumExceptionIsThrown -->
  <testcase name="testSumPassLong" time="0.0" classname="com.epam.calculator.testCalculator.baseOperations.TestSum"/>
  <testcase name="testMultFailLong" time="0.0" classname="com.epam.calculator.testCalculator.baseOperations.TestMult"/>
  <testcase name="testIsPositivePassLong" time="0.001" classname="com.epam.calculator.testCalculator.sign.TestIsPositive"/>
  <testcase name="testDivFailLong" time="0.0" classname="com.epam.calculator.testCalculator.baseOperations.TestDiv"/>
  <testcase name="testSubExceptionIsThrown" time="0.0" classname="com.epam.calculator.testCalculator.baseOperations.TestSub">
    <failure type="org.testng.TestException" message="
Expected exception java.lang.Exception but got org.testng.TestException: 
Method TestSub.testSubExceptionIsThrown(long, long)[pri:0, instance:com.epam.calculator.testCalculator.baseOperations.TestSub@2a67b4] should have thrown an exception of class java.lang.Exception">
      <![CDATA[org.testng.TestException: 
Method TestSub.testSubExceptionIsThrown(long, long)[pri:0, instance:com.epam.calculator.testCalculator.baseOperations.TestSub@2a67b4] should have thrown an exception of class java.lang.Exception
	at java.util.concurrent.FutureTask.run(FutureTask.java:266)
	at java.util.concurrent.Executors$RunnableAdapter.call(Executors.java:511)
	at java.util.concurrent.FutureTask.run(FutureTask.java:266)
	at java.util.concurrent.ThreadPoolExecutor.runWorker(ThreadPoolExecutor.java:1142)
	at java.util.concurrent.ThreadPoolExecutor$Worker.run(ThreadPoolExecutor.java:617)
	at java.lang.Thread.run(Thread.java:745)
Method TestSub.testSubExceptionIsThrown(long, long)[pri:0, instance:com.epam.calculator.testCalculator.baseOperations.TestSub@2a67b4] should have thrown an exception of class java.lang.Exception
	... 7 more
... Removed 9 stack frames]]>
    </failure>
  </testcase> <!-- testSubExceptionIsThrown -->
  <testcase name="testSubPassLong" time="0.001" classname="com.epam.calculator.testCalculator.baseOperations.TestSub"/>
  <testcase name="testSumExceptionIsThrown" time="0.001" classname="com.epam.calculator.testCalculator.baseOperations.TestSum">
    <failure type="org.testng.TestException" message="
Expected exception java.lang.Exception but got org.testng.TestException: 
Method TestSum.testSumExceptionIsThrown(long, long)[pri:0, instance:com.epam.calculator.testCalculator.baseOperations.TestSum@50a6f6] should have thrown an exception of class java.lang.Exception">
      <![CDATA[org.testng.TestException: 
Method TestSum.testSumExceptionIsThrown(long, long)[pri:0, instance:com.epam.calculator.testCalculator.baseOperations.TestSum@50a6f6] should have thrown an exception of class java.lang.Exception
	at java.util.concurrent.FutureTask.run(FutureTask.java:266)
	at java.util.concurrent.Executors$RunnableAdapter.call(Executors.java:511)
	at java.util.concurrent.FutureTask.run(FutureTask.java:266)
	at java.util.concurrent.ThreadPoolExecutor.runWorker(ThreadPoolExecutor.java:1142)
	at java.util.concurrent.ThreadPoolExecutor$Worker.run(ThreadPoolExecutor.java:617)
	at java.lang.Thread.run(Thread.java:745)
Method TestSum.testSumExceptionIsThrown(long, long)[pri:0, instance:com.epam.calculator.testCalculator.baseOperations.TestSum@50a6f6] should have thrown an exception of class java.lang.Exception
	... 7 more
... Removed 9 stack frames]]>
    </failure>
  </testcase> <!-- testSumExceptionIsThrown -->
  <testcase name="testSubFailLong" time="0.002" classname="com.epam.calculator.testCalculator.baseOperations.TestSub"/>
  <testcase name="testMultPassLong" time="0.001" classname="com.epam.calculator.testCalculator.baseOperations.TestMult"/>
  <testcase name="testSumExceptionIsThrown" time="0.0" classname="com.epam.calculator.testCalculator.baseOperations.TestSum">
    <failure type="org.testng.TestException" message="
Expected exception java.lang.Exception but got org.testng.TestException: 
Method TestSum.testSumExceptionIsThrown(long, long)[pri:0, instance:com.epam.calculator.testCalculator.baseOperations.TestSum@50a6f6] should have thrown an exception of class java.lang.Exception">
      <![CDATA[org.testng.TestException: 
Method TestSum.testSumExceptionIsThrown(long, long)[pri:0, instance:com.epam.calculator.testCalculator.baseOperations.TestSum@50a6f6] should have thrown an exception of class java.lang.Exception
	at java.util.concurrent.FutureTask.run(FutureTask.java:266)
	at java.util.concurrent.Executors$RunnableAdapter.call(Executors.java:511)
	at java.util.concurrent.FutureTask.run(FutureTask.java:266)
	at java.util.concurrent.ThreadPoolExecutor.runWorker(ThreadPoolExecutor.java:1142)
	at java.util.concurrent.ThreadPoolExecutor$Worker.run(ThreadPoolExecutor.java:617)
	at java.lang.Thread.run(Thread.java:745)
Method TestSum.testSumExceptionIsThrown(long, long)[pri:0, instance:com.epam.calculator.testCalculator.baseOperations.TestSum@50a6f6] should have thrown an exception of class java.lang.Exception
	... 7 more
... Removed 9 stack frames]]>
    </failure>
  </testcase> <!-- testSumExceptionIsThrown -->
  <testcase name="testDivPassLong" time="0.0" classname="com.epam.calculator.testCalculator.baseOperations.TestDiv"/>
  <testcase name="testSubPassLong" time="0.0" classname="com.epam.calculator.testCalculator.baseOperations.TestSub"/>
  <testcase name="testSumExceptionIsThrown" time="0.0" classname="com.epam.calculator.testCalculator.baseOperations.TestSum">
    <failure type="org.testng.TestException" message="
Expected exception java.lang.Exception but got org.testng.TestException: 
Method TestSum.testSumExceptionIsThrown(long, long)[pri:0, instance:com.epam.calculator.testCalculator.baseOperations.TestSum@50a6f6] should have thrown an exception of class java.lang.Exception">
      <![CDATA[org.testng.TestException: 
Method TestSum.testSumExceptionIsThrown(long, long)[pri:0, instance:com.epam.calculator.testCalculator.baseOperations.TestSum@50a6f6] should have thrown an exception of class java.lang.Exception
	at java.util.concurrent.FutureTask.run(FutureTask.java:266)
	at java.util.concurrent.Executors$RunnableAdapter.call(Executors.java:511)
	at java.util.concurrent.FutureTask.run(FutureTask.java:266)
	at java.util.concurrent.ThreadPoolExecutor.runWorker(ThreadPoolExecutor.java:1142)
	at java.util.concurrent.ThreadPoolExecutor$Worker.run(ThreadPoolExecutor.java:617)
	at java.lang.Thread.run(Thread.java:745)
Method TestSum.testSumExceptionIsThrown(long, long)[pri:0, instance:com.epam.calculator.testCalculator.baseOperations.TestSum@50a6f6] should have thrown an exception of class java.lang.Exception
	... 7 more
... Removed 9 stack frames]]>
    </failure>
  </testcase> <!-- testSumExceptionIsThrown -->
  <testcase name="testMultFailLong" time="0.0" classname="com.epam.calculator.testCalculator.baseOperations.TestMult"/>
  <testcase name="testSubPassLong" time="0.001" classname="com.epam.calculator.testCalculator.baseOperations.TestSub"/>
  <testcase name="testSumFailLong" time="0.001" classname="com.epam.calculator.testCalculator.baseOperations.TestSum"/>
  <testcase name="testMultFailLong" time="0.0" classname="com.epam.calculator.testCalculator.baseOperations.TestMult"/>
  <testcase name="testIsNegativePassLong" time="0.001" classname="com.epam.calculator.testCalculator.sign.TestIsNegative"/>
  <testcase name="testIsNegativeFailLong" time="0.0" classname="com.epam.calculator.testCalculator.sign.TestIsNegative"/>
  <testcase name="testIsNegativeFailLong" time="0.0" classname="com.epam.calculator.testCalculator.sign.TestIsNegative"/>
  <testcase name="testMultFailLong" time="0.001" classname="com.epam.calculator.testCalculator.baseOperations.TestMult"/>
  <testcase name="testIsNegativeFailLong" time="0.001" classname="com.epam.calculator.testCalculator.sign.TestIsNegative"/>
  <testcase name="testIsNegativeFailLong" time="0.001" classname="com.epam.calculator.testCalculator.sign.TestIsNegative"/>
  <testcase name="testMultExceptionIsThrown" time="0.0" classname="com.epam.calculator.testCalculator.baseOperations.TestMult">
    <failure type="org.testng.TestException" message="
Expected exception java.lang.Exception but got org.testng.TestException: 
Method TestMult.testMultExceptionIsThrown(long, long)[pri:0, instance:com.epam.calculator.testCalculator.baseOperations.TestMult@1f70c54] should have thrown an exception of class java.lang.Exception">
      <![CDATA[org.testng.TestException: 
Method TestMult.testMultExceptionIsThrown(long, long)[pri:0, instance:com.epam.calculator.testCalculator.baseOperations.TestMult@1f70c54] should have thrown an exception of class java.lang.Exception
	at java.util.concurrent.FutureTask.run(FutureTask.java:266)
	at java.util.concurrent.Executors$RunnableAdapter.call(Executors.java:511)
	at java.util.concurrent.FutureTask.run(FutureTask.java:266)
	at java.util.concurrent.ThreadPoolExecutor.runWorker(ThreadPoolExecutor.java:1142)
	at java.util.concurrent.ThreadPoolExecutor$Worker.run(ThreadPoolExecutor.java:617)
	at java.lang.Thread.run(Thread.java:745)
Method TestMult.testMultExceptionIsThrown(long, long)[pri:0, instance:com.epam.calculator.testCalculator.baseOperations.TestMult@1f70c54] should have thrown an exception of class java.lang.Exception
	... 7 more
... Removed 9 stack frames]]>
    </failure>
  </testcase> <!-- testMultExceptionIsThrown -->
  <testcase name="testMultExceptionIsThrown" time="0.0" classname="com.epam.calculator.testCalculator.baseOperations.TestMult">
    <failure type="org.testng.TestException" message="
Expected exception java.lang.Exception but got org.testng.TestException: 
Method TestMult.testMultExceptionIsThrown(long, long)[pri:0, instance:com.epam.calculator.testCalculator.baseOperations.TestMult@1f70c54] should have thrown an exception of class java.lang.Exception">
      <![CDATA[org.testng.TestException: 
Method TestMult.testMultExceptionIsThrown(long, long)[pri:0, instance:com.epam.calculator.testCalculator.baseOperations.TestMult@1f70c54] should have thrown an exception of class java.lang.Exception
	at java.util.concurrent.FutureTask.run(FutureTask.java:266)
	at java.util.concurrent.Executors$RunnableAdapter.call(Executors.java:511)
	at java.util.concurrent.FutureTask.run(FutureTask.java:266)
	at java.util.concurrent.ThreadPoolExecutor.runWorker(ThreadPoolExecutor.java:1142)
	at java.util.concurrent.ThreadPoolExecutor$Worker.run(ThreadPoolExecutor.java:617)
	at java.lang.Thread.run(Thread.java:745)
Method TestMult.testMultExceptionIsThrown(long, long)[pri:0, instance:com.epam.calculator.testCalculator.baseOperations.TestMult@1f70c54] should have thrown an exception of class java.lang.Exception
	... 7 more
... Removed 9 stack frames]]>
    </failure>
  </testcase> <!-- testMultExceptionIsThrown -->
  <testcase name="testIsPositiveFailLong" time="0.0" classname="com.epam.calculator.testCalculator.sign.TestIsPositive"/>
  <testcase name="testSumFailLong" time="0.001" classname="com.epam.calculator.testCalculator.baseOperations.TestSum"/>
  <testcase name="testDivExceptionIsThrown" time="0.0" classname="com.epam.calculator.testCalculator.baseOperations.TestDiv"/>
  <testcase name="testIsPositiveFailLong" time="0.0" classname="com.epam.calculator.testCalculator.sign.TestIsPositive"/>
  <testcase name="testDivExceptionIsThrown" time="0.0" classname="com.epam.calculator.testCalculator.baseOperations.TestDiv"/>
  <testcase name="testSumFailLong" time="0.0" classname="com.epam.calculator.testCalculator.baseOperations.TestSum"/>
  <testcase name="testSumExceptionIsThrown" time="0.001" classname="com.epam.calculator.testCalculator.baseOperations.TestSum">
    <failure type="org.testng.TestException" message="
Expected exception java.lang.Exception but got org.testng.TestException: 
Method TestSum.testSumExceptionIsThrown(long, long)[pri:0, instance:com.epam.calculator.testCalculator.baseOperations.TestSum@50a6f6] should have thrown an exception of class java.lang.Exception">
      <![CDATA[org.testng.TestException: 
Method TestSum.testSumExceptionIsThrown(long, long)[pri:0, instance:com.epam.calculator.testCalculator.baseOperations.TestSum@50a6f6] should have thrown an exception of class java.lang.Exception
	at java.util.concurrent.FutureTask.run(FutureTask.java:266)
	at java.util.concurrent.Executors$RunnableAdapter.call(Executors.java:511)
	at java.util.concurrent.FutureTask.run(FutureTask.java:266)
	at java.util.concurrent.ThreadPoolExecutor.runWorker(ThreadPoolExecutor.java:1142)
	at java.util.concurrent.ThreadPoolExecutor$Worker.run(ThreadPoolExecutor.java:617)
	at java.lang.Thread.run(Thread.java:745)
Method TestSum.testSumExceptionIsThrown(long, long)[pri:0, instance:com.epam.calculator.testCalculator.baseOperations.TestSum@50a6f6] should have thrown an exception of class java.lang.Exception
	... 7 more
... Removed 9 stack frames]]>
    </failure>
  </testcase> <!-- testSumExceptionIsThrown -->
  <testcase name="testSumFailLong" time="0.0" classname="com.epam.calculator.testCalculator.baseOperations.TestSum"/>
  <testcase name="testDivExceptionIsThrown" time="0.0" classname="com.epam.calculator.testCalculator.baseOperations.TestDiv"/>
  <testcase name="testDivPassLong" time="0.0" classname="com.epam.calculator.testCalculator.baseOperations.TestDiv"/>
  <testcase name="testIsNegativePassLong" time="0.0" classname="com.epam.calculator.testCalculator.sign.TestIsNegative"/>
  <testcase name="testSumExceptionIsThrown" time="0.0" classname="com.epam.calculator.testCalculator.baseOperations.TestSum">
    <failure type="org.testng.TestException" message="
Expected exception java.lang.Exception but got org.testng.TestException: 
Method TestSum.testSumExceptionIsThrown(long, long)[pri:0, instance:com.epam.calculator.testCalculator.baseOperations.TestSum@50a6f6] should have thrown an exception of class java.lang.Exception">
      <![CDATA[org.testng.TestException: 
Method TestSum.testSumExceptionIsThrown(long, long)[pri:0, instance:com.epam.calculator.testCalculator.baseOperations.TestSum@50a6f6] should have thrown an exception of class java.lang.Exception
	at java.util.concurrent.FutureTask.run(FutureTask.java:266)
	at java.util.concurrent.Executors$RunnableAdapter.call(Executors.java:511)
	at java.util.concurrent.FutureTask.run(FutureTask.java:266)
	at java.util.concurrent.ThreadPoolExecutor.runWorker(ThreadPoolExecutor.java:1142)
	at java.util.concurrent.ThreadPoolExecutor$Worker.run(ThreadPoolExecutor.java:617)
	at java.lang.Thread.run(Thread.java:745)
Method TestSum.testSumExceptionIsThrown(long, long)[pri:0, instance:com.epam.calculator.testCalculator.baseOperations.TestSum@50a6f6] should have thrown an exception of class java.lang.Exception
	... 7 more
... Removed 9 stack frames]]>
    </failure>
  </testcase> <!-- testSumExceptionIsThrown -->
  <testcase name="testDivPassLong" time="0.0" classname="com.epam.calculator.testCalculator.baseOperations.TestDiv"/>
  <testcase name="testSumFailLong" time="0.0" classname="com.epam.calculator.testCalculator.baseOperations.TestSum"/>
  <testcase name="testSumFailLong" time="0.0" classname="com.epam.calculator.testCalculator.baseOperations.TestSum"/>
  <testcase name="testIsPositiveFailLong" time="0.003" classname="com.epam.calculator.testCalculator.sign.TestIsPositive"/>
  <testcase name="testSubExceptionIsThrown" time="0.0" classname="com.epam.calculator.testCalculator.baseOperations.TestSub">
    <failure type="org.testng.TestException" message="
Expected exception java.lang.Exception but got org.testng.TestException: 
Method TestSub.testSubExceptionIsThrown(long, long)[pri:0, instance:com.epam.calculator.testCalculator.baseOperations.TestSub@2a67b4] should have thrown an exception of class java.lang.Exception">
      <![CDATA[org.testng.TestException: 
Method TestSub.testSubExceptionIsThrown(long, long)[pri:0, instance:com.epam.calculator.testCalculator.baseOperations.TestSub@2a67b4] should have thrown an exception of class java.lang.Exception
	at java.util.concurrent.FutureTask.run(FutureTask.java:266)
	at java.util.concurrent.Executors$RunnableAdapter.call(Executors.java:511)
	at java.util.concurrent.FutureTask.run(FutureTask.java:266)
	at java.util.concurrent.ThreadPoolExecutor.runWorker(ThreadPoolExecutor.java:1142)
	at java.util.concurrent.ThreadPoolExecutor$Worker.run(ThreadPoolExecutor.java:617)
	at java.lang.Thread.run(Thread.java:745)
Method TestSub.testSubExceptionIsThrown(long, long)[pri:0, instance:com.epam.calculator.testCalculator.baseOperations.TestSub@2a67b4] should have thrown an exception of class java.lang.Exception
	... 7 more
... Removed 9 stack frames]]>
    </failure>
  </testcase> <!-- testSubExceptionIsThrown -->
  <testcase name="testDivPassLong" time="0.001" classname="com.epam.calculator.testCalculator.baseOperations.TestDiv"/>
  <testcase name="testMultExceptionIsThrown" time="0.004" classname="com.epam.calculator.testCalculator.baseOperations.TestMult">
    <failure type="org.testng.TestException" message="
Expected exception java.lang.Exception but got org.testng.TestException: 
Method TestMult.testMultExceptionIsThrown(long, long)[pri:0, instance:com.epam.calculator.testCalculator.baseOperations.TestMult@1f70c54] should have thrown an exception of class java.lang.Exception">
      <![CDATA[org.testng.TestException: 
Method TestMult.testMultExceptionIsThrown(long, long)[pri:0, instance:com.epam.calculator.testCalculator.baseOperations.TestMult@1f70c54] should have thrown an exception of class java.lang.Exception
	at java.util.concurrent.FutureTask.run(FutureTask.java:266)
	at java.util.concurrent.Executors$RunnableAdapter.call(Executors.java:511)
	at java.util.concurrent.FutureTask.run(FutureTask.java:266)
	at java.util.concurrent.ThreadPoolExecutor.runWorker(ThreadPoolExecutor.java:1142)
	at java.util.concurrent.ThreadPoolExecutor$Worker.run(ThreadPoolExecutor.java:617)
	at java.lang.Thread.run(Thread.java:745)
Method TestMult.testMultExceptionIsThrown(long, long)[pri:0, instance:com.epam.calculator.testCalculator.baseOperations.TestMult@1f70c54] should have thrown an exception of class java.lang.Exception
	... 7 more
... Removed 9 stack frames]]>
    </failure>
  </testcase> <!-- testMultExceptionIsThrown -->
  <testcase name="testMultExceptionIsThrown" time="0.004" classname="com.epam.calculator.testCalculator.baseOperations.TestMult">
    <failure type="org.testng.TestException" message="
Expected exception java.lang.Exception but got org.testng.TestException: 
Method TestMult.testMultExceptionIsThrown(long, long)[pri:0, instance:com.epam.calculator.testCalculator.baseOperations.TestMult@1f70c54] should have thrown an exception of class java.lang.Exception">
      <![CDATA[org.testng.TestException: 
Method TestMult.testMultExceptionIsThrown(long, long)[pri:0, instance:com.epam.calculator.testCalculator.baseOperations.TestMult@1f70c54] should have thrown an exception of class java.lang.Exception
	at java.util.concurrent.FutureTask.run(FutureTask.java:266)
	at java.util.concurrent.Executors$RunnableAdapter.call(Executors.java:511)
	at java.util.concurrent.FutureTask.run(FutureTask.java:266)
	at java.util.concurrent.ThreadPoolExecutor.runWorker(ThreadPoolExecutor.java:1142)
	at java.util.concurrent.ThreadPoolExecutor$Worker.run(ThreadPoolExecutor.java:617)
	at java.lang.Thread.run(Thread.java:745)
Method TestMult.testMultExceptionIsThrown(long, long)[pri:0, instance:com.epam.calculator.testCalculator.baseOperations.TestMult@1f70c54] should have thrown an exception of class java.lang.Exception
	... 7 more
... Removed 9 stack frames]]>
    </failure>
  </testcase> <!-- testMultExceptionIsThrown -->
  <testcase name="testDivPassLong" time="0.0" classname="com.epam.calculator.testCalculator.baseOperations.TestDiv"/>
  <testcase name="testMultPassLong" time="0.001" classname="com.epam.calculator.testCalculator.baseOperations.TestMult"/>
  <testcase name="testSumExceptionIsThrown" time="0.001" classname="com.epam.calculator.testCalculator.baseOperations.TestSum">
    <failure type="org.testng.TestException" message="
Expected exception java.lang.Exception but got org.testng.TestException: 
Method TestSum.testSumExceptionIsThrown(long, long)[pri:0, instance:com.epam.calculator.testCalculator.baseOperations.TestSum@50a6f6] should have thrown an exception of class java.lang.Exception">
      <![CDATA[org.testng.TestException: 
Method TestSum.testSumExceptionIsThrown(long, long)[pri:0, instance:com.epam.calculator.testCalculator.baseOperations.TestSum@50a6f6] should have thrown an exception of class java.lang.Exception
	at java.util.concurrent.FutureTask.run(FutureTask.java:266)
	at java.util.concurrent.Executors$RunnableAdapter.call(Executors.java:511)
	at java.util.concurrent.FutureTask.run(FutureTask.java:266)
	at java.util.concurrent.ThreadPoolExecutor.runWorker(ThreadPoolExecutor.java:1142)
	at java.util.concurrent.ThreadPoolExecutor$Worker.run(ThreadPoolExecutor.java:617)
	at java.lang.Thread.run(Thread.java:745)
Method TestSum.testSumExceptionIsThrown(long, long)[pri:0, instance:com.epam.calculator.testCalculator.baseOperations.TestSum@50a6f6] should have thrown an exception of class java.lang.Exception
	... 7 more
... Removed 9 stack frames]]>
    </failure>
  </testcase> <!-- testSumExceptionIsThrown -->
  <testcase name="testIsNegativeFailLong" time="0.002" classname="com.epam.calculator.testCalculator.sign.TestIsNegative"/>
  <testcase name="testSumFailLong" time="0.035" classname="com.epam.calculator.testCalculator.baseOperations.TestSum"/>
  <testcase name="testSumFailLong" time="0.003" classname="com.epam.calculator.testCalculator.baseOperations.TestSum"/>
  <testcase name="testSumExceptionIsThrown" time="0.001" classname="com.epam.calculator.testCalculator.baseOperations.TestSum">
    <failure type="org.testng.TestException" message="
Expected exception java.lang.Exception but got org.testng.TestException: 
Method TestSum.testSumExceptionIsThrown(long, long)[pri:0, instance:com.epam.calculator.testCalculator.baseOperations.TestSum@50a6f6] should have thrown an exception of class java.lang.Exception">
      <![CDATA[org.testng.TestException: 
Method TestSum.testSumExceptionIsThrown(long, long)[pri:0, instance:com.epam.calculator.testCalculator.baseOperations.TestSum@50a6f6] should have thrown an exception of class java.lang.Exception
	at java.util.concurrent.FutureTask.run(FutureTask.java:266)
	at java.util.concurrent.Executors$RunnableAdapter.call(Executors.java:511)
	at java.util.concurrent.FutureTask.run(FutureTask.java:266)
	at java.util.concurrent.ThreadPoolExecutor.runWorker(ThreadPoolExecutor.java:1142)
	at java.util.concurrent.ThreadPoolExecutor$Worker.run(ThreadPoolExecutor.java:617)
	at java.lang.Thread.run(Thread.java:745)
Method TestSum.testSumExceptionIsThrown(long, long)[pri:0, instance:com.epam.calculator.testCalculator.baseOperations.TestSum@50a6f6] should have thrown an exception of class java.lang.Exception
	... 7 more
... Removed 9 stack frames]]>
    </failure>
  </testcase> <!-- testSumExceptionIsThrown -->
  <testcase name="testDivFailLong" time="0.0" classname="com.epam.calculator.testCalculator.baseOperations.TestDiv"/>
  <testcase name="testDivFailLong" time="0.0" classname="com.epam.calculator.testCalculator.baseOperations.TestDiv"/>
  <testcase name="testSubFailLong" time="0.0" classname="com.epam.calculator.testCalculator.baseOperations.TestSub"/>
  <testcase name="testSumExceptionIsThrown" time="0.001" classname="com.epam.calculator.testCalculator.baseOperations.TestSum">
    <failure type="org.testng.TestException" message="
Expected exception java.lang.Exception but got org.testng.TestException: 
Method TestSum.testSumExceptionIsThrown(long, long)[pri:0, instance:com.epam.calculator.testCalculator.baseOperations.TestSum@50a6f6] should have thrown an exception of class java.lang.Exception">
      <![CDATA[org.testng.TestException: 
Method TestSum.testSumExceptionIsThrown(long, long)[pri:0, instance:com.epam.calculator.testCalculator.baseOperations.TestSum@50a6f6] should have thrown an exception of class java.lang.Exception
	at java.util.concurrent.FutureTask.run(FutureTask.java:266)
	at java.util.concurrent.Executors$RunnableAdapter.call(Executors.java:511)
	at java.util.concurrent.FutureTask.run(FutureTask.java:266)
	at java.util.concurrent.ThreadPoolExecutor.runWorker(ThreadPoolExecutor.java:1142)
	at java.util.concurrent.ThreadPoolExecutor$Worker.run(ThreadPoolExecutor.java:617)
	at java.lang.Thread.run(Thread.java:745)
Method TestSum.testSumExceptionIsThrown(long, long)[pri:0, instance:com.epam.calculator.testCalculator.baseOperations.TestSum@50a6f6] should have thrown an exception of class java.lang.Exception
	... 7 more
... Removed 9 stack frames]]>
    </failure>
  </testcase> <!-- testSumExceptionIsThrown -->
  <testcase name="testSubFailLong" time="0.001" classname="com.epam.calculator.testCalculator.baseOperations.TestSub"/>
  <testcase name="testDivPassLong" time="0.006" classname="com.epam.calculator.testCalculator.baseOperations.TestDiv"/>
  <testcase name="testSubFailLong" time="0.0" classname="com.epam.calculator.testCalculator.baseOperations.TestSub"/>
  <testcase name="testSubPassLong" time="0.002" classname="com.epam.calculator.testCalculator.baseOperations.TestSub"/>
  <testcase name="testSubPassLong" time="0.017" classname="com.epam.calculator.testCalculator.baseOperations.TestSub"/>
  <testcase name="testDivPassLong" time="0.006" classname="com.epam.calculator.testCalculator.baseOperations.TestDiv"/>
  <testcase name="testSubFailLong" time="0.0" classname="com.epam.calculator.testCalculator.baseOperations.TestSub"/>
  <testcase name="testSumExceptionIsThrown" time="0.001" classname="com.epam.calculator.testCalculator.baseOperations.TestSum">
    <failure type="org.testng.TestException" message="
Expected exception java.lang.Exception but got org.testng.TestException: 
Method TestSum.testSumExceptionIsThrown(long, long)[pri:0, instance:com.epam.calculator.testCalculator.baseOperations.TestSum@50a6f6] should have thrown an exception of class java.lang.Exception">
      <![CDATA[org.testng.TestException: 
Method TestSum.testSumExceptionIsThrown(long, long)[pri:0, instance:com.epam.calculator.testCalculator.baseOperations.TestSum@50a6f6] should have thrown an exception of class java.lang.Exception
	at java.util.concurrent.FutureTask.run(FutureTask.java:266)
	at java.util.concurrent.Executors$RunnableAdapter.call(Executors.java:511)
	at java.util.concurrent.FutureTask.run(FutureTask.java:266)
	at java.util.concurrent.ThreadPoolExecutor.runWorker(ThreadPoolExecutor.java:1142)
	at java.util.concurrent.ThreadPoolExecutor$Worker.run(ThreadPoolExecutor.java:617)
	at java.lang.Thread.run(Thread.java:745)
Method TestSum.testSumExceptionIsThrown(long, long)[pri:0, instance:com.epam.calculator.testCalculator.baseOperations.TestSum@50a6f6] should have thrown an exception of class java.lang.Exception
	... 7 more
... Removed 9 stack frames]]>
    </failure>
  </testcase> <!-- testSumExceptionIsThrown -->
  <testcase name="testSumPassLong" time="0.0" classname="com.epam.calculator.testCalculator.baseOperations.TestSum"/>
  <testcase name="testSumPassLong" time="0.0" classname="com.epam.calculator.testCalculator.baseOperations.TestSum"/>
  <testcase name="testSumPassLong" time="0.001" classname="com.epam.calculator.testCalculator.baseOperations.TestSum"/>
  <testcase name="testSubFailLong" time="0.001" classname="com.epam.calculator.testCalculator.baseOperations.TestSub"/>
  <testcase name="testDivPassLong" time="0.008" classname="com.epam.calculator.testCalculator.baseOperations.TestDiv"/>
  <testcase name="testSubPassLong" time="0.0" classname="com.epam.calculator.testCalculator.baseOperations.TestSub"/>
  <testcase name="testSumFailLong" time="0.01" classname="com.epam.calculator.testCalculator.baseOperations.TestSum"/>
  <testcase name="testSubPassLong" time="0.001" classname="com.epam.calculator.testCalculator.baseOperations.TestSub"/>
  <testcase name="testDivPassLong" time="0.001" classname="com.epam.calculator.testCalculator.baseOperations.TestDiv"/>
  <testcase name="testDivPassLong" time="0.001" classname="com.epam.calculator.testCalculator.baseOperations.TestDiv"/>
  <testcase name="testDivExceptionIsThrown" time="0.0" classname="com.epam.calculator.testCalculator.baseOperations.TestDiv"/>
  <testcase name="testDivPassLong" time="0.001" classname="com.epam.calculator.testCalculator.baseOperations.TestDiv"/>
  <testcase name="testSumFailLong" time="0.01" classname="com.epam.calculator.testCalculator.baseOperations.TestSum"/>
  <testcase name="testMultPassLong" time="0.001" classname="com.epam.calculator.testCalculator.baseOperations.TestMult"/>
  <testcase name="testSubFailLong" time="0.004" classname="com.epam.calculator.testCalculator.baseOperations.TestSub"/>
  <testcase name="testIsPositivePassLong" time="0.007" classname="com.epam.calculator.testCalculator.sign.TestIsPositive"/>
  <testcase name="testMultFailLong" time="0.0" classname="com.epam.calculator.testCalculator.baseOperations.TestMult"/>
  <testcase name="testDivFailLong" time="0.001" classname="com.epam.calculator.testCalculator.baseOperations.TestDiv"/>
  <testcase name="testIsPositivePassLong" time="0.001" classname="com.epam.calculator.testCalculator.sign.TestIsPositive"/>
  <testcase name="testSubExceptionIsThrown" time="0.002" classname="com.epam.calculator.testCalculator.baseOperations.TestSub">
    <failure type="org.testng.TestException" message="
Expected exception java.lang.Exception but got org.testng.TestException: 
Method TestSub.testSubExceptionIsThrown(long, long)[pri:0, instance:com.epam.calculator.testCalculator.baseOperations.TestSub@2a67b4] should have thrown an exception of class java.lang.Exception">
      <![CDATA[org.testng.TestException: 
Method TestSub.testSubExceptionIsThrown(long, long)[pri:0, instance:com.epam.calculator.testCalculator.baseOperations.TestSub@2a67b4] should have thrown an exception of class java.lang.Exception
	at java.util.concurrent.FutureTask.run(FutureTask.java:266)
	at java.util.concurrent.Executors$RunnableAdapter.call(Executors.java:511)
	at java.util.concurrent.FutureTask.run(FutureTask.java:266)
	at java.util.concurrent.ThreadPoolExecutor.runWorker(ThreadPoolExecutor.java:1142)
	at java.util.concurrent.ThreadPoolExecutor$Worker.run(ThreadPoolExecutor.java:617)
	at java.lang.Thread.run(Thread.java:745)
Method TestSub.testSubExceptionIsThrown(long, long)[pri:0, instance:com.epam.calculator.testCalculator.baseOperations.TestSub@2a67b4] should have thrown an exception of class java.lang.Exception
	... 7 more
... Removed 9 stack frames]]>
    </failure>
  </testcase> <!-- testSubExceptionIsThrown -->
  <testcase name="testDivFailLong" time="0.0" classname="com.epam.calculator.testCalculator.baseOperations.TestDiv"/>
  <testcase name="testSumPassLong" time="0.0" classname="com.epam.calculator.testCalculator.baseOperations.TestSum"/>
  <testcase name="testSumPassLong" time="0.001" classname="com.epam.calculator.testCalculator.baseOperations.TestSum"/>
  <testcase name="testDivFailLong" time="0.005" classname="com.epam.calculator.testCalculator.baseOperations.TestDiv"/>
  <testcase name="testSubExceptionIsThrown" time="0.0" classname="com.epam.calculator.testCalculator.baseOperations.TestSub">
    <failure type="org.testng.TestException" message="
Expected exception java.lang.Exception but got org.testng.TestException: 
Method TestSub.testSubExceptionIsThrown(long, long)[pri:0, instance:com.epam.calculator.testCalculator.baseOperations.TestSub@2a67b4] should have thrown an exception of class java.lang.Exception">
      <![CDATA[org.testng.TestException: 
Method TestSub.testSubExceptionIsThrown(long, long)[pri:0, instance:com.epam.calculator.testCalculator.baseOperations.TestSub@2a67b4] should have thrown an exception of class java.lang.Exception
	at java.util.concurrent.FutureTask.run(FutureTask.java:266)
	at java.util.concurrent.Executors$RunnableAdapter.call(Executors.java:511)
	at java.util.concurrent.FutureTask.run(FutureTask.java:266)
	at java.util.concurrent.ThreadPoolExecutor.runWorker(ThreadPoolExecutor.java:1142)
	at java.util.concurrent.ThreadPoolExecutor$Worker.run(ThreadPoolExecutor.java:617)
	at java.lang.Thread.run(Thread.java:745)
Method TestSub.testSubExceptionIsThrown(long, long)[pri:0, instance:com.epam.calculator.testCalculator.baseOperations.TestSub@2a67b4] should have thrown an exception of class java.lang.Exception
	... 7 more
... Removed 9 stack frames]]>
    </failure>
  </testcase> <!-- testSubExceptionIsThrown -->
  <testcase name="testSubFailLong" time="0.0" classname="com.epam.calculator.testCalculator.baseOperations.TestSub"/>
  <testcase name="testSumPassLong" time="0.001" classname="com.epam.calculator.testCalculator.baseOperations.TestSum"/>
  <testcase name="testSumPassLong" time="0.002" classname="com.epam.calculator.testCalculator.baseOperations.TestSum"/>
  <testcase name="testDivFailLong" time="0.006" classname="com.epam.calculator.testCalculator.baseOperations.TestDiv"/>
  <testcase name="testSubExceptionIsThrown" time="0.001" classname="com.epam.calculator.testCalculator.baseOperations.TestSub">
    <failure type="org.testng.TestException" message="
Expected exception java.lang.Exception but got org.testng.TestException: 
Method TestSub.testSubExceptionIsThrown(long, long)[pri:0, instance:com.epam.calculator.testCalculator.baseOperations.TestSub@2a67b4] should have thrown an exception of class java.lang.Exception">
      <![CDATA[org.testng.TestException: 
Method TestSub.testSubExceptionIsThrown(long, long)[pri:0, instance:com.epam.calculator.testCalculator.baseOperations.TestSub@2a67b4] should have thrown an exception of class java.lang.Exception
	at java.util.concurrent.FutureTask.run(FutureTask.java:266)
	at java.util.concurrent.Executors$RunnableAdapter.call(Executors.java:511)
	at java.util.concurrent.FutureTask.run(FutureTask.java:266)
	at java.util.concurrent.ThreadPoolExecutor.runWorker(ThreadPoolExecutor.java:1142)
	at java.util.concurrent.ThreadPoolExecutor$Worker.run(ThreadPoolExecutor.java:617)
	at java.lang.Thread.run(Thread.java:745)
Method TestSub.testSubExceptionIsThrown(long, long)[pri:0, instance:com.epam.calculator.testCalculator.baseOperations.TestSub@2a67b4] should have thrown an exception of class java.lang.Exception
	... 7 more
... Removed 9 stack frames]]>
    </failure>
  </testcase> <!-- testSubExceptionIsThrown -->
  <testcase name="testSumPassLong" time="0.0" classname="com.epam.calculator.testCalculator.baseOperations.TestSum"/>
  <testcase name="testSubFailLong" time="0.001" classname="com.epam.calculator.testCalculator.baseOperations.TestSub"/>
  <testcase name="testSubPassLong" time="0.0" classname="com.epam.calculator.testCalculator.baseOperations.TestSub"/>
  <testcase name="testSubPassLong" time="0.001" classname="com.epam.calculator.testCalculator.baseOperations.TestSub"/>
  <testcase name="testSubExceptionIsThrown" time="0.003" classname="com.epam.calculator.testCalculator.baseOperations.TestSub">
    <failure type="org.testng.TestException" message="
Expected exception java.lang.Exception but got org.testng.TestException: 
Method TestSub.testSubExceptionIsThrown(long, long)[pri:0, instance:com.epam.calculator.testCalculator.baseOperations.TestSub@2a67b4] should have thrown an exception of class java.lang.Exception">
      <![CDATA[org.testng.TestException: 
Method TestSub.testSubExceptionIsThrown(long, long)[pri:0, instance:com.epam.calculator.testCalculator.baseOperations.TestSub@2a67b4] should have thrown an exception of class java.lang.Exception
	at java.util.concurrent.FutureTask.run(FutureTask.java:266)
	at java.util.concurrent.Executors$RunnableAdapter.call(Executors.java:511)
	at java.util.concurrent.FutureTask.run(FutureTask.java:266)
	at java.util.concurrent.ThreadPoolExecutor.runWorker(ThreadPoolExecutor.java:1142)
	at java.util.concurrent.ThreadPoolExecutor$Worker.run(ThreadPoolExecutor.java:617)
	at java.lang.Thread.run(Thread.java:745)
Method TestSub.testSubExceptionIsThrown(long, long)[pri:0, instance:com.epam.calculator.testCalculator.baseOperations.TestSub@2a67b4] should have thrown an exception of class java.lang.Exception
	... 7 more
... Removed 9 stack frames]]>
    </failure>
  </testcase> <!-- testSubExceptionIsThrown -->
  <testcase name="testSubPassLong" time="0.0" classname="com.epam.calculator.testCalculator.baseOperations.TestSub"/>
  <testcase name="testSubFailLong" time="0.007" classname="com.epam.calculator.testCalculator.baseOperations.TestSub"/>
  <testcase name="testMultFailLong" time="0.0" classname="com.epam.calculator.testCalculator.baseOperations.TestMult"/>
  <testcase name="testSubFailLong" time="0.001" classname="com.epam.calculator.testCalculator.baseOperations.TestSub"/>
  <testcase name="testSubExceptionIsThrown" time="0.001" classname="com.epam.calculator.testCalculator.baseOperations.TestSub">
    <failure type="org.testng.TestException" message="
Expected exception java.lang.Exception but got org.testng.TestException: 
Method TestSub.testSubExceptionIsThrown(long, long)[pri:0, instance:com.epam.calculator.testCalculator.baseOperations.TestSub@2a67b4] should have thrown an exception of class java.lang.Exception">
      <![CDATA[org.testng.TestException: 
Method TestSub.testSubExceptionIsThrown(long, long)[pri:0, instance:com.epam.calculator.testCalculator.baseOperations.TestSub@2a67b4] should have thrown an exception of class java.lang.Exception
	at java.util.concurrent.FutureTask.run(FutureTask.java:266)
	at java.util.concurrent.Executors$RunnableAdapter.call(Executors.java:511)
	at java.util.concurrent.FutureTask.run(FutureTask.java:266)
	at java.util.concurrent.ThreadPoolExecutor.runWorker(ThreadPoolExecutor.java:1142)
	at java.util.concurrent.ThreadPoolExecutor$Worker.run(ThreadPoolExecutor.java:617)
	at java.lang.Thread.run(Thread.java:745)
Method TestSub.testSubExceptionIsThrown(long, long)[pri:0, instance:com.epam.calculator.testCalculator.baseOperations.TestSub@2a67b4] should have thrown an exception of class java.lang.Exception
	... 7 more
... Removed 9 stack frames]]>
    </failure>
  </testcase> <!-- testSubExceptionIsThrown -->
  <testcase name="testSubExceptionIsThrown" time="0.0" classname="com.epam.calculator.testCalculator.baseOperations.TestSub">
    <failure type="org.testng.TestException" message="
Expected exception java.lang.Exception but got org.testng.TestException: 
Method TestSub.testSubExceptionIsThrown(long, long)[pri:0, instance:com.epam.calculator.testCalculator.baseOperations.TestSub@2a67b4] should have thrown an exception of class java.lang.Exception">
      <![CDATA[org.testng.TestException: 
Method TestSub.testSubExceptionIsThrown(long, long)[pri:0, instance:com.epam.calculator.testCalculator.baseOperations.TestSub@2a67b4] should have thrown an exception of class java.lang.Exception
	at java.util.concurrent.FutureTask.run(FutureTask.java:266)
	at java.util.concurrent.Executors$RunnableAdapter.call(Executors.java:511)
	at java.util.concurrent.FutureTask.run(FutureTask.java:266)
	at java.util.concurrent.ThreadPoolExecutor.runWorker(ThreadPoolExecutor.java:1142)
	at java.util.concurrent.ThreadPoolExecutor$Worker.run(ThreadPoolExecutor.java:617)
	at java.lang.Thread.run(Thread.java:745)
Method TestSub.testSubExceptionIsThrown(long, long)[pri:0, instance:com.epam.calculator.testCalculator.baseOperations.TestSub@2a67b4] should have thrown an exception of class java.lang.Exception
	... 7 more
... Removed 9 stack frames]]>
    </failure>
  </testcase> <!-- testSubExceptionIsThrown -->
  <testcase name="testDivPassLong" time="0.004" classname="com.epam.calculator.testCalculator.baseOperations.TestDiv"/>
  <testcase name="testDivPassLong" time="0.0" classname="com.epam.calculator.testCalculator.baseOperations.TestDiv"/>
  <testcase name="testSumPassLong" time="0.003" classname="com.epam.calculator.testCalculator.baseOperations.TestSum"/>
  <testcase name="testMultFailLong" time="0.0" classname="com.epam.calculator.testCalculator.baseOperations.TestMult"/>
  <testcase name="testMultFailLong" time="0.0" classname="com.epam.calculator.testCalculator.baseOperations.TestMult"/>
  <testcase name="testSubPassLong" time="0.0" classname="com.epam.calculator.testCalculator.baseOperations.TestSub"/>
  <testcase name="testSubPassLong" time="0.0" classname="com.epam.calculator.testCalculator.baseOperations.TestSub"/>
  <testcase name="testMultPassLong" time="0.0" classname="com.epam.calculator.testCalculator.baseOperations.TestMult"/>
  <testcase name="testMultFailLong" time="0.002" classname="com.epam.calculator.testCalculator.baseOperations.TestMult"/>
  <testcase name="testSumPassLong" time="0.001" classname="com.epam.calculator.testCalculator.baseOperations.TestSum"/>
  <testcase name="testMultFailLong" time="0.0" classname="com.epam.calculator.testCalculator.baseOperations.TestMult"/>
  <testcase name="testSubPassLong" time="0.0" classname="com.epam.calculator.testCalculator.baseOperations.TestSub"/>
  <testcase name="testMultPassLong" time="0.0" classname="com.epam.calculator.testCalculator.baseOperations.TestMult"/>
  <testcase name="testMultFailLong" time="0.0" classname="com.epam.calculator.testCalculator.baseOperations.TestMult"/>
  <testcase name="testMultFailLong" time="0.001" classname="com.epam.calculator.testCalculator.baseOperations.TestMult"/>
  <testcase name="testDivFailLong" time="0.0" classname="com.epam.calculator.testCalculator.baseOperations.TestDiv"/>
  <testcase name="testMultPassLong" time="0.0" classname="com.epam.calculator.testCalculator.baseOperations.TestMult"/>
  <testcase name="testDivFailLong" time="0.0" classname="com.epam.calculator.testCalculator.baseOperations.TestDiv"/>
  <testcase name="testDivFailLong" time="0.0" classname="com.epam.calculator.testCalculator.baseOperations.TestDiv"/>
  <testcase name="testMultPassLong" time="0.0" classname="com.epam.calculator.testCalculator.baseOperations.TestMult"/>
  <testcase name="testMultPassLong" time="0.0" classname="com.epam.calculator.testCalculator.baseOperations.TestMult"/>
  <testcase name="testMultPassLong" time="0.001" classname="com.epam.calculator.testCalculator.baseOperations.TestMult"/>
  <testcase name="testSubPassLong" time="0.0" classname="com.epam.calculator.testCalculator.baseOperations.TestSub"/>
  <testcase name="testIsPositiveFailLong" time="0.0" classname="com.epam.calculator.testCalculator.sign.TestIsPositive"/>
  <testcase name="testMultPassLong" time="0.001" classname="com.epam.calculator.testCalculator.baseOperations.TestMult"/>
  <testcase name="testSumFailLong" time="0.0" classname="com.epam.calculator.testCalculator.baseOperations.TestSum"/>
  <testcase name="testMultPassLong" time="0.004" classname="com.epam.calculator.testCalculator.baseOperations.TestMult"/>
  <testcase name="testMultPassLong" time="0.0" classname="com.epam.calculator.testCalculator.baseOperations.TestMult"/>
  <testcase name="testMultPassLong" time="0.0" classname="com.epam.calculator.testCalculator.baseOperations.TestMult"/>
  <testcase name="testSubPassLong" time="0.001" classname="com.epam.calculator.testCalculator.baseOperations.TestSub"/>
  <testcase name="testSumFailLong" time="0.001" classname="com.epam.calculator.testCalculator.baseOperations.TestSum"/>
  <testcase name="testSubPassLong" time="0.001" classname="com.epam.calculator.testCalculator.baseOperations.TestSub"/>
  <testcase name="testSubPassLong" time="0.0" classname="com.epam.calculator.testCalculator.baseOperations.TestSub"/>
  <testcase name="testSubPassLong" time="0.0" classname="com.epam.calculator.testCalculator.baseOperations.TestSub"/>
  <testcase name="testMultPassLong" time="0.0" classname="com.epam.calculator.testCalculator.baseOperations.TestMult"/>
  <testcase name="testSumFailLong" time="0.0" classname="com.epam.calculator.testCalculator.baseOperations.TestSum"/>
  <testcase name="testSumFailLong" time="0.0" classname="com.epam.calculator.testCalculator.baseOperations.TestSum"/>
  <testcase name="testSumFailLong" time="0.0" classname="com.epam.calculator.testCalculator.baseOperations.TestSum"/>
  <testcase name="testSumPassLong" time="0.003" classname="com.epam.calculator.testCalculator.baseOperations.TestSum"/>
  <testcase name="testSubFailLong" time="0.0" classname="com.epam.calculator.testCalculator.baseOperations.TestSub"/>
  <testcase name="testSubFailLong" time="0.0" classname="com.epam.calculator.testCalculator.baseOperations.TestSub"/>
  <testcase name="testSumPassLong" time="0.0" classname="com.epam.calculator.testCalculator.baseOperations.TestSum"/>
  <testcase name="testSubFailLong" time="0.0" classname="com.epam.calculator.testCalculator.baseOperations.TestSub"/>
  <testcase name="testSumPassLong" time="0.0" classname="com.epam.calculator.testCalculator.baseOperations.TestSum"/>
  <testcase name="testSubFailLong" time="0.001" classname="com.epam.calculator.testCalculator.baseOperations.TestSub"/>
  <testcase name="testSumPassLong" time="0.0" classname="com.epam.calculator.testCalculator.baseOperations.TestSum"/>
  <testcase name="testSubFailLong" time="0.0" classname="com.epam.calculator.testCalculator.baseOperations.TestSub"/>
  <testcase name="testSumPassLong" time="0.001" classname="com.epam.calculator.testCalculator.baseOperations.TestSum"/>
  <testcase name="testSumPassLong" time="0.001" classname="com.epam.calculator.testCalculator.baseOperations.TestSum"/>
  <testcase name="testSumPassLong" time="0.001" classname="com.epam.calculator.testCalculator.baseOperations.TestSum"/>
  <testcase name="testSumPassLong" time="0.0" classname="com.epam.calculator.testCalculator.baseOperations.TestSum"/>
  <testcase name="testSumPassLong" time="0.0" classname="com.epam.calculator.testCalculator.baseOperations.TestSum"/>
</testsuite> <!-- TestNG Functional Group -->
