<?xml version="1.0" encoding="UTF-8"?>
<!-- Generated by org.testng.reporters.JUnitReportReporter -->
<testsuite hostname="BIL-PC" name="com.epam.calculator.testCalculator.baseOperations.TestSum" tests="158" failures="30" timestamp="31 May 2016 22:34:05 GMT" time="0.154" errors="0">
  <testcase name="testSumFailLong" time="0.000" classname="com.epam.calculator.testCalculator.baseOperations.TestSum"/>
  <testcase name="testSumFailLong" time="0.000" classname="com.epam.calculator.testCalculator.baseOperations.TestSum"/>
  <testcase name="testSumFailLong" time="0.002" classname="com.epam.calculator.testCalculator.baseOperations.TestSum"/>
  <testcase name="testSumFailLong" time="0.000" classname="com.epam.calculator.testCalculator.baseOperations.TestSum"/>
  <testcase name="testSumPassLong" time="0.001" classname="com.epam.calculator.testCalculator.baseOperations.TestSum"/>
  <testcase name="testSumExceptionIsThrown" time="0.001" classname="com.epam.calculator.testCalculator.baseOperations.TestSum">
    <failure type="org.testng.TestException" message="
Expected exception java.lang.Exception but got org.testng.TestException: 
Method TestSum.testSumExceptionIsThrown(long, long)[pri:0, instance:com.epam.calculator.testCalculator.baseOperations.TestSum@1af06fc] should have thrown an exception of class java.lang.Exception">
      <![CDATA[org.testng.TestException: 
Expected exception java.lang.Exception but got org.testng.TestException: 
Method TestSum.testSumExceptionIsThrown(long, long)[pri:0, instance:com.epam.calculator.testCalculator.baseOperations.TestSum@1af06fc] should have thrown an exception of class java.lang.Exception
	at org.testng.internal.Invoker.handleInvocationResults(Invoker.java:1497)
	at org.testng.internal.TestMethodWithDataProviderMethodWorker.call(TestMethodWithDataProviderMethodWorker.java:87)
	at org.testng.internal.TestMethodWithDataProviderMethodWorker.call(TestMethodWithDataProviderMethodWorker.java:14)
	at java.util.concurrent.FutureTask.run(FutureTask.java:266)
	at java.util.concurrent.Executors$RunnableAdapter.call(Executors.java:511)
	at java.util.concurrent.FutureTask.run(FutureTask.java:266)
	at java.util.concurrent.ThreadPoolExecutor.runWorker(ThreadPoolExecutor.java:1142)
	at java.util.concurrent.ThreadPoolExecutor$Worker.run(ThreadPoolExecutor.java:617)
	at java.lang.Thread.run(Thread.java:745)
Caused by: org.testng.TestException: 
Method TestSum.testSumExceptionIsThrown(long, long)[pri:0, instance:com.epam.calculator.testCalculator.baseOperations.TestSum@1af06fc] should have thrown an exception of class java.lang.Exception
	at org.testng.internal.Invoker.handleInvocationResults(Invoker.java:1512)
	at org.testng.internal.Invoker.invokeMethod(Invoker.java:754)
	at org.testng.internal.Invoker.invokeTestMethod(Invoker.java:901)
	at org.testng.internal.TestMethodWithDataProviderMethodWorker.call(TestMethodWithDataProviderMethodWorker.java:73)
	... 7 more
]]>
    </failure>
  </testcase> <!-- testSumExceptionIsThrown -->
  <testcase name="testSumPassLong" time="0.001" classname="com.epam.calculator.testCalculator.baseOperations.TestSum"/>
  <testcase name="testSumFailLong" time="0.000" classname="com.epam.calculator.testCalculator.baseOperations.TestSum"/>
  <testcase name="testSumFailLong" time="0.000" classname="com.epam.calculator.testCalculator.baseOperations.TestSum"/>
  <testcase name="testSumPassLong" time="0.001" classname="com.epam.calculator.testCalculator.baseOperations.TestSum"/>
  <testcase name="testSumPassLong" time="0.000" classname="com.epam.calculator.testCalculator.baseOperations.TestSum"/>
  <testcase name="testSumFailLong" time="0.003" classname="com.epam.calculator.testCalculator.baseOperations.TestSum"/>
  <testcase name="testSumFailLong" time="0.000" classname="com.epam.calculator.testCalculator.baseOperations.TestSum"/>
  <testcase name="testSumPassLong" time="0.001" classname="com.epam.calculator.testCalculator.baseOperations.TestSum"/>
  <testcase name="testSumFailLong" time="0.000" classname="com.epam.calculator.testCalculator.baseOperations.TestSum"/>
  <testcase name="testSumPassLong" time="0.000" classname="com.epam.calculator.testCalculator.baseOperations.TestSum"/>
  <testcase name="testSumPassLong" time="0.002" classname="com.epam.calculator.testCalculator.baseOperations.TestSum"/>
  <testcase name="testSumPassLong" time="0.001" classname="com.epam.calculator.testCalculator.baseOperations.TestSum"/>
  <testcase name="testSumFailLong" time="0.010" classname="com.epam.calculator.testCalculator.baseOperations.TestSum"/>
  <testcase name="testSumPassLong" time="0.001" classname="com.epam.calculator.testCalculator.baseOperations.TestSum"/>
  <testcase name="testSumFailLong" time="0.001" classname="com.epam.calculator.testCalculator.baseOperations.TestSum"/>
  <testcase name="testSumExceptionIsThrown" time="0.000" classname="com.epam.calculator.testCalculator.baseOperations.TestSum">
    <failure type="org.testng.TestException" message="
Expected exception java.lang.Exception but got org.testng.TestException: 
Method TestSum.testSumExceptionIsThrown(long, long)[pri:0, instance:com.epam.calculator.testCalculator.baseOperations.TestSum@50a6f6] should have thrown an exception of class java.lang.Exception">
      <![CDATA[org.testng.TestException: 
Expected exception java.lang.Exception but got org.testng.TestException: 
Method TestSum.testSumExceptionIsThrown(long, long)[pri:0, instance:com.epam.calculator.testCalculator.baseOperations.TestSum@50a6f6] should have thrown an exception of class java.lang.Exception
	at org.testng.internal.Invoker.handleInvocationResults(Invoker.java:1497)
	at org.testng.internal.TestMethodWithDataProviderMethodWorker.call(TestMethodWithDataProviderMethodWorker.java:87)
	at org.testng.internal.TestMethodWithDataProviderMethodWorker.call(TestMethodWithDataProviderMethodWorker.java:14)
	at java.util.concurrent.FutureTask.run(FutureTask.java:266)
	at java.util.concurrent.Executors$RunnableAdapter.call(Executors.java:511)
	at java.util.concurrent.FutureTask.run(FutureTask.java:266)
	at java.util.concurrent.ThreadPoolExecutor.runWorker(ThreadPoolExecutor.java:1142)
	at java.util.concurrent.ThreadPoolExecutor$Worker.run(ThreadPoolExecutor.java:617)
	at java.lang.Thread.run(Thread.java:745)
Caused by: org.testng.TestException: 
Method TestSum.testSumExceptionIsThrown(long, long)[pri:0, instance:com.epam.calculator.testCalculator.baseOperations.TestSum@50a6f6] should have thrown an exception of class java.lang.Exception
	at org.testng.internal.Invoker.handleInvocationResults(Invoker.java:1512)
	at org.testng.internal.Invoker.invokeMethod(Invoker.java:754)
	at org.testng.internal.Invoker.invokeTestMethod(Invoker.java:901)
	at org.testng.internal.TestMethodWithDataProviderMethodWorker.call(TestMethodWithDataProviderMethodWorker.java:73)
	... 7 more
]]>
    </failure>
  </testcase> <!-- testSumExceptionIsThrown -->
  <testcase name="testSumPassLong" time="0.000" classname="com.epam.calculator.testCalculator.baseOperations.TestSum"/>
  <testcase name="testSumPassLong" time="0.000" classname="com.epam.calculator.testCalculator.baseOperations.TestSum"/>
  <testcase name="testSumFailLong" time="0.000" classname="com.epam.calculator.testCalculator.baseOperations.TestSum"/>
  <testcase name="testSumPassLong" time="0.000" classname="com.epam.calculator.testCalculator.baseOperations.TestSum"/>
  <testcase name="testSumFailLong" time="0.000" classname="com.epam.calculator.testCalculator.baseOperations.TestSum"/>
  <testcase name="testSumPassLong" time="0.001" classname="com.epam.calculator.testCalculator.baseOperations.TestSum"/>
  <testcase name="testSumFailLong" time="0.035" classname="com.epam.calculator.testCalculator.baseOperations.TestSum"/>
  <testcase name="testSumFailLong" time="0.000" classname="com.epam.calculator.testCalculator.baseOperations.TestSum"/>
  <testcase name="testSumExceptionIsThrown" time="0.001" classname="com.epam.calculator.testCalculator.baseOperations.TestSum">
    <failure type="org.testng.TestException" message="
Expected exception java.lang.Exception but got org.testng.TestException: 
Method TestSum.testSumExceptionIsThrown(long, long)[pri:0, instance:com.epam.calculator.testCalculator.baseOperations.TestSum@50a6f6] should have thrown an exception of class java.lang.Exception">
      <![CDATA[org.testng.TestException: 
Expected exception java.lang.Exception but got org.testng.TestException: 
Method TestSum.testSumExceptionIsThrown(long, long)[pri:0, instance:com.epam.calculator.testCalculator.baseOperations.TestSum@50a6f6] should have thrown an exception of class java.lang.Exception
	at org.testng.internal.Invoker.handleInvocationResults(Invoker.java:1497)
	at org.testng.internal.TestMethodWithDataProviderMethodWorker.call(TestMethodWithDataProviderMethodWorker.java:87)
	at org.testng.internal.TestMethodWithDataProviderMethodWorker.call(TestMethodWithDataProviderMethodWorker.java:14)
	at java.util.concurrent.FutureTask.run(FutureTask.java:266)
	at java.util.concurrent.Executors$RunnableAdapter.call(Executors.java:511)
	at java.util.concurrent.FutureTask.run(FutureTask.java:266)
	at java.util.concurrent.ThreadPoolExecutor.runWorker(ThreadPoolExecutor.java:1142)
	at java.util.concurrent.ThreadPoolExecutor$Worker.run(ThreadPoolExecutor.java:617)
	at java.lang.Thread.run(Thread.java:745)
Caused by: org.testng.TestException: 
Method TestSum.testSumExceptionIsThrown(long, long)[pri:0, instance:com.epam.calculator.testCalculator.baseOperations.TestSum@50a6f6] should have thrown an exception of class java.lang.Exception
	at org.testng.internal.Invoker.handleInvocationResults(Invoker.java:1512)
	at org.testng.internal.Invoker.invokeMethod(Invoker.java:754)
	at org.testng.internal.Invoker.invokeTestMethod(Invoker.java:901)
	at org.testng.internal.TestMethodWithDataProviderMethodWorker.call(TestMethodWithDataProviderMethodWorker.java:73)
	... 7 more
]]>
    </failure>
  </testcase> <!-- testSumExceptionIsThrown -->
  <testcase name="testSumFailLong" time="0.005" classname="com.epam.calculator.testCalculator.baseOperations.TestSum"/>
  <testcase name="testSumPassLong" time="0.000" classname="com.epam.calculator.testCalculator.baseOperations.TestSum"/>
  <testcase name="testSumPassLong" time="0.000" classname="com.epam.calculator.testCalculator.baseOperations.TestSum"/>
  <testcase name="testSumPassLong" time="0.000" classname="com.epam.calculator.testCalculator.baseOperations.TestSum"/>
  <testcase name="testSumPassLong" time="0.000" classname="com.epam.calculator.testCalculator.baseOperations.TestSum"/>
  <testcase name="testSumPassLong" time="0.000" classname="com.epam.calculator.testCalculator.baseOperations.TestSum"/>
  <testcase name="testSumPassLong" time="0.000" classname="com.epam.calculator.testCalculator.baseOperations.TestSum"/>
  <testcase name="testSumPassLong" time="0.001" classname="com.epam.calculator.testCalculator.baseOperations.TestSum"/>
  <testcase name="testSumPassLong" time="0.000" classname="com.epam.calculator.testCalculator.baseOperations.TestSum"/>
  <testcase name="testSumExceptionIsThrown" time="0.002" classname="com.epam.calculator.testCalculator.baseOperations.TestSum">
    <failure type="org.testng.TestException" message="
Expected exception java.lang.Exception but got org.testng.TestException: 
Method TestSum.testSumExceptionIsThrown(long, long)[pri:0, instance:com.epam.calculator.testCalculator.baseOperations.TestSum@11c311e] should have thrown an exception of class java.lang.Exception">
      <![CDATA[org.testng.TestException: 
Expected exception java.lang.Exception but got org.testng.TestException: 
Method TestSum.testSumExceptionIsThrown(long, long)[pri:0, instance:com.epam.calculator.testCalculator.baseOperations.TestSum@11c311e] should have thrown an exception of class java.lang.Exception
	at org.testng.internal.Invoker.handleInvocationResults(Invoker.java:1497)
	at org.testng.internal.TestMethodWithDataProviderMethodWorker.call(TestMethodWithDataProviderMethodWorker.java:87)
	at org.testng.internal.TestMethodWithDataProviderMethodWorker.call(TestMethodWithDataProviderMethodWorker.java:14)
	at java.util.concurrent.FutureTask.run(FutureTask.java:266)
	at java.util.concurrent.Executors$RunnableAdapter.call(Executors.java:511)
	at java.util.concurrent.FutureTask.run(FutureTask.java:266)
	at java.util.concurrent.ThreadPoolExecutor.runWorker(ThreadPoolExecutor.java:1142)
	at java.util.concurrent.ThreadPoolExecutor$Worker.run(ThreadPoolExecutor.java:617)
	at java.lang.Thread.run(Thread.java:745)
Caused by: org.testng.TestException: 
Method TestSum.testSumExceptionIsThrown(long, long)[pri:0, instance:com.epam.calculator.testCalculator.baseOperations.TestSum@11c311e] should have thrown an exception of class java.lang.Exception
	at org.testng.internal.Invoker.handleInvocationResults(Invoker.java:1512)
	at org.testng.internal.Invoker.invokeMethod(Invoker.java:754)
	at org.testng.internal.Invoker.invokeTestMethod(Invoker.java:901)
	at org.testng.internal.TestMethodWithDataProviderMethodWorker.call(TestMethodWithDataProviderMethodWorker.java:73)
	... 7 more
]]>
    </failure>
  </testcase> <!-- testSumExceptionIsThrown -->
  <testcase name="testSumPassLong" time="0.000" classname="com.epam.calculator.testCalculator.baseOperations.TestSum"/>
  <testcase name="testSumExceptionIsThrown" time="0.000" classname="com.epam.calculator.testCalculator.baseOperations.TestSum">
    <failure type="org.testng.TestException" message="
Expected exception java.lang.Exception but got org.testng.TestException: 
Method TestSum.testSumExceptionIsThrown(long, long)[pri:0, instance:com.epam.calculator.testCalculator.baseOperations.TestSum@1af06fc] should have thrown an exception of class java.lang.Exception">
      <![CDATA[org.testng.TestException: 
Expected exception java.lang.Exception but got org.testng.TestException: 
Method TestSum.testSumExceptionIsThrown(long, long)[pri:0, instance:com.epam.calculator.testCalculator.baseOperations.TestSum@1af06fc] should have thrown an exception of class java.lang.Exception
	at org.testng.internal.Invoker.handleInvocationResults(Invoker.java:1497)
	at org.testng.internal.TestMethodWithDataProviderMethodWorker.call(TestMethodWithDataProviderMethodWorker.java:87)
	at org.testng.internal.TestMethodWithDataProviderMethodWorker.call(TestMethodWithDataProviderMethodWorker.java:14)
	at java.util.concurrent.FutureTask.run(FutureTask.java:266)
	at java.util.concurrent.Executors$RunnableAdapter.call(Executors.java:511)
	at java.util.concurrent.FutureTask.run(FutureTask.java:266)
	at java.util.concurrent.ThreadPoolExecutor.runWorker(ThreadPoolExecutor.java:1142)
	at java.util.concurrent.ThreadPoolExecutor$Worker.run(ThreadPoolExecutor.java:617)
	at java.lang.Thread.run(Thread.java:745)
Caused by: org.testng.TestException: 
Method TestSum.testSumExceptionIsThrown(long, long)[pri:0, instance:com.epam.calculator.testCalculator.baseOperations.TestSum@1af06fc] should have thrown an exception of class java.lang.Exception
	at org.testng.internal.Invoker.handleInvocationResults(Invoker.java:1512)
	at org.testng.internal.Invoker.invokeMethod(Invoker.java:754)
	at org.testng.internal.Invoker.invokeTestMethod(Invoker.java:901)
	at org.testng.internal.TestMethodWithDataProviderMethodWorker.call(TestMethodWithDataProviderMethodWorker.java:73)
	... 7 more
]]>
    </failure>
  </testcase> <!-- testSumExceptionIsThrown -->
  <testcase name="testSumPassLong" time="0.003" classname="com.epam.calculator.testCalculator.baseOperations.TestSum"/>
  <testcase name="testSumFailLong" time="0.001" classname="com.epam.calculator.testCalculator.baseOperations.TestSum"/>
  <testcase name="testSumFailLong" time="0.000" classname="com.epam.calculator.testCalculator.baseOperations.TestSum"/>
  <testcase name="testSumPassLong" time="0.001" classname="com.epam.calculator.testCalculator.baseOperations.TestSum"/>
  <testcase name="testSumPassLong" time="0.000" classname="com.epam.calculator.testCalculator.baseOperations.TestSum"/>
  <testcase name="testSumPassLong" time="0.001" classname="com.epam.calculator.testCalculator.baseOperations.TestSum"/>
  <testcase name="testSumExceptionIsThrown" time="0.000" classname="com.epam.calculator.testCalculator.baseOperations.TestSum">
    <failure type="org.testng.TestException" message="
Expected exception java.lang.Exception but got org.testng.TestException: 
Method TestSum.testSumExceptionIsThrown(long, long)[pri:0, instance:com.epam.calculator.testCalculator.baseOperations.TestSum@1af06fc] should have thrown an exception of class java.lang.Exception">
      <![CDATA[org.testng.TestException: 
Expected exception java.lang.Exception but got org.testng.TestException: 
Method TestSum.testSumExceptionIsThrown(long, long)[pri:0, instance:com.epam.calculator.testCalculator.baseOperations.TestSum@1af06fc] should have thrown an exception of class java.lang.Exception
	at org.testng.internal.Invoker.handleInvocationResults(Invoker.java:1497)
	at org.testng.internal.TestMethodWithDataProviderMethodWorker.call(TestMethodWithDataProviderMethodWorker.java:87)
	at org.testng.internal.TestMethodWithDataProviderMethodWorker.call(TestMethodWithDataProviderMethodWorker.java:14)
	at java.util.concurrent.FutureTask.run(FutureTask.java:266)
	at java.util.concurrent.Executors$RunnableAdapter.call(Executors.java:511)
	at java.util.concurrent.FutureTask.run(FutureTask.java:266)
	at java.util.concurrent.ThreadPoolExecutor.runWorker(ThreadPoolExecutor.java:1142)
	at java.util.concurrent.ThreadPoolExecutor$Worker.run(ThreadPoolExecutor.java:617)
	at java.lang.Thread.run(Thread.java:745)
Caused by: org.testng.TestException: 
Method TestSum.testSumExceptionIsThrown(long, long)[pri:0, instance:com.epam.calculator.testCalculator.baseOperations.TestSum@1af06fc] should have thrown an exception of class java.lang.Exception
	at org.testng.internal.Invoker.handleInvocationResults(Invoker.java:1512)
	at org.testng.internal.Invoker.invokeMethod(Invoker.java:754)
	at org.testng.internal.Invoker.invokeTestMethod(Invoker.java:901)
	at org.testng.internal.TestMethodWithDataProviderMethodWorker.call(TestMethodWithDataProviderMethodWorker.java:73)
	... 7 more
]]>
    </failure>
  </testcase> <!-- testSumExceptionIsThrown -->
  <testcase name="testSumPassLong" time="0.001" classname="com.epam.calculator.testCalculator.baseOperations.TestSum"/>
  <testcase name="testSumFailLong" time="0.000" classname="com.epam.calculator.testCalculator.baseOperations.TestSum"/>
  <testcase name="testSumFailLong" time="0.001" classname="com.epam.calculator.testCalculator.baseOperations.TestSum"/>
  <testcase name="testSumPassLong" time="0.000" classname="com.epam.calculator.testCalculator.baseOperations.TestSum"/>
  <testcase name="testSumExceptionIsThrown" time="0.000" classname="com.epam.calculator.testCalculator.baseOperations.TestSum">
    <failure type="org.testng.TestException" message="
Expected exception java.lang.Exception but got org.testng.TestException: 
Method TestSum.testSumExceptionIsThrown(long, long)[pri:0, instance:com.epam.calculator.testCalculator.baseOperations.TestSum@1af06fc] should have thrown an exception of class java.lang.Exception">
      <![CDATA[org.testng.TestException: 
Expected exception java.lang.Exception but got org.testng.TestException: 
Method TestSum.testSumExceptionIsThrown(long, long)[pri:0, instance:com.epam.calculator.testCalculator.baseOperations.TestSum@1af06fc] should have thrown an exception of class java.lang.Exception
	at org.testng.internal.Invoker.handleInvocationResults(Invoker.java:1497)
	at org.testng.internal.TestMethodWithDataProviderMethodWorker.call(TestMethodWithDataProviderMethodWorker.java:87)
	at org.testng.internal.TestMethodWithDataProviderMethodWorker.call(TestMethodWithDataProviderMethodWorker.java:14)
	at java.util.concurrent.FutureTask.run(FutureTask.java:266)
	at java.util.concurrent.Executors$RunnableAdapter.call(Executors.java:511)
	at java.util.concurrent.FutureTask.run(FutureTask.java:266)
	at java.util.concurrent.ThreadPoolExecutor.runWorker(ThreadPoolExecutor.java:1142)
	at java.util.concurrent.ThreadPoolExecutor$Worker.run(ThreadPoolExecutor.java:617)
	at java.lang.Thread.run(Thread.java:745)
Caused by: org.testng.TestException: 
Method TestSum.testSumExceptionIsThrown(long, long)[pri:0, instance:com.epam.calculator.testCalculator.baseOperations.TestSum@1af06fc] should have thrown an exception of class java.lang.Exception
	at org.testng.internal.Invoker.handleInvocationResults(Invoker.java:1512)
	at org.testng.internal.Invoker.invokeMethod(Invoker.java:754)
	at org.testng.internal.Invoker.invokeTestMethod(Invoker.java:901)
	at org.testng.internal.TestMethodWithDataProviderMethodWorker.call(TestMethodWithDataProviderMethodWorker.java:73)
	... 7 more
]]>
    </failure>
  </testcase> <!-- testSumExceptionIsThrown -->
  <testcase name="testSumPassLong" time="0.001" classname="com.epam.calculator.testCalculator.baseOperations.TestSum"/>
  <testcase name="testSumPassLong" time="0.000" classname="com.epam.calculator.testCalculator.baseOperations.TestSum"/>
  <testcase name="testSumPassLong" time="0.000" classname="com.epam.calculator.testCalculator.baseOperations.TestSum"/>
  <testcase name="testSumFailLong" time="0.000" classname="com.epam.calculator.testCalculator.baseOperations.TestSum"/>
  <testcase name="testSumExceptionIsThrown" time="0.001" classname="com.epam.calculator.testCalculator.baseOperations.TestSum">
    <failure type="org.testng.TestException" message="
Expected exception java.lang.Exception but got org.testng.TestException: 
Method TestSum.testSumExceptionIsThrown(long, long)[pri:0, instance:com.epam.calculator.testCalculator.baseOperations.TestSum@50a6f6] should have thrown an exception of class java.lang.Exception">
      <![CDATA[org.testng.TestException: 
Expected exception java.lang.Exception but got org.testng.TestException: 
Method TestSum.testSumExceptionIsThrown(long, long)[pri:0, instance:com.epam.calculator.testCalculator.baseOperations.TestSum@50a6f6] should have thrown an exception of class java.lang.Exception
	at org.testng.internal.Invoker.handleInvocationResults(Invoker.java:1497)
	at org.testng.internal.TestMethodWithDataProviderMethodWorker.call(TestMethodWithDataProviderMethodWorker.java:87)
	at org.testng.internal.TestMethodWithDataProviderMethodWorker.call(TestMethodWithDataProviderMethodWorker.java:14)
	at java.util.concurrent.FutureTask.run(FutureTask.java:266)
	at java.util.concurrent.Executors$RunnableAdapter.call(Executors.java:511)
	at java.util.concurrent.FutureTask.run(FutureTask.java:266)
	at java.util.concurrent.ThreadPoolExecutor.runWorker(ThreadPoolExecutor.java:1142)
	at java.util.concurrent.ThreadPoolExecutor$Worker.run(ThreadPoolExecutor.java:617)
	at java.lang.Thread.run(Thread.java:745)
Caused by: org.testng.TestException: 
Method TestSum.testSumExceptionIsThrown(long, long)[pri:0, instance:com.epam.calculator.testCalculator.baseOperations.TestSum@50a6f6] should have thrown an exception of class java.lang.Exception
	at org.testng.internal.Invoker.handleInvocationResults(Invoker.java:1512)
	at org.testng.internal.Invoker.invokeMethod(Invoker.java:754)
	at org.testng.internal.Invoker.invokeTestMethod(Invoker.java:901)
	at org.testng.internal.TestMethodWithDataProviderMethodWorker.call(TestMethodWithDataProviderMethodWorker.java:73)
	... 7 more
]]>
    </failure>
  </testcase> <!-- testSumExceptionIsThrown -->
  <testcase name="testSumExceptionIsThrown" time="0.001" classname="com.epam.calculator.testCalculator.baseOperations.TestSum">
    <failure type="org.testng.TestException" message="
Expected exception java.lang.Exception but got org.testng.TestException: 
Method TestSum.testSumExceptionIsThrown(long, long)[pri:0, instance:com.epam.calculator.testCalculator.baseOperations.TestSum@50a6f6] should have thrown an exception of class java.lang.Exception">
      <![CDATA[org.testng.TestException: 
Expected exception java.lang.Exception but got org.testng.TestException: 
Method TestSum.testSumExceptionIsThrown(long, long)[pri:0, instance:com.epam.calculator.testCalculator.baseOperations.TestSum@50a6f6] should have thrown an exception of class java.lang.Exception
	at org.testng.internal.Invoker.handleInvocationResults(Invoker.java:1497)
	at org.testng.internal.TestMethodWithDataProviderMethodWorker.call(TestMethodWithDataProviderMethodWorker.java:87)
	at org.testng.internal.TestMethodWithDataProviderMethodWorker.call(TestMethodWithDataProviderMethodWorker.java:14)
	at java.util.concurrent.FutureTask.run(FutureTask.java:266)
	at java.util.concurrent.Executors$RunnableAdapter.call(Executors.java:511)
	at java.util.concurrent.FutureTask.run(FutureTask.java:266)
	at java.util.concurrent.ThreadPoolExecutor.runWorker(ThreadPoolExecutor.java:1142)
	at java.util.concurrent.ThreadPoolExecutor$Worker.run(ThreadPoolExecutor.java:617)
	at java.lang.Thread.run(Thread.java:745)
Caused by: org.testng.TestException: 
Method TestSum.testSumExceptionIsThrown(long, long)[pri:0, instance:com.epam.calculator.testCalculator.baseOperations.TestSum@50a6f6] should have thrown an exception of class java.lang.Exception
	at org.testng.internal.Invoker.handleInvocationResults(Invoker.java:1512)
	at org.testng.internal.Invoker.invokeMethod(Invoker.java:754)
	at org.testng.internal.Invoker.invokeTestMethod(Invoker.java:901)
	at org.testng.internal.TestMethodWithDataProviderMethodWorker.call(TestMethodWithDataProviderMethodWorker.java:73)
	... 7 more
]]>
    </failure>
  </testcase> <!-- testSumExceptionIsThrown -->
  <testcase name="testSumPassLong" time="0.001" classname="com.epam.calculator.testCalculator.baseOperations.TestSum"/>
  <testcase name="testSumPassLong" time="0.000" classname="com.epam.calculator.testCalculator.baseOperations.TestSum"/>
  <testcase name="testSumPassLong" time="0.000" classname="com.epam.calculator.testCalculator.baseOperations.TestSum"/>
  <testcase name="testSumFailLong" time="0.000" classname="com.epam.calculator.testCalculator.baseOperations.TestSum"/>
  <testcase name="testSumExceptionIsThrown" time="0.001" classname="com.epam.calculator.testCalculator.baseOperations.TestSum">
    <failure type="org.testng.TestException" message="
Expected exception java.lang.Exception but got org.testng.TestException: 
Method TestSum.testSumExceptionIsThrown(long, long)[pri:0, instance:com.epam.calculator.testCalculator.baseOperations.TestSum@1af06fc] should have thrown an exception of class java.lang.Exception">
      <![CDATA[org.testng.TestException: 
Expected exception java.lang.Exception but got org.testng.TestException: 
Method TestSum.testSumExceptionIsThrown(long, long)[pri:0, instance:com.epam.calculator.testCalculator.baseOperations.TestSum@1af06fc] should have thrown an exception of class java.lang.Exception
	at org.testng.internal.Invoker.handleInvocationResults(Invoker.java:1497)
	at org.testng.internal.TestMethodWithDataProviderMethodWorker.call(TestMethodWithDataProviderMethodWorker.java:87)
	at org.testng.internal.TestMethodWithDataProviderMethodWorker.call(TestMethodWithDataProviderMethodWorker.java:14)
	at java.util.concurrent.FutureTask.run(FutureTask.java:266)
	at java.util.concurrent.Executors$RunnableAdapter.call(Executors.java:511)
	at java.util.concurrent.FutureTask.run(FutureTask.java:266)
	at java.util.concurrent.ThreadPoolExecutor.runWorker(ThreadPoolExecutor.java:1142)
	at java.util.concurrent.ThreadPoolExecutor$Worker.run(ThreadPoolExecutor.java:617)
	at java.lang.Thread.run(Thread.java:745)
Caused by: org.testng.TestException: 
Method TestSum.testSumExceptionIsThrown(long, long)[pri:0, instance:com.epam.calculator.testCalculator.baseOperations.TestSum@1af06fc] should have thrown an exception of class java.lang.Exception
	at org.testng.internal.Invoker.handleInvocationResults(Invoker.java:1512)
	at org.testng.internal.Invoker.invokeMethod(Invoker.java:754)
	at org.testng.internal.Invoker.invokeTestMethod(Invoker.java:901)
	at org.testng.internal.TestMethodWithDataProviderMethodWorker.call(TestMethodWithDataProviderMethodWorker.java:73)
	... 7 more
]]>
    </failure>
  </testcase> <!-- testSumExceptionIsThrown -->
  <testcase name="testSumPassLong" time="0.000" classname="com.epam.calculator.testCalculator.baseOperations.TestSum"/>
  <testcase name="testSumPassLong" time="0.001" classname="com.epam.calculator.testCalculator.baseOperations.TestSum"/>
  <testcase name="testSumExceptionIsThrown" time="0.002" classname="com.epam.calculator.testCalculator.baseOperations.TestSum">
    <failure type="org.testng.TestException" message="
Expected exception java.lang.Exception but got org.testng.TestException: 
Method TestSum.testSumExceptionIsThrown(long, long)[pri:0, instance:com.epam.calculator.testCalculator.baseOperations.TestSum@11c311e] should have thrown an exception of class java.lang.Exception">
      <![CDATA[org.testng.TestException: 
Expected exception java.lang.Exception but got org.testng.TestException: 
Method TestSum.testSumExceptionIsThrown(long, long)[pri:0, instance:com.epam.calculator.testCalculator.baseOperations.TestSum@11c311e] should have thrown an exception of class java.lang.Exception
	at org.testng.internal.Invoker.handleInvocationResults(Invoker.java:1497)
	at org.testng.internal.TestMethodWithDataProviderMethodWorker.call(TestMethodWithDataProviderMethodWorker.java:87)
	at org.testng.internal.TestMethodWithDataProviderMethodWorker.call(TestMethodWithDataProviderMethodWorker.java:14)
	at java.util.concurrent.FutureTask.run(FutureTask.java:266)
	at java.util.concurrent.Executors$RunnableAdapter.call(Executors.java:511)
	at java.util.concurrent.FutureTask.run(FutureTask.java:266)
	at java.util.concurrent.ThreadPoolExecutor.runWorker(ThreadPoolExecutor.java:1142)
	at java.util.concurrent.ThreadPoolExecutor$Worker.run(ThreadPoolExecutor.java:617)
	at java.lang.Thread.run(Thread.java:745)
Caused by: org.testng.TestException: 
Method TestSum.testSumExceptionIsThrown(long, long)[pri:0, instance:com.epam.calculator.testCalculator.baseOperations.TestSum@11c311e] should have thrown an exception of class java.lang.Exception
	at org.testng.internal.Invoker.handleInvocationResults(Invoker.java:1512)
	at org.testng.internal.Invoker.invokeMethod(Invoker.java:754)
	at org.testng.internal.Invoker.invokeTestMethod(Invoker.java:901)
	at org.testng.internal.TestMethodWithDataProviderMethodWorker.call(TestMethodWithDataProviderMethodWorker.java:73)
	... 7 more
]]>
    </failure>
  </testcase> <!-- testSumExceptionIsThrown -->
  <testcase name="testSumPassLong" time="0.001" classname="com.epam.calculator.testCalculator.baseOperations.TestSum"/>
  <testcase name="testSumPassLong" time="0.001" classname="com.epam.calculator.testCalculator.baseOperations.TestSum"/>
  <testcase name="testSumFailLong" time="0.000" classname="com.epam.calculator.testCalculator.baseOperations.TestSum"/>
  <testcase name="testSumFailLong" time="0.000" classname="com.epam.calculator.testCalculator.baseOperations.TestSum"/>
  <testcase name="testSumPassLong" time="0.000" classname="com.epam.calculator.testCalculator.baseOperations.TestSum"/>
  <testcase name="testSumFailLong" time="0.000" classname="com.epam.calculator.testCalculator.baseOperations.TestSum"/>
  <testcase name="testSumPassLong" time="0.001" classname="com.epam.calculator.testCalculator.baseOperations.TestSum"/>
  <testcase name="testSumExceptionIsThrown" time="0.000" classname="com.epam.calculator.testCalculator.baseOperations.TestSum">
    <failure type="org.testng.TestException" message="
Expected exception java.lang.Exception but got org.testng.TestException: 
Method TestSum.testSumExceptionIsThrown(long, long)[pri:0, instance:com.epam.calculator.testCalculator.baseOperations.TestSum@1af06fc] should have thrown an exception of class java.lang.Exception">
      <![CDATA[org.testng.TestException: 
Expected exception java.lang.Exception but got org.testng.TestException: 
Method TestSum.testSumExceptionIsThrown(long, long)[pri:0, instance:com.epam.calculator.testCalculator.baseOperations.TestSum@1af06fc] should have thrown an exception of class java.lang.Exception
	at org.testng.internal.Invoker.handleInvocationResults(Invoker.java:1497)
	at org.testng.internal.TestMethodWithDataProviderMethodWorker.call(TestMethodWithDataProviderMethodWorker.java:87)
	at org.testng.internal.TestMethodWithDataProviderMethodWorker.call(TestMethodWithDataProviderMethodWorker.java:14)
	at java.util.concurrent.FutureTask.run(FutureTask.java:266)
	at java.util.concurrent.Executors$RunnableAdapter.call(Executors.java:511)
	at java.util.concurrent.FutureTask.run(FutureTask.java:266)
	at java.util.concurrent.ThreadPoolExecutor.runWorker(ThreadPoolExecutor.java:1142)
	at java.util.concurrent.ThreadPoolExecutor$Worker.run(ThreadPoolExecutor.java:617)
	at java.lang.Thread.run(Thread.java:745)
Caused by: org.testng.TestException: 
Method TestSum.testSumExceptionIsThrown(long, long)[pri:0, instance:com.epam.calculator.testCalculator.baseOperations.TestSum@1af06fc] should have thrown an exception of class java.lang.Exception
	at org.testng.internal.Invoker.handleInvocationResults(Invoker.java:1512)
	at org.testng.internal.Invoker.invokeMethod(Invoker.java:754)
	at org.testng.internal.Invoker.invokeTestMethod(Invoker.java:901)
	at org.testng.internal.TestMethodWithDataProviderMethodWorker.call(TestMethodWithDataProviderMethodWorker.java:73)
	... 7 more
]]>
    </failure>
  </testcase> <!-- testSumExceptionIsThrown -->
  <testcase name="testSumPassLong" time="0.001" classname="com.epam.calculator.testCalculator.baseOperations.TestSum"/>
  <testcase name="testSumExceptionIsThrown" time="0.001" classname="com.epam.calculator.testCalculator.baseOperations.TestSum">
    <failure type="org.testng.TestException" message="
Expected exception java.lang.Exception but got org.testng.TestException: 
Method TestSum.testSumExceptionIsThrown(long, long)[pri:0, instance:com.epam.calculator.testCalculator.baseOperations.TestSum@11c311e] should have thrown an exception of class java.lang.Exception">
      <![CDATA[org.testng.TestException: 
Expected exception java.lang.Exception but got org.testng.TestException: 
Method TestSum.testSumExceptionIsThrown(long, long)[pri:0, instance:com.epam.calculator.testCalculator.baseOperations.TestSum@11c311e] should have thrown an exception of class java.lang.Exception
	at org.testng.internal.Invoker.handleInvocationResults(Invoker.java:1497)
	at org.testng.internal.TestMethodWithDataProviderMethodWorker.call(TestMethodWithDataProviderMethodWorker.java:87)
	at org.testng.internal.TestMethodWithDataProviderMethodWorker.call(TestMethodWithDataProviderMethodWorker.java:14)
	at java.util.concurrent.FutureTask.run(FutureTask.java:266)
	at java.util.concurrent.Executors$RunnableAdapter.call(Executors.java:511)
	at java.util.concurrent.FutureTask.run(FutureTask.java:266)
	at java.util.concurrent.ThreadPoolExecutor.runWorker(ThreadPoolExecutor.java:1142)
	at java.util.concurrent.ThreadPoolExecutor$Worker.run(ThreadPoolExecutor.java:617)
	at java.lang.Thread.run(Thread.java:745)
Caused by: org.testng.TestException: 
Method TestSum.testSumExceptionIsThrown(long, long)[pri:0, instance:com.epam.calculator.testCalculator.baseOperations.TestSum@11c311e] should have thrown an exception of class java.lang.Exception
	at org.testng.internal.Invoker.handleInvocationResults(Invoker.java:1512)
	at org.testng.internal.Invoker.invokeMethod(Invoker.java:754)
	at org.testng.internal.Invoker.invokeTestMethod(Invoker.java:901)
	at org.testng.internal.TestMethodWithDataProviderMethodWorker.call(TestMethodWithDataProviderMethodWorker.java:73)
	... 7 more
]]>
    </failure>
  </testcase> <!-- testSumExceptionIsThrown -->
  <testcase name="testSumFailLong" time="0.000" classname="com.epam.calculator.testCalculator.baseOperations.TestSum"/>
  <testcase name="testSumPassLong" time="0.001" classname="com.epam.calculator.testCalculator.baseOperations.TestSum"/>
  <testcase name="testSumFailLong" time="0.000" classname="com.epam.calculator.testCalculator.baseOperations.TestSum"/>
  <testcase name="testSumPassLong" time="0.000" classname="com.epam.calculator.testCalculator.baseOperations.TestSum"/>
  <testcase name="testSumPassLong" time="0.000" classname="com.epam.calculator.testCalculator.baseOperations.TestSum"/>
  <testcase name="testSumPassLong" time="0.000" classname="com.epam.calculator.testCalculator.baseOperations.TestSum"/>
  <testcase name="testSumPassLong" time="0.001" classname="com.epam.calculator.testCalculator.baseOperations.TestSum"/>
  <testcase name="testSumFailLong" time="0.001" classname="com.epam.calculator.testCalculator.baseOperations.TestSum"/>
  <testcase name="testSumExceptionIsThrown" time="0.001" classname="com.epam.calculator.testCalculator.baseOperations.TestSum">
    <failure type="org.testng.TestException" message="
Expected exception java.lang.Exception but got org.testng.TestException: 
Method TestSum.testSumExceptionIsThrown(long, long)[pri:0, instance:com.epam.calculator.testCalculator.baseOperations.TestSum@50a6f6] should have thrown an exception of class java.lang.Exception">
      <![CDATA[org.testng.TestException: 
Expected exception java.lang.Exception but got org.testng.TestException: 
Method TestSum.testSumExceptionIsThrown(long, long)[pri:0, instance:com.epam.calculator.testCalculator.baseOperations.TestSum@50a6f6] should have thrown an exception of class java.lang.Exception
	at org.testng.internal.Invoker.handleInvocationResults(Invoker.java:1497)
	at org.testng.internal.TestMethodWithDataProviderMethodWorker.call(TestMethodWithDataProviderMethodWorker.java:87)
	at org.testng.internal.TestMethodWithDataProviderMethodWorker.call(TestMethodWithDataProviderMethodWorker.java:14)
	at java.util.concurrent.FutureTask.run(FutureTask.java:266)
	at java.util.concurrent.Executors$RunnableAdapter.call(Executors.java:511)
	at java.util.concurrent.FutureTask.run(FutureTask.java:266)
	at java.util.concurrent.ThreadPoolExecutor.runWorker(ThreadPoolExecutor.java:1142)
	at java.util.concurrent.ThreadPoolExecutor$Worker.run(ThreadPoolExecutor.java:617)
	at java.lang.Thread.run(Thread.java:745)
Caused by: org.testng.TestException: 
Method TestSum.testSumExceptionIsThrown(long, long)[pri:0, instance:com.epam.calculator.testCalculator.baseOperations.TestSum@50a6f6] should have thrown an exception of class java.lang.Exception
	at org.testng.internal.Invoker.handleInvocationResults(Invoker.java:1512)
	at org.testng.internal.Invoker.invokeMethod(Invoker.java:754)
	at org.testng.internal.Invoker.invokeTestMethod(Invoker.java:901)
	at org.testng.internal.TestMethodWithDataProviderMethodWorker.call(TestMethodWithDataProviderMethodWorker.java:73)
	... 7 more
]]>
    </failure>
  </testcase> <!-- testSumExceptionIsThrown -->
  <testcase name="testSumPassLong" time="0.000" classname="com.epam.calculator.testCalculator.baseOperations.TestSum"/>
  <testcase name="testSumPassLong" time="0.001" classname="com.epam.calculator.testCalculator.baseOperations.TestSum"/>
  <testcase name="testSumPassLong" time="0.000" classname="com.epam.calculator.testCalculator.baseOperations.TestSum"/>
  <testcase name="testSumPassLong" time="0.003" classname="com.epam.calculator.testCalculator.baseOperations.TestSum"/>
  <testcase name="testSumPassLong" time="0.003" classname="com.epam.calculator.testCalculator.baseOperations.TestSum"/>
  <testcase name="testSumPassLong" time="0.001" classname="com.epam.calculator.testCalculator.baseOperations.TestSum"/>
  <testcase name="testSumFailLong" time="0.000" classname="com.epam.calculator.testCalculator.baseOperations.TestSum"/>
  <testcase name="testSumExceptionIsThrown" time="0.006" classname="com.epam.calculator.testCalculator.baseOperations.TestSum">
    <failure type="org.testng.TestException" message="
Expected exception java.lang.Exception but got org.testng.TestException: 
Method TestSum.testSumExceptionIsThrown(long, long)[pri:0, instance:com.epam.calculator.testCalculator.baseOperations.TestSum@11c311e] should have thrown an exception of class java.lang.Exception">
      <![CDATA[org.testng.TestException: 
Expected exception java.lang.Exception but got org.testng.TestException: 
Method TestSum.testSumExceptionIsThrown(long, long)[pri:0, instance:com.epam.calculator.testCalculator.baseOperations.TestSum@11c311e] should have thrown an exception of class java.lang.Exception
	at org.testng.internal.Invoker.handleInvocationResults(Invoker.java:1497)
	at org.testng.internal.TestMethodWithDataProviderMethodWorker.call(TestMethodWithDataProviderMethodWorker.java:87)
	at org.testng.internal.TestMethodWithDataProviderMethodWorker.call(TestMethodWithDataProviderMethodWorker.java:14)
	at java.util.concurrent.FutureTask.run(FutureTask.java:266)
	at java.util.concurrent.Executors$RunnableAdapter.call(Executors.java:511)
	at java.util.concurrent.FutureTask.run(FutureTask.java:266)
	at java.util.concurrent.ThreadPoolExecutor.runWorker(ThreadPoolExecutor.java:1142)
	at java.util.concurrent.ThreadPoolExecutor$Worker.run(ThreadPoolExecutor.java:617)
	at java.lang.Thread.run(Thread.java:745)
Caused by: org.testng.TestException: 
Method TestSum.testSumExceptionIsThrown(long, long)[pri:0, instance:com.epam.calculator.testCalculator.baseOperations.TestSum@11c311e] should have thrown an exception of class java.lang.Exception
	at org.testng.internal.Invoker.handleInvocationResults(Invoker.java:1512)
	at org.testng.internal.Invoker.invokeMethod(Invoker.java:754)
	at org.testng.internal.Invoker.invokeTestMethod(Invoker.java:901)
	at org.testng.internal.TestMethodWithDataProviderMethodWorker.call(TestMethodWithDataProviderMethodWorker.java:73)
	... 7 more
]]>
    </failure>
  </testcase> <!-- testSumExceptionIsThrown -->
  <testcase name="testSumFailLong" time="0.002" classname="com.epam.calculator.testCalculator.baseOperations.TestSum"/>
  <testcase name="testSumPassLong" time="0.000" classname="com.epam.calculator.testCalculator.baseOperations.TestSum"/>
  <testcase name="testSumPassLong" time="0.000" classname="com.epam.calculator.testCalculator.baseOperations.TestSum"/>
  <testcase name="testSumFailLong" time="0.000" classname="com.epam.calculator.testCalculator.baseOperations.TestSum"/>
  <testcase name="testSumPassLong" time="0.001" classname="com.epam.calculator.testCalculator.baseOperations.TestSum"/>
  <testcase name="testSumFailLong" time="0.000" classname="com.epam.calculator.testCalculator.baseOperations.TestSum"/>
  <testcase name="testSumPassLong" time="0.000" classname="com.epam.calculator.testCalculator.baseOperations.TestSum"/>
  <testcase name="testSumFailLong" time="0.001" classname="com.epam.calculator.testCalculator.baseOperations.TestSum"/>
  <testcase name="testSumPassLong" time="0.000" classname="com.epam.calculator.testCalculator.baseOperations.TestSum"/>
  <testcase name="testSumPassLong" time="0.001" classname="com.epam.calculator.testCalculator.baseOperations.TestSum"/>
  <testcase name="testSumExceptionIsThrown" time="0.001" classname="com.epam.calculator.testCalculator.baseOperations.TestSum">
    <failure type="org.testng.TestException" message="
Expected exception java.lang.Exception but got org.testng.TestException: 
Method TestSum.testSumExceptionIsThrown(long, long)[pri:0, instance:com.epam.calculator.testCalculator.baseOperations.TestSum@50a6f6] should have thrown an exception of class java.lang.Exception">
      <![CDATA[org.testng.TestException: 
Expected exception java.lang.Exception but got org.testng.TestException: 
Method TestSum.testSumExceptionIsThrown(long, long)[pri:0, instance:com.epam.calculator.testCalculator.baseOperations.TestSum@50a6f6] should have thrown an exception of class java.lang.Exception
	at org.testng.internal.Invoker.handleInvocationResults(Invoker.java:1497)
	at org.testng.internal.TestMethodWithDataProviderMethodWorker.call(TestMethodWithDataProviderMethodWorker.java:87)
	at org.testng.internal.TestMethodWithDataProviderMethodWorker.call(TestMethodWithDataProviderMethodWorker.java:14)
	at java.util.concurrent.FutureTask.run(FutureTask.java:266)
	at java.util.concurrent.Executors$RunnableAdapter.call(Executors.java:511)
	at java.util.concurrent.FutureTask.run(FutureTask.java:266)
	at java.util.concurrent.ThreadPoolExecutor.runWorker(ThreadPoolExecutor.java:1142)
	at java.util.concurrent.ThreadPoolExecutor$Worker.run(ThreadPoolExecutor.java:617)
	at java.lang.Thread.run(Thread.java:745)
Caused by: org.testng.TestException: 
Method TestSum.testSumExceptionIsThrown(long, long)[pri:0, instance:com.epam.calculator.testCalculator.baseOperations.TestSum@50a6f6] should have thrown an exception of class java.lang.Exception
	at org.testng.internal.Invoker.handleInvocationResults(Invoker.java:1512)
	at org.testng.internal.Invoker.invokeMethod(Invoker.java:754)
	at org.testng.internal.Invoker.invokeTestMethod(Invoker.java:901)
	at org.testng.internal.TestMethodWithDataProviderMethodWorker.call(TestMethodWithDataProviderMethodWorker.java:73)
	... 7 more
]]>
    </failure>
  </testcase> <!-- testSumExceptionIsThrown -->
  <testcase name="testSumFailLong" time="0.000" classname="com.epam.calculator.testCalculator.baseOperations.TestSum"/>
  <testcase name="testSumFailLong" time="0.010" classname="com.epam.calculator.testCalculator.baseOperations.TestSum"/>
  <testcase name="testSumFailLong" time="0.000" classname="com.epam.calculator.testCalculator.baseOperations.TestSum"/>
  <testcase name="testSumExceptionIsThrown" time="0.000" classname="com.epam.calculator.testCalculator.baseOperations.TestSum">
    <failure type="org.testng.TestException" message="
Expected exception java.lang.Exception but got org.testng.TestException: 
Method TestSum.testSumExceptionIsThrown(long, long)[pri:0, instance:com.epam.calculator.testCalculator.baseOperations.TestSum@1af06fc] should have thrown an exception of class java.lang.Exception">
      <![CDATA[org.testng.TestException: 
Expected exception java.lang.Exception but got org.testng.TestException: 
Method TestSum.testSumExceptionIsThrown(long, long)[pri:0, instance:com.epam.calculator.testCalculator.baseOperations.TestSum@1af06fc] should have thrown an exception of class java.lang.Exception
	at org.testng.internal.Invoker.handleInvocationResults(Invoker.java:1497)
	at org.testng.internal.TestMethodWithDataProviderMethodWorker.call(TestMethodWithDataProviderMethodWorker.java:87)
	at org.testng.internal.TestMethodWithDataProviderMethodWorker.call(TestMethodWithDataProviderMethodWorker.java:14)
	at java.util.concurrent.FutureTask.run(FutureTask.java:266)
	at java.util.concurrent.Executors$RunnableAdapter.call(Executors.java:511)
	at java.util.concurrent.FutureTask.run(FutureTask.java:266)
	at java.util.concurrent.ThreadPoolExecutor.runWorker(ThreadPoolExecutor.java:1142)
	at java.util.concurrent.ThreadPoolExecutor$Worker.run(ThreadPoolExecutor.java:617)
	at java.lang.Thread.run(Thread.java:745)
Caused by: org.testng.TestException: 
Method TestSum.testSumExceptionIsThrown(long, long)[pri:0, instance:com.epam.calculator.testCalculator.baseOperations.TestSum@1af06fc] should have thrown an exception of class java.lang.Exception
	at org.testng.internal.Invoker.handleInvocationResults(Invoker.java:1512)
	at org.testng.internal.Invoker.invokeMethod(Invoker.java:754)
	at org.testng.internal.Invoker.invokeTestMethod(Invoker.java:901)
	at org.testng.internal.TestMethodWithDataProviderMethodWorker.call(TestMethodWithDataProviderMethodWorker.java:73)
	... 7 more
]]>
    </failure>
  </testcase> <!-- testSumExceptionIsThrown -->
  <testcase name="testSumExceptionIsThrown" time="0.000" classname="com.epam.calculator.testCalculator.baseOperations.TestSum">
    <failure type="org.testng.TestException" message="
Expected exception java.lang.Exception but got org.testng.TestException: 
Method TestSum.testSumExceptionIsThrown(long, long)[pri:0, instance:com.epam.calculator.testCalculator.baseOperations.TestSum@11c311e] should have thrown an exception of class java.lang.Exception">
      <![CDATA[org.testng.TestException: 
Expected exception java.lang.Exception but got org.testng.TestException: 
Method TestSum.testSumExceptionIsThrown(long, long)[pri:0, instance:com.epam.calculator.testCalculator.baseOperations.TestSum@11c311e] should have thrown an exception of class java.lang.Exception
	at org.testng.internal.Invoker.handleInvocationResults(Invoker.java:1497)
	at org.testng.internal.TestMethodWithDataProviderMethodWorker.call(TestMethodWithDataProviderMethodWorker.java:87)
	at org.testng.internal.TestMethodWithDataProviderMethodWorker.call(TestMethodWithDataProviderMethodWorker.java:14)
	at java.util.concurrent.FutureTask.run(FutureTask.java:266)
	at java.util.concurrent.Executors$RunnableAdapter.call(Executors.java:511)
	at java.util.concurrent.FutureTask.run(FutureTask.java:266)
	at java.util.concurrent.ThreadPoolExecutor.runWorker(ThreadPoolExecutor.java:1142)
	at java.util.concurrent.ThreadPoolExecutor$Worker.run(ThreadPoolExecutor.java:617)
	at java.lang.Thread.run(Thread.java:745)
Caused by: org.testng.TestException: 
Method TestSum.testSumExceptionIsThrown(long, long)[pri:0, instance:com.epam.calculator.testCalculator.baseOperations.TestSum@11c311e] should have thrown an exception of class java.lang.Exception
	at org.testng.internal.Invoker.handleInvocationResults(Invoker.java:1512)
	at org.testng.internal.Invoker.invokeMethod(Invoker.java:754)
	at org.testng.internal.Invoker.invokeTestMethod(Invoker.java:901)
	at org.testng.internal.TestMethodWithDataProviderMethodWorker.call(TestMethodWithDataProviderMethodWorker.java:73)
	... 7 more
]]>
    </failure>
  </testcase> <!-- testSumExceptionIsThrown -->
  <testcase name="testSumPassLong" time="0.000" classname="com.epam.calculator.testCalculator.baseOperations.TestSum"/>
  <testcase name="testSumPassLong" time="0.000" classname="com.epam.calculator.testCalculator.baseOperations.TestSum"/>
  <testcase name="testSumPassLong" time="0.000" classname="com.epam.calculator.testCalculator.baseOperations.TestSum"/>
  <testcase name="testSumFailLong" time="0.000" classname="com.epam.calculator.testCalculator.baseOperations.TestSum"/>
  <testcase name="testSumExceptionIsThrown" time="0.001" classname="com.epam.calculator.testCalculator.baseOperations.TestSum">
    <failure type="org.testng.TestException" message="
Expected exception java.lang.Exception but got org.testng.TestException: 
Method TestSum.testSumExceptionIsThrown(long, long)[pri:0, instance:com.epam.calculator.testCalculator.baseOperations.TestSum@11c311e] should have thrown an exception of class java.lang.Exception">
      <![CDATA[org.testng.TestException: 
Expected exception java.lang.Exception but got org.testng.TestException: 
Method TestSum.testSumExceptionIsThrown(long, long)[pri:0, instance:com.epam.calculator.testCalculator.baseOperations.TestSum@11c311e] should have thrown an exception of class java.lang.Exception
	at org.testng.internal.Invoker.handleInvocationResults(Invoker.java:1497)
	at org.testng.internal.TestMethodWithDataProviderMethodWorker.call(TestMethodWithDataProviderMethodWorker.java:87)
	at org.testng.internal.TestMethodWithDataProviderMethodWorker.call(TestMethodWithDataProviderMethodWorker.java:14)
	at java.util.concurrent.FutureTask.run(FutureTask.java:266)
	at java.util.concurrent.Executors$RunnableAdapter.call(Executors.java:511)
	at java.util.concurrent.FutureTask.run(FutureTask.java:266)
	at java.util.concurrent.ThreadPoolExecutor.runWorker(ThreadPoolExecutor.java:1142)
	at java.util.concurrent.ThreadPoolExecutor$Worker.run(ThreadPoolExecutor.java:617)
	at java.lang.Thread.run(Thread.java:745)
Caused by: org.testng.TestException: 
Method TestSum.testSumExceptionIsThrown(long, long)[pri:0, instance:com.epam.calculator.testCalculator.baseOperations.TestSum@11c311e] should have thrown an exception of class java.lang.Exception
	at org.testng.internal.Invoker.handleInvocationResults(Invoker.java:1512)
	at org.testng.internal.Invoker.invokeMethod(Invoker.java:754)
	at org.testng.internal.Invoker.invokeTestMethod(Invoker.java:901)
	at org.testng.internal.TestMethodWithDataProviderMethodWorker.call(TestMethodWithDataProviderMethodWorker.java:73)
	... 7 more
]]>
    </failure>
  </testcase> <!-- testSumExceptionIsThrown -->
  <testcase name="testSumPassLong" time="0.000" classname="com.epam.calculator.testCalculator.baseOperations.TestSum"/>
  <testcase name="testSumPassLong" time="0.001" classname="com.epam.calculator.testCalculator.baseOperations.TestSum"/>
  <testcase name="testSumFailLong" time="0.000" classname="com.epam.calculator.testCalculator.baseOperations.TestSum"/>
  <testcase name="testSumPassLong" time="0.001" classname="com.epam.calculator.testCalculator.baseOperations.TestSum"/>
  <testcase name="testSumExceptionIsThrown" time="0.001" classname="com.epam.calculator.testCalculator.baseOperations.TestSum">
    <failure type="org.testng.TestException" message="
Expected exception java.lang.Exception but got org.testng.TestException: 
Method TestSum.testSumExceptionIsThrown(long, long)[pri:0, instance:com.epam.calculator.testCalculator.baseOperations.TestSum@1af06fc] should have thrown an exception of class java.lang.Exception">
      <![CDATA[org.testng.TestException: 
Expected exception java.lang.Exception but got org.testng.TestException: 
Method TestSum.testSumExceptionIsThrown(long, long)[pri:0, instance:com.epam.calculator.testCalculator.baseOperations.TestSum@1af06fc] should have thrown an exception of class java.lang.Exception
	at org.testng.internal.Invoker.handleInvocationResults(Invoker.java:1497)
	at org.testng.internal.TestMethodWithDataProviderMethodWorker.call(TestMethodWithDataProviderMethodWorker.java:87)
	at org.testng.internal.TestMethodWithDataProviderMethodWorker.call(TestMethodWithDataProviderMethodWorker.java:14)
	at java.util.concurrent.FutureTask.run(FutureTask.java:266)
	at java.util.concurrent.Executors$RunnableAdapter.call(Executors.java:511)
	at java.util.concurrent.FutureTask.run(FutureTask.java:266)
	at java.util.concurrent.ThreadPoolExecutor.runWorker(ThreadPoolExecutor.java:1142)
	at java.util.concurrent.ThreadPoolExecutor$Worker.run(ThreadPoolExecutor.java:617)
	at java.lang.Thread.run(Thread.java:745)
Caused by: org.testng.TestException: 
Method TestSum.testSumExceptionIsThrown(long, long)[pri:0, instance:com.epam.calculator.testCalculator.baseOperations.TestSum@1af06fc] should have thrown an exception of class java.lang.Exception
	at org.testng.internal.Invoker.handleInvocationResults(Invoker.java:1512)
	at org.testng.internal.Invoker.invokeMethod(Invoker.java:754)
	at org.testng.internal.Invoker.invokeTestMethod(Invoker.java:901)
	at org.testng.internal.TestMethodWithDataProviderMethodWorker.call(TestMethodWithDataProviderMethodWorker.java:73)
	... 7 more
]]>
    </failure>
  </testcase> <!-- testSumExceptionIsThrown -->
  <testcase name="testSumFailLong" time="0.000" classname="com.epam.calculator.testCalculator.baseOperations.TestSum"/>
  <testcase name="testSumFailLong" time="0.001" classname="com.epam.calculator.testCalculator.baseOperations.TestSum"/>
  <testcase name="testSumPassLong" time="0.010" classname="com.epam.calculator.testCalculator.baseOperations.TestSum"/>
  <testcase name="testSumPassLong" time="0.000" classname="com.epam.calculator.testCalculator.baseOperations.TestSum"/>
  <testcase name="testSumPassLong" time="0.000" classname="com.epam.calculator.testCalculator.baseOperations.TestSum"/>
  <testcase name="testSumFailLong" time="0.000" classname="com.epam.calculator.testCalculator.baseOperations.TestSum"/>
  <testcase name="testSumPassLong" time="0.000" classname="com.epam.calculator.testCalculator.baseOperations.TestSum"/>
  <testcase name="testSumPassLong" time="0.001" classname="com.epam.calculator.testCalculator.baseOperations.TestSum"/>
  <testcase name="testSumFailLong" time="0.000" classname="com.epam.calculator.testCalculator.baseOperations.TestSum"/>
  <testcase name="testSumFailLong" time="0.001" classname="com.epam.calculator.testCalculator.baseOperations.TestSum"/>
  <testcase name="testSumExceptionIsThrown" time="0.000" classname="com.epam.calculator.testCalculator.baseOperations.TestSum">
    <failure type="org.testng.TestException" message="
Expected exception java.lang.Exception but got org.testng.TestException: 
Method TestSum.testSumExceptionIsThrown(long, long)[pri:0, instance:com.epam.calculator.testCalculator.baseOperations.TestSum@50a6f6] should have thrown an exception of class java.lang.Exception">
      <![CDATA[org.testng.TestException: 
Expected exception java.lang.Exception but got org.testng.TestException: 
Method TestSum.testSumExceptionIsThrown(long, long)[pri:0, instance:com.epam.calculator.testCalculator.baseOperations.TestSum@50a6f6] should have thrown an exception of class java.lang.Exception
	at org.testng.internal.Invoker.handleInvocationResults(Invoker.java:1497)
	at org.testng.internal.TestMethodWithDataProviderMethodWorker.call(TestMethodWithDataProviderMethodWorker.java:87)
	at org.testng.internal.TestMethodWithDataProviderMethodWorker.call(TestMethodWithDataProviderMethodWorker.java:14)
	at java.util.concurrent.FutureTask.run(FutureTask.java:266)
	at java.util.concurrent.Executors$RunnableAdapter.call(Executors.java:511)
	at java.util.concurrent.FutureTask.run(FutureTask.java:266)
	at java.util.concurrent.ThreadPoolExecutor.runWorker(ThreadPoolExecutor.java:1142)
	at java.util.concurrent.ThreadPoolExecutor$Worker.run(ThreadPoolExecutor.java:617)
	at java.lang.Thread.run(Thread.java:745)
Caused by: org.testng.TestException: 
Method TestSum.testSumExceptionIsThrown(long, long)[pri:0, instance:com.epam.calculator.testCalculator.baseOperations.TestSum@50a6f6] should have thrown an exception of class java.lang.Exception
	at org.testng.internal.Invoker.handleInvocationResults(Invoker.java:1512)
	at org.testng.internal.Invoker.invokeMethod(Invoker.java:754)
	at org.testng.internal.Invoker.invokeTestMethod(Invoker.java:901)
	at org.testng.internal.TestMethodWithDataProviderMethodWorker.call(TestMethodWithDataProviderMethodWorker.java:73)
	... 7 more
]]>
    </failure>
  </testcase> <!-- testSumExceptionIsThrown -->
  <testcase name="testSumExceptionIsThrown" time="0.001" classname="com.epam.calculator.testCalculator.baseOperations.TestSum">
    <failure type="org.testng.TestException" message="
Expected exception java.lang.Exception but got org.testng.TestException: 
Method TestSum.testSumExceptionIsThrown(long, long)[pri:0, instance:com.epam.calculator.testCalculator.baseOperations.TestSum@50a6f6] should have thrown an exception of class java.lang.Exception">
      <![CDATA[org.testng.TestException: 
Expected exception java.lang.Exception but got org.testng.TestException: 
Method TestSum.testSumExceptionIsThrown(long, long)[pri:0, instance:com.epam.calculator.testCalculator.baseOperations.TestSum@50a6f6] should have thrown an exception of class java.lang.Exception
	at org.testng.internal.Invoker.handleInvocationResults(Invoker.java:1497)
	at org.testng.internal.TestMethodWithDataProviderMethodWorker.call(TestMethodWithDataProviderMethodWorker.java:87)
	at org.testng.internal.TestMethodWithDataProviderMethodWorker.call(TestMethodWithDataProviderMethodWorker.java:14)
	at java.util.concurrent.FutureTask.run(FutureTask.java:266)
	at java.util.concurrent.Executors$RunnableAdapter.call(Executors.java:511)
	at java.util.concurrent.FutureTask.run(FutureTask.java:266)
	at java.util.concurrent.ThreadPoolExecutor.runWorker(ThreadPoolExecutor.java:1142)
	at java.util.concurrent.ThreadPoolExecutor$Worker.run(ThreadPoolExecutor.java:617)
	at java.lang.Thread.run(Thread.java:745)
Caused by: org.testng.TestException: 
Method TestSum.testSumExceptionIsThrown(long, long)[pri:0, instance:com.epam.calculator.testCalculator.baseOperations.TestSum@50a6f6] should have thrown an exception of class java.lang.Exception
	at org.testng.internal.Invoker.handleInvocationResults(Invoker.java:1512)
	at org.testng.internal.Invoker.invokeMethod(Invoker.java:754)
	at org.testng.internal.Invoker.invokeTestMethod(Invoker.java:901)
	at org.testng.internal.TestMethodWithDataProviderMethodWorker.call(TestMethodWithDataProviderMethodWorker.java:73)
	... 7 more
]]>
    </failure>
  </testcase> <!-- testSumExceptionIsThrown -->
  <testcase name="testSumPassLong" time="0.000" classname="com.epam.calculator.testCalculator.baseOperations.TestSum"/>
  <testcase name="testSumFailLong" time="0.000" classname="com.epam.calculator.testCalculator.baseOperations.TestSum"/>
  <testcase name="testSumPassLong" time="0.000" classname="com.epam.calculator.testCalculator.baseOperations.TestSum"/>
  <testcase name="testSumExceptionIsThrown" time="0.000" classname="com.epam.calculator.testCalculator.baseOperations.TestSum">
    <failure type="org.testng.TestException" message="
Expected exception java.lang.Exception but got org.testng.TestException: 
Method TestSum.testSumExceptionIsThrown(long, long)[pri:0, instance:com.epam.calculator.testCalculator.baseOperations.TestSum@50a6f6] should have thrown an exception of class java.lang.Exception">
      <![CDATA[org.testng.TestException: 
Expected exception java.lang.Exception but got org.testng.TestException: 
Method TestSum.testSumExceptionIsThrown(long, long)[pri:0, instance:com.epam.calculator.testCalculator.baseOperations.TestSum@50a6f6] should have thrown an exception of class java.lang.Exception
	at org.testng.internal.Invoker.handleInvocationResults(Invoker.java:1497)
	at org.testng.internal.TestMethodWithDataProviderMethodWorker.call(TestMethodWithDataProviderMethodWorker.java:87)
	at org.testng.internal.TestMethodWithDataProviderMethodWorker.call(TestMethodWithDataProviderMethodWorker.java:14)
	at java.util.concurrent.FutureTask.run(FutureTask.java:266)
	at java.util.concurrent.Executors$RunnableAdapter.call(Executors.java:511)
	at java.util.concurrent.FutureTask.run(FutureTask.java:266)
	at java.util.concurrent.ThreadPoolExecutor.runWorker(ThreadPoolExecutor.java:1142)
	at java.util.concurrent.ThreadPoolExecutor$Worker.run(ThreadPoolExecutor.java:617)
	at java.lang.Thread.run(Thread.java:745)
Caused by: org.testng.TestException: 
Method TestSum.testSumExceptionIsThrown(long, long)[pri:0, instance:com.epam.calculator.testCalculator.baseOperations.TestSum@50a6f6] should have thrown an exception of class java.lang.Exception
	at org.testng.internal.Invoker.handleInvocationResults(Invoker.java:1512)
	at org.testng.internal.Invoker.invokeMethod(Invoker.java:754)
	at org.testng.internal.Invoker.invokeTestMethod(Invoker.java:901)
	at org.testng.internal.TestMethodWithDataProviderMethodWorker.call(TestMethodWithDataProviderMethodWorker.java:73)
	... 7 more
]]>
    </failure>
  </testcase> <!-- testSumExceptionIsThrown -->
  <testcase name="testSumPassLong" time="0.000" classname="com.epam.calculator.testCalculator.baseOperations.TestSum"/>
  <testcase name="testSumPassLong" time="0.000" classname="com.epam.calculator.testCalculator.baseOperations.TestSum"/>
  <testcase name="testSumPassLong" time="0.000" classname="com.epam.calculator.testCalculator.baseOperations.TestSum"/>
  <testcase name="testSumPassLong" time="0.001" classname="com.epam.calculator.testCalculator.baseOperations.TestSum"/>
  <testcase name="testSumFailLong" time="0.000" classname="com.epam.calculator.testCalculator.baseOperations.TestSum"/>
  <testcase name="testSumExceptionIsThrown" time="0.001" classname="com.epam.calculator.testCalculator.baseOperations.TestSum">
    <failure type="org.testng.TestException" message="
Expected exception java.lang.Exception but got org.testng.TestException: 
Method TestSum.testSumExceptionIsThrown(long, long)[pri:0, instance:com.epam.calculator.testCalculator.baseOperations.TestSum@50a6f6] should have thrown an exception of class java.lang.Exception">
      <![CDATA[org.testng.TestException: 
Expected exception java.lang.Exception but got org.testng.TestException: 
Method TestSum.testSumExceptionIsThrown(long, long)[pri:0, instance:com.epam.calculator.testCalculator.baseOperations.TestSum@50a6f6] should have thrown an exception of class java.lang.Exception
	at org.testng.internal.Invoker.handleInvocationResults(Invoker.java:1497)
	at org.testng.internal.TestMethodWithDataProviderMethodWorker.call(TestMethodWithDataProviderMethodWorker.java:87)
	at org.testng.internal.TestMethodWithDataProviderMethodWorker.call(TestMethodWithDataProviderMethodWorker.java:14)
	at java.util.concurrent.FutureTask.run(FutureTask.java:266)
	at java.util.concurrent.Executors$RunnableAdapter.call(Executors.java:511)
	at java.util.concurrent.FutureTask.run(FutureTask.java:266)
	at java.util.concurrent.ThreadPoolExecutor.runWorker(ThreadPoolExecutor.java:1142)
	at java.util.concurrent.ThreadPoolExecutor$Worker.run(ThreadPoolExecutor.java:617)
	at java.lang.Thread.run(Thread.java:745)
Caused by: org.testng.TestException: 
Method TestSum.testSumExceptionIsThrown(long, long)[pri:0, instance:com.epam.calculator.testCalculator.baseOperations.TestSum@50a6f6] should have thrown an exception of class java.lang.Exception
	at org.testng.internal.Invoker.handleInvocationResults(Invoker.java:1512)
	at org.testng.internal.Invoker.invokeMethod(Invoker.java:754)
	at org.testng.internal.Invoker.invokeTestMethod(Invoker.java:901)
	at org.testng.internal.TestMethodWithDataProviderMethodWorker.call(TestMethodWithDataProviderMethodWorker.java:73)
	... 7 more
]]>
    </failure>
  </testcase> <!-- testSumExceptionIsThrown -->
  <testcase name="testSumExceptionIsThrown" time="0.000" classname="com.epam.calculator.testCalculator.baseOperations.TestSum">
    <failure type="org.testng.TestException" message="
Expected exception java.lang.Exception but got org.testng.TestException: 
Method TestSum.testSumExceptionIsThrown(long, long)[pri:0, instance:com.epam.calculator.testCalculator.baseOperations.TestSum@11c311e] should have thrown an exception of class java.lang.Exception">
      <![CDATA[org.testng.TestException: 
Expected exception java.lang.Exception but got org.testng.TestException: 
Method TestSum.testSumExceptionIsThrown(long, long)[pri:0, instance:com.epam.calculator.testCalculator.baseOperations.TestSum@11c311e] should have thrown an exception of class java.lang.Exception
	at org.testng.internal.Invoker.handleInvocationResults(Invoker.java:1497)
	at org.testng.internal.TestMethodWithDataProviderMethodWorker.call(TestMethodWithDataProviderMethodWorker.java:87)
	at org.testng.internal.TestMethodWithDataProviderMethodWorker.call(TestMethodWithDataProviderMethodWorker.java:14)
	at java.util.concurrent.FutureTask.run(FutureTask.java:266)
	at java.util.concurrent.Executors$RunnableAdapter.call(Executors.java:511)
	at java.util.concurrent.FutureTask.run(FutureTask.java:266)
	at java.util.concurrent.ThreadPoolExecutor.runWorker(ThreadPoolExecutor.java:1142)
	at java.util.concurrent.ThreadPoolExecutor$Worker.run(ThreadPoolExecutor.java:617)
	at java.lang.Thread.run(Thread.java:745)
Caused by: org.testng.TestException: 
Method TestSum.testSumExceptionIsThrown(long, long)[pri:0, instance:com.epam.calculator.testCalculator.baseOperations.TestSum@11c311e] should have thrown an exception of class java.lang.Exception
	at org.testng.internal.Invoker.handleInvocationResults(Invoker.java:1512)
	at org.testng.internal.Invoker.invokeMethod(Invoker.java:754)
	at org.testng.internal.Invoker.invokeTestMethod(Invoker.java:901)
	at org.testng.internal.TestMethodWithDataProviderMethodWorker.call(TestMethodWithDataProviderMethodWorker.java:73)
	... 7 more
]]>
    </failure>
  </testcase> <!-- testSumExceptionIsThrown -->
  <testcase name="testSumFailLong" time="0.001" classname="com.epam.calculator.testCalculator.baseOperations.TestSum"/>
  <testcase name="testSumPassLong" time="0.000" classname="com.epam.calculator.testCalculator.baseOperations.TestSum"/>
  <testcase name="testSumFailLong" time="0.000" classname="com.epam.calculator.testCalculator.baseOperations.TestSum"/>
  <testcase name="testSumPassLong" time="0.004" classname="com.epam.calculator.testCalculator.baseOperations.TestSum"/>
  <testcase name="testSumPassLong" time="0.001" classname="com.epam.calculator.testCalculator.baseOperations.TestSum"/>
  <testcase name="testSumExceptionIsThrown" time="0.000" classname="com.epam.calculator.testCalculator.baseOperations.TestSum">
    <failure type="org.testng.TestException" message="
Expected exception java.lang.Exception but got org.testng.TestException: 
Method TestSum.testSumExceptionIsThrown(long, long)[pri:0, instance:com.epam.calculator.testCalculator.baseOperations.TestSum@11c311e] should have thrown an exception of class java.lang.Exception">
      <![CDATA[org.testng.TestException: 
Expected exception java.lang.Exception but got org.testng.TestException: 
Method TestSum.testSumExceptionIsThrown(long, long)[pri:0, instance:com.epam.calculator.testCalculator.baseOperations.TestSum@11c311e] should have thrown an exception of class java.lang.Exception
	at org.testng.internal.Invoker.handleInvocationResults(Invoker.java:1497)
	at org.testng.internal.TestMethodWithDataProviderMethodWorker.call(TestMethodWithDataProviderMethodWorker.java:87)
	at org.testng.internal.TestMethodWithDataProviderMethodWorker.call(TestMethodWithDataProviderMethodWorker.java:14)
	at java.util.concurrent.FutureTask.run(FutureTask.java:266)
	at java.util.concurrent.Executors$RunnableAdapter.call(Executors.java:511)
	at java.util.concurrent.FutureTask.run(FutureTask.java:266)
	at java.util.concurrent.ThreadPoolExecutor.runWorker(ThreadPoolExecutor.java:1142)
	at java.util.concurrent.ThreadPoolExecutor$Worker.run(ThreadPoolExecutor.java:617)
	at java.lang.Thread.run(Thread.java:745)
Caused by: org.testng.TestException: 
Method TestSum.testSumExceptionIsThrown(long, long)[pri:0, instance:com.epam.calculator.testCalculator.baseOperations.TestSum@11c311e] should have thrown an exception of class java.lang.Exception
	at org.testng.internal.Invoker.handleInvocationResults(Invoker.java:1512)
	at org.testng.internal.Invoker.invokeMethod(Invoker.java:754)
	at org.testng.internal.Invoker.invokeTestMethod(Invoker.java:901)
	at org.testng.internal.TestMethodWithDataProviderMethodWorker.call(TestMethodWithDataProviderMethodWorker.java:73)
	... 7 more
]]>
    </failure>
  </testcase> <!-- testSumExceptionIsThrown -->
  <testcase name="testSumFailLong" time="0.000" classname="com.epam.calculator.testCalculator.baseOperations.TestSum"/>
  <testcase name="testSumExceptionIsThrown" time="0.001" classname="com.epam.calculator.testCalculator.baseOperations.TestSum">
    <failure type="org.testng.TestException" message="
Expected exception java.lang.Exception but got org.testng.TestException: 
Method TestSum.testSumExceptionIsThrown(long, long)[pri:0, instance:com.epam.calculator.testCalculator.baseOperations.TestSum@11c311e] should have thrown an exception of class java.lang.Exception">
      <![CDATA[org.testng.TestException: 
Expected exception java.lang.Exception but got org.testng.TestException: 
Method TestSum.testSumExceptionIsThrown(long, long)[pri:0, instance:com.epam.calculator.testCalculator.baseOperations.TestSum@11c311e] should have thrown an exception of class java.lang.Exception
	at org.testng.internal.Invoker.handleInvocationResults(Invoker.java:1497)
	at org.testng.internal.TestMethodWithDataProviderMethodWorker.call(TestMethodWithDataProviderMethodWorker.java:87)
	at org.testng.internal.TestMethodWithDataProviderMethodWorker.call(TestMethodWithDataProviderMethodWorker.java:14)
	at java.util.concurrent.FutureTask.run(FutureTask.java:266)
	at java.util.concurrent.Executors$RunnableAdapter.call(Executors.java:511)
	at java.util.concurrent.FutureTask.run(FutureTask.java:266)
	at java.util.concurrent.ThreadPoolExecutor.runWorker(ThreadPoolExecutor.java:1142)
	at java.util.concurrent.ThreadPoolExecutor$Worker.run(ThreadPoolExecutor.java:617)
	at java.lang.Thread.run(Thread.java:745)
Caused by: org.testng.TestException: 
Method TestSum.testSumExceptionIsThrown(long, long)[pri:0, instance:com.epam.calculator.testCalculator.baseOperations.TestSum@11c311e] should have thrown an exception of class java.lang.Exception
	at org.testng.internal.Invoker.handleInvocationResults(Invoker.java:1512)
	at org.testng.internal.Invoker.invokeMethod(Invoker.java:754)
	at org.testng.internal.Invoker.invokeTestMethod(Invoker.java:901)
	at org.testng.internal.TestMethodWithDataProviderMethodWorker.call(TestMethodWithDataProviderMethodWorker.java:73)
	... 7 more
]]>
    </failure>
  </testcase> <!-- testSumExceptionIsThrown -->
  <testcase name="testSumPassLong" time="0.001" classname="com.epam.calculator.testCalculator.baseOperations.TestSum"/>
  <testcase name="testSumExceptionIsThrown" time="0.001" classname="com.epam.calculator.testCalculator.baseOperations.TestSum">
    <failure type="org.testng.TestException" message="
Expected exception java.lang.Exception but got org.testng.TestException: 
Method TestSum.testSumExceptionIsThrown(long, long)[pri:0, instance:com.epam.calculator.testCalculator.baseOperations.TestSum@1af06fc] should have thrown an exception of class java.lang.Exception">
      <![CDATA[org.testng.TestException: 
Expected exception java.lang.Exception but got org.testng.TestException: 
Method TestSum.testSumExceptionIsThrown(long, long)[pri:0, instance:com.epam.calculator.testCalculator.baseOperations.TestSum@1af06fc] should have thrown an exception of class java.lang.Exception
	at org.testng.internal.Invoker.handleInvocationResults(Invoker.java:1497)
	at org.testng.internal.TestMethodWithDataProviderMethodWorker.call(TestMethodWithDataProviderMethodWorker.java:87)
	at org.testng.internal.TestMethodWithDataProviderMethodWorker.call(TestMethodWithDataProviderMethodWorker.java:14)
	at java.util.concurrent.FutureTask.run(FutureTask.java:266)
	at java.util.concurrent.Executors$RunnableAdapter.call(Executors.java:511)
	at java.util.concurrent.FutureTask.run(FutureTask.java:266)
	at java.util.concurrent.ThreadPoolExecutor.runWorker(ThreadPoolExecutor.java:1142)
	at java.util.concurrent.ThreadPoolExecutor$Worker.run(ThreadPoolExecutor.java:617)
	at java.lang.Thread.run(Thread.java:745)
Caused by: org.testng.TestException: 
Method TestSum.testSumExceptionIsThrown(long, long)[pri:0, instance:com.epam.calculator.testCalculator.baseOperations.TestSum@1af06fc] should have thrown an exception of class java.lang.Exception
	at org.testng.internal.Invoker.handleInvocationResults(Invoker.java:1512)
	at org.testng.internal.Invoker.invokeMethod(Invoker.java:754)
	at org.testng.internal.Invoker.invokeTestMethod(Invoker.java:901)
	at org.testng.internal.TestMethodWithDataProviderMethodWorker.call(TestMethodWithDataProviderMethodWorker.java:73)
	... 7 more
]]>
    </failure>
  </testcase> <!-- testSumExceptionIsThrown -->
  <testcase name="testSumPassLong" time="0.000" classname="com.epam.calculator.testCalculator.baseOperations.TestSum"/>
  <testcase name="testSumExceptionIsThrown" time="0.000" classname="com.epam.calculator.testCalculator.baseOperations.TestSum">
    <failure type="org.testng.TestException" message="
Expected exception java.lang.Exception but got org.testng.TestException: 
Method TestSum.testSumExceptionIsThrown(long, long)[pri:0, instance:com.epam.calculator.testCalculator.baseOperations.TestSum@1af06fc] should have thrown an exception of class java.lang.Exception">
      <![CDATA[org.testng.TestException: 
Expected exception java.lang.Exception but got org.testng.TestException: 
Method TestSum.testSumExceptionIsThrown(long, long)[pri:0, instance:com.epam.calculator.testCalculator.baseOperations.TestSum@1af06fc] should have thrown an exception of class java.lang.Exception
	at org.testng.internal.Invoker.handleInvocationResults(Invoker.java:1497)
	at org.testng.internal.TestMethodWithDataProviderMethodWorker.call(TestMethodWithDataProviderMethodWorker.java:87)
	at org.testng.internal.TestMethodWithDataProviderMethodWorker.call(TestMethodWithDataProviderMethodWorker.java:14)
	at java.util.concurrent.FutureTask.run(FutureTask.java:266)
	at java.util.concurrent.Executors$RunnableAdapter.call(Executors.java:511)
	at java.util.concurrent.FutureTask.run(FutureTask.java:266)
	at java.util.concurrent.ThreadPoolExecutor.runWorker(ThreadPoolExecutor.java:1142)
	at java.util.concurrent.ThreadPoolExecutor$Worker.run(ThreadPoolExecutor.java:617)
	at java.lang.Thread.run(Thread.java:745)
Caused by: org.testng.TestException: 
Method TestSum.testSumExceptionIsThrown(long, long)[pri:0, instance:com.epam.calculator.testCalculator.baseOperations.TestSum@1af06fc] should have thrown an exception of class java.lang.Exception
	at org.testng.internal.Invoker.handleInvocationResults(Invoker.java:1512)
	at org.testng.internal.Invoker.invokeMethod(Invoker.java:754)
	at org.testng.internal.Invoker.invokeTestMethod(Invoker.java:901)
	at org.testng.internal.TestMethodWithDataProviderMethodWorker.call(TestMethodWithDataProviderMethodWorker.java:73)
	... 7 more
]]>
    </failure>
  </testcase> <!-- testSumExceptionIsThrown -->
  <testcase name="testSumExceptionIsThrown" time="0.000" classname="com.epam.calculator.testCalculator.baseOperations.TestSum">
    <failure type="org.testng.TestException" message="
Expected exception java.lang.Exception but got org.testng.TestException: 
Method TestSum.testSumExceptionIsThrown(long, long)[pri:0, instance:com.epam.calculator.testCalculator.baseOperations.TestSum@11c311e] should have thrown an exception of class java.lang.Exception">
      <![CDATA[org.testng.TestException: 
Expected exception java.lang.Exception but got org.testng.TestException: 
Method TestSum.testSumExceptionIsThrown(long, long)[pri:0, instance:com.epam.calculator.testCalculator.baseOperations.TestSum@11c311e] should have thrown an exception of class java.lang.Exception
	at org.testng.internal.Invoker.handleInvocationResults(Invoker.java:1497)
	at org.testng.internal.TestMethodWithDataProviderMethodWorker.call(TestMethodWithDataProviderMethodWorker.java:87)
	at org.testng.internal.TestMethodWithDataProviderMethodWorker.call(TestMethodWithDataProviderMethodWorker.java:14)
	at java.util.concurrent.FutureTask.run(FutureTask.java:266)
	at java.util.concurrent.Executors$RunnableAdapter.call(Executors.java:511)
	at java.util.concurrent.FutureTask.run(FutureTask.java:266)
	at java.util.concurrent.ThreadPoolExecutor.runWorker(ThreadPoolExecutor.java:1142)
	at java.util.concurrent.ThreadPoolExecutor$Worker.run(ThreadPoolExecutor.java:617)
	at java.lang.Thread.run(Thread.java:745)
Caused by: org.testng.TestException: 
Method TestSum.testSumExceptionIsThrown(long, long)[pri:0, instance:com.epam.calculator.testCalculator.baseOperations.TestSum@11c311e] should have thrown an exception of class java.lang.Exception
	at org.testng.internal.Invoker.handleInvocationResults(Invoker.java:1512)
	at org.testng.internal.Invoker.invokeMethod(Invoker.java:754)
	at org.testng.internal.Invoker.invokeTestMethod(Invoker.java:901)
	at org.testng.internal.TestMethodWithDataProviderMethodWorker.call(TestMethodWithDataProviderMethodWorker.java:73)
	... 7 more
]]>
    </failure>
  </testcase> <!-- testSumExceptionIsThrown -->
</testsuite> <!-- com.epam.calculator.testCalculator.baseOperations.TestSum -->
