<?xml version="1.0" encoding="UTF-8"?>
<!-- Generated by org.testng.reporters.JUnitReportReporter -->
<testsuite hostname="BIL-PC" name="com.epam.calculator.testCalculator.baseOperations.TestSub" tests="144" failures="24" timestamp="31 May 2016 22:34:05 GMT" time="0.116" errors="0">
  <testcase name="testSubFailLong" time="0.000" classname="com.epam.calculator.testCalculator.baseOperations.TestSub"/>
  <testcase name="testSubPassLong" time="0.000" classname="com.epam.calculator.testCalculator.baseOperations.TestSub"/>
  <testcase name="testSubExceptionIsThrown" time="0.000" classname="com.epam.calculator.testCalculator.baseOperations.TestSub">
    <failure type="org.testng.TestException" message="
Expected exception java.lang.Exception but got org.testng.TestException: 
Method TestSub.testSubExceptionIsThrown(long, long)[pri:0, instance:com.epam.calculator.testCalculator.baseOperations.TestSub@1c6f96d] should have thrown an exception of class java.lang.Exception">
      <![CDATA[org.testng.TestException: 
Expected exception java.lang.Exception but got org.testng.TestException: 
Method TestSub.testSubExceptionIsThrown(long, long)[pri:0, instance:com.epam.calculator.testCalculator.baseOperations.TestSub@1c6f96d] should have thrown an exception of class java.lang.Exception
	at org.testng.internal.Invoker.handleInvocationResults(Invoker.java:1497)
	at org.testng.internal.TestMethodWithDataProviderMethodWorker.call(TestMethodWithDataProviderMethodWorker.java:87)
	at org.testng.internal.TestMethodWithDataProviderMethodWorker.call(TestMethodWithDataProviderMethodWorker.java:14)
	at java.util.concurrent.FutureTask.run(FutureTask.java:266)
	at java.util.concurrent.Executors$RunnableAdapter.call(Executors.java:511)
	at java.util.concurrent.FutureTask.run(FutureTask.java:266)
	at java.util.concurrent.ThreadPoolExecutor.runWorker(ThreadPoolExecutor.java:1142)
	at java.util.concurrent.ThreadPoolExecutor$Worker.run(ThreadPoolExecutor.java:617)
	at java.lang.Thread.run(Thread.java:745)
Caused by: org.testng.TestException: 
Method TestSub.testSubExceptionIsThrown(long, long)[pri:0, instance:com.epam.calculator.testCalculator.baseOperations.TestSub@1c6f96d] should have thrown an exception of class java.lang.Exception
	at org.testng.internal.Invoker.handleInvocationResults(Invoker.java:1512)
	at org.testng.internal.Invoker.invokeMethod(Invoker.java:754)
	at org.testng.internal.Invoker.invokeTestMethod(Invoker.java:901)
	at org.testng.internal.TestMethodWithDataProviderMethodWorker.call(TestMethodWithDataProviderMethodWorker.java:73)
	... 7 more
]]>
    </failure>
  </testcase> <!-- testSubExceptionIsThrown -->
  <testcase name="testSubExceptionIsThrown" time="0.001" classname="com.epam.calculator.testCalculator.baseOperations.TestSub">
    <failure type="org.testng.TestException" message="
Expected exception java.lang.Exception but got org.testng.TestException: 
Method TestSub.testSubExceptionIsThrown(long, long)[pri:0, instance:com.epam.calculator.testCalculator.baseOperations.TestSub@de6747] should have thrown an exception of class java.lang.Exception">
      <![CDATA[org.testng.TestException: 
Expected exception java.lang.Exception but got org.testng.TestException: 
Method TestSub.testSubExceptionIsThrown(long, long)[pri:0, instance:com.epam.calculator.testCalculator.baseOperations.TestSub@de6747] should have thrown an exception of class java.lang.Exception
	at org.testng.internal.Invoker.handleInvocationResults(Invoker.java:1497)
	at org.testng.internal.TestMethodWithDataProviderMethodWorker.call(TestMethodWithDataProviderMethodWorker.java:87)
	at org.testng.internal.TestMethodWithDataProviderMethodWorker.call(TestMethodWithDataProviderMethodWorker.java:14)
	at java.util.concurrent.FutureTask.run(FutureTask.java:266)
	at java.util.concurrent.Executors$RunnableAdapter.call(Executors.java:511)
	at java.util.concurrent.FutureTask.run(FutureTask.java:266)
	at java.util.concurrent.ThreadPoolExecutor.runWorker(ThreadPoolExecutor.java:1142)
	at java.util.concurrent.ThreadPoolExecutor$Worker.run(ThreadPoolExecutor.java:617)
	at java.lang.Thread.run(Thread.java:745)
Caused by: org.testng.TestException: 
Method TestSub.testSubExceptionIsThrown(long, long)[pri:0, instance:com.epam.calculator.testCalculator.baseOperations.TestSub@de6747] should have thrown an exception of class java.lang.Exception
	at org.testng.internal.Invoker.handleInvocationResults(Invoker.java:1512)
	at org.testng.internal.Invoker.invokeMethod(Invoker.java:754)
	at org.testng.internal.Invoker.invokeTestMethod(Invoker.java:901)
	at org.testng.internal.TestMethodWithDataProviderMethodWorker.call(TestMethodWithDataProviderMethodWorker.java:73)
	... 7 more
]]>
    </failure>
  </testcase> <!-- testSubExceptionIsThrown -->
  <testcase name="testSubPassLong" time="0.001" classname="com.epam.calculator.testCalculator.baseOperations.TestSub"/>
  <testcase name="testSubPassLong" time="0.003" classname="com.epam.calculator.testCalculator.baseOperations.TestSub"/>
  <testcase name="testSubFailLong" time="0.000" classname="com.epam.calculator.testCalculator.baseOperations.TestSub"/>
  <testcase name="testSubPassLong" time="0.003" classname="com.epam.calculator.testCalculator.baseOperations.TestSub"/>
  <testcase name="testSubFailLong" time="0.000" classname="com.epam.calculator.testCalculator.baseOperations.TestSub"/>
  <testcase name="testSubFailLong" time="0.001" classname="com.epam.calculator.testCalculator.baseOperations.TestSub"/>
  <testcase name="testSubPassLong" time="0.002" classname="com.epam.calculator.testCalculator.baseOperations.TestSub"/>
  <testcase name="testSubFailLong" time="0.000" classname="com.epam.calculator.testCalculator.baseOperations.TestSub"/>
  <testcase name="testSubExceptionIsThrown" time="0.000" classname="com.epam.calculator.testCalculator.baseOperations.TestSub">
    <failure type="org.testng.TestException" message="
Expected exception java.lang.Exception but got org.testng.TestException: 
Method TestSub.testSubExceptionIsThrown(long, long)[pri:0, instance:com.epam.calculator.testCalculator.baseOperations.TestSub@2a67b4] should have thrown an exception of class java.lang.Exception">
      <![CDATA[org.testng.TestException: 
Expected exception java.lang.Exception but got org.testng.TestException: 
Method TestSub.testSubExceptionIsThrown(long, long)[pri:0, instance:com.epam.calculator.testCalculator.baseOperations.TestSub@2a67b4] should have thrown an exception of class java.lang.Exception
	at org.testng.internal.Invoker.handleInvocationResults(Invoker.java:1497)
	at org.testng.internal.TestMethodWithDataProviderMethodWorker.call(TestMethodWithDataProviderMethodWorker.java:87)
	at org.testng.internal.TestMethodWithDataProviderMethodWorker.call(TestMethodWithDataProviderMethodWorker.java:14)
	at java.util.concurrent.FutureTask.run(FutureTask.java:266)
	at java.util.concurrent.Executors$RunnableAdapter.call(Executors.java:511)
	at java.util.concurrent.FutureTask.run(FutureTask.java:266)
	at java.util.concurrent.ThreadPoolExecutor.runWorker(ThreadPoolExecutor.java:1142)
	at java.util.concurrent.ThreadPoolExecutor$Worker.run(ThreadPoolExecutor.java:617)
	at java.lang.Thread.run(Thread.java:745)
Caused by: org.testng.TestException: 
Method TestSub.testSubExceptionIsThrown(long, long)[pri:0, instance:com.epam.calculator.testCalculator.baseOperations.TestSub@2a67b4] should have thrown an exception of class java.lang.Exception
	at org.testng.internal.Invoker.handleInvocationResults(Invoker.java:1512)
	at org.testng.internal.Invoker.invokeMethod(Invoker.java:754)
	at org.testng.internal.Invoker.invokeTestMethod(Invoker.java:901)
	at org.testng.internal.TestMethodWithDataProviderMethodWorker.call(TestMethodWithDataProviderMethodWorker.java:73)
	... 7 more
]]>
    </failure>
  </testcase> <!-- testSubExceptionIsThrown -->
  <testcase name="testSubFailLong" time="0.001" classname="com.epam.calculator.testCalculator.baseOperations.TestSub"/>
  <testcase name="testSubPassLong" time="0.000" classname="com.epam.calculator.testCalculator.baseOperations.TestSub"/>
  <testcase name="testSubPassLong" time="0.000" classname="com.epam.calculator.testCalculator.baseOperations.TestSub"/>
  <testcase name="testSubFailLong" time="0.000" classname="com.epam.calculator.testCalculator.baseOperations.TestSub"/>
  <testcase name="testSubFailLong" time="0.004" classname="com.epam.calculator.testCalculator.baseOperations.TestSub"/>
  <testcase name="testSubPassLong" time="0.000" classname="com.epam.calculator.testCalculator.baseOperations.TestSub"/>
  <testcase name="testSubPassLong" time="0.002" classname="com.epam.calculator.testCalculator.baseOperations.TestSub"/>
  <testcase name="testSubExceptionIsThrown" time="0.000" classname="com.epam.calculator.testCalculator.baseOperations.TestSub">
    <failure type="org.testng.TestException" message="
Expected exception java.lang.Exception but got org.testng.TestException: 
Method TestSub.testSubExceptionIsThrown(long, long)[pri:0, instance:com.epam.calculator.testCalculator.baseOperations.TestSub@2a67b4] should have thrown an exception of class java.lang.Exception">
      <![CDATA[org.testng.TestException: 
Expected exception java.lang.Exception but got org.testng.TestException: 
Method TestSub.testSubExceptionIsThrown(long, long)[pri:0, instance:com.epam.calculator.testCalculator.baseOperations.TestSub@2a67b4] should have thrown an exception of class java.lang.Exception
	at org.testng.internal.Invoker.handleInvocationResults(Invoker.java:1497)
	at org.testng.internal.TestMethodWithDataProviderMethodWorker.call(TestMethodWithDataProviderMethodWorker.java:87)
	at org.testng.internal.TestMethodWithDataProviderMethodWorker.call(TestMethodWithDataProviderMethodWorker.java:14)
	at java.util.concurrent.FutureTask.run(FutureTask.java:266)
	at java.util.concurrent.Executors$RunnableAdapter.call(Executors.java:511)
	at java.util.concurrent.FutureTask.run(FutureTask.java:266)
	at java.util.concurrent.ThreadPoolExecutor.runWorker(ThreadPoolExecutor.java:1142)
	at java.util.concurrent.ThreadPoolExecutor$Worker.run(ThreadPoolExecutor.java:617)
	at java.lang.Thread.run(Thread.java:745)
Caused by: org.testng.TestException: 
Method TestSub.testSubExceptionIsThrown(long, long)[pri:0, instance:com.epam.calculator.testCalculator.baseOperations.TestSub@2a67b4] should have thrown an exception of class java.lang.Exception
	at org.testng.internal.Invoker.handleInvocationResults(Invoker.java:1512)
	at org.testng.internal.Invoker.invokeMethod(Invoker.java:754)
	at org.testng.internal.Invoker.invokeTestMethod(Invoker.java:901)
	at org.testng.internal.TestMethodWithDataProviderMethodWorker.call(TestMethodWithDataProviderMethodWorker.java:73)
	... 7 more
]]>
    </failure>
  </testcase> <!-- testSubExceptionIsThrown -->
  <testcase name="testSubPassLong" time="0.000" classname="com.epam.calculator.testCalculator.baseOperations.TestSub"/>
  <testcase name="testSubPassLong" time="0.017" classname="com.epam.calculator.testCalculator.baseOperations.TestSub"/>
  <testcase name="testSubPassLong" time="0.000" classname="com.epam.calculator.testCalculator.baseOperations.TestSub"/>
  <testcase name="testSubPassLong" time="0.001" classname="com.epam.calculator.testCalculator.baseOperations.TestSub"/>
  <testcase name="testSubFailLong" time="0.000" classname="com.epam.calculator.testCalculator.baseOperations.TestSub"/>
  <testcase name="testSubPassLong" time="0.000" classname="com.epam.calculator.testCalculator.baseOperations.TestSub"/>
  <testcase name="testSubExceptionIsThrown" time="0.000" classname="com.epam.calculator.testCalculator.baseOperations.TestSub">
    <failure type="org.testng.TestException" message="
Expected exception java.lang.Exception but got org.testng.TestException: 
Method TestSub.testSubExceptionIsThrown(long, long)[pri:0, instance:com.epam.calculator.testCalculator.baseOperations.TestSub@2a67b4] should have thrown an exception of class java.lang.Exception">
      <![CDATA[org.testng.TestException: 
Expected exception java.lang.Exception but got org.testng.TestException: 
Method TestSub.testSubExceptionIsThrown(long, long)[pri:0, instance:com.epam.calculator.testCalculator.baseOperations.TestSub@2a67b4] should have thrown an exception of class java.lang.Exception
	at org.testng.internal.Invoker.handleInvocationResults(Invoker.java:1497)
	at org.testng.internal.TestMethodWithDataProviderMethodWorker.call(TestMethodWithDataProviderMethodWorker.java:87)
	at org.testng.internal.TestMethodWithDataProviderMethodWorker.call(TestMethodWithDataProviderMethodWorker.java:14)
	at java.util.concurrent.FutureTask.run(FutureTask.java:266)
	at java.util.concurrent.Executors$RunnableAdapter.call(Executors.java:511)
	at java.util.concurrent.FutureTask.run(FutureTask.java:266)
	at java.util.concurrent.ThreadPoolExecutor.runWorker(ThreadPoolExecutor.java:1142)
	at java.util.concurrent.ThreadPoolExecutor$Worker.run(ThreadPoolExecutor.java:617)
	at java.lang.Thread.run(Thread.java:745)
Caused by: org.testng.TestException: 
Method TestSub.testSubExceptionIsThrown(long, long)[pri:0, instance:com.epam.calculator.testCalculator.baseOperations.TestSub@2a67b4] should have thrown an exception of class java.lang.Exception
	at org.testng.internal.Invoker.handleInvocationResults(Invoker.java:1512)
	at org.testng.internal.Invoker.invokeMethod(Invoker.java:754)
	at org.testng.internal.Invoker.invokeTestMethod(Invoker.java:901)
	at org.testng.internal.TestMethodWithDataProviderMethodWorker.call(TestMethodWithDataProviderMethodWorker.java:73)
	... 7 more
]]>
    </failure>
  </testcase> <!-- testSubExceptionIsThrown -->
  <testcase name="testSubExceptionIsThrown" time="0.000" classname="com.epam.calculator.testCalculator.baseOperations.TestSub">
    <failure type="org.testng.TestException" message="
Expected exception java.lang.Exception but got org.testng.TestException: 
Method TestSub.testSubExceptionIsThrown(long, long)[pri:0, instance:com.epam.calculator.testCalculator.baseOperations.TestSub@de6747] should have thrown an exception of class java.lang.Exception">
      <![CDATA[org.testng.TestException: 
Expected exception java.lang.Exception but got org.testng.TestException: 
Method TestSub.testSubExceptionIsThrown(long, long)[pri:0, instance:com.epam.calculator.testCalculator.baseOperations.TestSub@de6747] should have thrown an exception of class java.lang.Exception
	at org.testng.internal.Invoker.handleInvocationResults(Invoker.java:1497)
	at org.testng.internal.TestMethodWithDataProviderMethodWorker.call(TestMethodWithDataProviderMethodWorker.java:87)
	at org.testng.internal.TestMethodWithDataProviderMethodWorker.call(TestMethodWithDataProviderMethodWorker.java:14)
	at java.util.concurrent.FutureTask.run(FutureTask.java:266)
	at java.util.concurrent.Executors$RunnableAdapter.call(Executors.java:511)
	at java.util.concurrent.FutureTask.run(FutureTask.java:266)
	at java.util.concurrent.ThreadPoolExecutor.runWorker(ThreadPoolExecutor.java:1142)
	at java.util.concurrent.ThreadPoolExecutor$Worker.run(ThreadPoolExecutor.java:617)
	at java.lang.Thread.run(Thread.java:745)
Caused by: org.testng.TestException: 
Method TestSub.testSubExceptionIsThrown(long, long)[pri:0, instance:com.epam.calculator.testCalculator.baseOperations.TestSub@de6747] should have thrown an exception of class java.lang.Exception
	at org.testng.internal.Invoker.handleInvocationResults(Invoker.java:1512)
	at org.testng.internal.Invoker.invokeMethod(Invoker.java:754)
	at org.testng.internal.Invoker.invokeTestMethod(Invoker.java:901)
	at org.testng.internal.TestMethodWithDataProviderMethodWorker.call(TestMethodWithDataProviderMethodWorker.java:73)
	... 7 more
]]>
    </failure>
  </testcase> <!-- testSubExceptionIsThrown -->
  <testcase name="testSubPassLong" time="0.000" classname="com.epam.calculator.testCalculator.baseOperations.TestSub"/>
  <testcase name="testSubFailLong" time="0.000" classname="com.epam.calculator.testCalculator.baseOperations.TestSub"/>
  <testcase name="testSubPassLong" time="0.000" classname="com.epam.calculator.testCalculator.baseOperations.TestSub"/>
  <testcase name="testSubExceptionIsThrown" time="0.000" classname="com.epam.calculator.testCalculator.baseOperations.TestSub">
    <failure type="org.testng.TestException" message="
Expected exception java.lang.Exception but got org.testng.TestException: 
Method TestSub.testSubExceptionIsThrown(long, long)[pri:0, instance:com.epam.calculator.testCalculator.baseOperations.TestSub@de6747] should have thrown an exception of class java.lang.Exception">
      <![CDATA[org.testng.TestException: 
Expected exception java.lang.Exception but got org.testng.TestException: 
Method TestSub.testSubExceptionIsThrown(long, long)[pri:0, instance:com.epam.calculator.testCalculator.baseOperations.TestSub@de6747] should have thrown an exception of class java.lang.Exception
	at org.testng.internal.Invoker.handleInvocationResults(Invoker.java:1497)
	at org.testng.internal.TestMethodWithDataProviderMethodWorker.call(TestMethodWithDataProviderMethodWorker.java:87)
	at org.testng.internal.TestMethodWithDataProviderMethodWorker.call(TestMethodWithDataProviderMethodWorker.java:14)
	at java.util.concurrent.FutureTask.run(FutureTask.java:266)
	at java.util.concurrent.Executors$RunnableAdapter.call(Executors.java:511)
	at java.util.concurrent.FutureTask.run(FutureTask.java:266)
	at java.util.concurrent.ThreadPoolExecutor.runWorker(ThreadPoolExecutor.java:1142)
	at java.util.concurrent.ThreadPoolExecutor$Worker.run(ThreadPoolExecutor.java:617)
	at java.lang.Thread.run(Thread.java:745)
Caused by: org.testng.TestException: 
Method TestSub.testSubExceptionIsThrown(long, long)[pri:0, instance:com.epam.calculator.testCalculator.baseOperations.TestSub@de6747] should have thrown an exception of class java.lang.Exception
	at org.testng.internal.Invoker.handleInvocationResults(Invoker.java:1512)
	at org.testng.internal.Invoker.invokeMethod(Invoker.java:754)
	at org.testng.internal.Invoker.invokeTestMethod(Invoker.java:901)
	at org.testng.internal.TestMethodWithDataProviderMethodWorker.call(TestMethodWithDataProviderMethodWorker.java:73)
	... 7 more
]]>
    </failure>
  </testcase> <!-- testSubExceptionIsThrown -->
  <testcase name="testSubPassLong" time="0.000" classname="com.epam.calculator.testCalculator.baseOperations.TestSub"/>
  <testcase name="testSubExceptionIsThrown" time="0.000" classname="com.epam.calculator.testCalculator.baseOperations.TestSub">
    <failure type="org.testng.TestException" message="
Expected exception java.lang.Exception but got org.testng.TestException: 
Method TestSub.testSubExceptionIsThrown(long, long)[pri:0, instance:com.epam.calculator.testCalculator.baseOperations.TestSub@1c6f96d] should have thrown an exception of class java.lang.Exception">
      <![CDATA[org.testng.TestException: 
Expected exception java.lang.Exception but got org.testng.TestException: 
Method TestSub.testSubExceptionIsThrown(long, long)[pri:0, instance:com.epam.calculator.testCalculator.baseOperations.TestSub@1c6f96d] should have thrown an exception of class java.lang.Exception
	at org.testng.internal.Invoker.handleInvocationResults(Invoker.java:1497)
	at org.testng.internal.TestMethodWithDataProviderMethodWorker.call(TestMethodWithDataProviderMethodWorker.java:87)
	at org.testng.internal.TestMethodWithDataProviderMethodWorker.call(TestMethodWithDataProviderMethodWorker.java:14)
	at java.util.concurrent.FutureTask.run(FutureTask.java:266)
	at java.util.concurrent.Executors$RunnableAdapter.call(Executors.java:511)
	at java.util.concurrent.FutureTask.run(FutureTask.java:266)
	at java.util.concurrent.ThreadPoolExecutor.runWorker(ThreadPoolExecutor.java:1142)
	at java.util.concurrent.ThreadPoolExecutor$Worker.run(ThreadPoolExecutor.java:617)
	at java.lang.Thread.run(Thread.java:745)
Caused by: org.testng.TestException: 
Method TestSub.testSubExceptionIsThrown(long, long)[pri:0, instance:com.epam.calculator.testCalculator.baseOperations.TestSub@1c6f96d] should have thrown an exception of class java.lang.Exception
	at org.testng.internal.Invoker.handleInvocationResults(Invoker.java:1512)
	at org.testng.internal.Invoker.invokeMethod(Invoker.java:754)
	at org.testng.internal.Invoker.invokeTestMethod(Invoker.java:901)
	at org.testng.internal.TestMethodWithDataProviderMethodWorker.call(TestMethodWithDataProviderMethodWorker.java:73)
	... 7 more
]]>
    </failure>
  </testcase> <!-- testSubExceptionIsThrown -->
  <testcase name="testSubPassLong" time="0.000" classname="com.epam.calculator.testCalculator.baseOperations.TestSub"/>
  <testcase name="testSubFailLong" time="0.003" classname="com.epam.calculator.testCalculator.baseOperations.TestSub"/>
  <testcase name="testSubFailLong" time="0.000" classname="com.epam.calculator.testCalculator.baseOperations.TestSub"/>
  <testcase name="testSubExceptionIsThrown" time="0.001" classname="com.epam.calculator.testCalculator.baseOperations.TestSub">
    <failure type="org.testng.TestException" message="
Expected exception java.lang.Exception but got org.testng.TestException: 
Method TestSub.testSubExceptionIsThrown(long, long)[pri:0, instance:com.epam.calculator.testCalculator.baseOperations.TestSub@2a67b4] should have thrown an exception of class java.lang.Exception">
      <![CDATA[org.testng.TestException: 
Expected exception java.lang.Exception but got org.testng.TestException: 
Method TestSub.testSubExceptionIsThrown(long, long)[pri:0, instance:com.epam.calculator.testCalculator.baseOperations.TestSub@2a67b4] should have thrown an exception of class java.lang.Exception
	at org.testng.internal.Invoker.handleInvocationResults(Invoker.java:1497)
	at org.testng.internal.TestMethodWithDataProviderMethodWorker.call(TestMethodWithDataProviderMethodWorker.java:87)
	at org.testng.internal.TestMethodWithDataProviderMethodWorker.call(TestMethodWithDataProviderMethodWorker.java:14)
	at java.util.concurrent.FutureTask.run(FutureTask.java:266)
	at java.util.concurrent.Executors$RunnableAdapter.call(Executors.java:511)
	at java.util.concurrent.FutureTask.run(FutureTask.java:266)
	at java.util.concurrent.ThreadPoolExecutor.runWorker(ThreadPoolExecutor.java:1142)
	at java.util.concurrent.ThreadPoolExecutor$Worker.run(ThreadPoolExecutor.java:617)
	at java.lang.Thread.run(Thread.java:745)
Caused by: org.testng.TestException: 
Method TestSub.testSubExceptionIsThrown(long, long)[pri:0, instance:com.epam.calculator.testCalculator.baseOperations.TestSub@2a67b4] should have thrown an exception of class java.lang.Exception
	at org.testng.internal.Invoker.handleInvocationResults(Invoker.java:1512)
	at org.testng.internal.Invoker.invokeMethod(Invoker.java:754)
	at org.testng.internal.Invoker.invokeTestMethod(Invoker.java:901)
	at org.testng.internal.TestMethodWithDataProviderMethodWorker.call(TestMethodWithDataProviderMethodWorker.java:73)
	... 7 more
]]>
    </failure>
  </testcase> <!-- testSubExceptionIsThrown -->
  <testcase name="testSubFailLong" time="0.000" classname="com.epam.calculator.testCalculator.baseOperations.TestSub"/>
  <testcase name="testSubPassLong" time="0.001" classname="com.epam.calculator.testCalculator.baseOperations.TestSub"/>
  <testcase name="testSubPassLong" time="0.000" classname="com.epam.calculator.testCalculator.baseOperations.TestSub"/>
  <testcase name="testSubPassLong" time="0.001" classname="com.epam.calculator.testCalculator.baseOperations.TestSub"/>
  <testcase name="testSubFailLong" time="0.001" classname="com.epam.calculator.testCalculator.baseOperations.TestSub"/>
  <testcase name="testSubPassLong" time="0.001" classname="com.epam.calculator.testCalculator.baseOperations.TestSub"/>
  <testcase name="testSubFailLong" time="0.001" classname="com.epam.calculator.testCalculator.baseOperations.TestSub"/>
  <testcase name="testSubPassLong" time="0.001" classname="com.epam.calculator.testCalculator.baseOperations.TestSub"/>
  <testcase name="testSubExceptionIsThrown" time="0.002" classname="com.epam.calculator.testCalculator.baseOperations.TestSub">
    <failure type="org.testng.TestException" message="
Expected exception java.lang.Exception but got org.testng.TestException: 
Method TestSub.testSubExceptionIsThrown(long, long)[pri:0, instance:com.epam.calculator.testCalculator.baseOperations.TestSub@1c6f96d] should have thrown an exception of class java.lang.Exception">
      <![CDATA[org.testng.TestException: 
Expected exception java.lang.Exception but got org.testng.TestException: 
Method TestSub.testSubExceptionIsThrown(long, long)[pri:0, instance:com.epam.calculator.testCalculator.baseOperations.TestSub@1c6f96d] should have thrown an exception of class java.lang.Exception
	at org.testng.internal.Invoker.handleInvocationResults(Invoker.java:1497)
	at org.testng.internal.TestMethodWithDataProviderMethodWorker.call(TestMethodWithDataProviderMethodWorker.java:87)
	at org.testng.internal.TestMethodWithDataProviderMethodWorker.call(TestMethodWithDataProviderMethodWorker.java:14)
	at java.util.concurrent.FutureTask.run(FutureTask.java:266)
	at java.util.concurrent.Executors$RunnableAdapter.call(Executors.java:511)
	at java.util.concurrent.FutureTask.run(FutureTask.java:266)
	at java.util.concurrent.ThreadPoolExecutor.runWorker(ThreadPoolExecutor.java:1142)
	at java.util.concurrent.ThreadPoolExecutor$Worker.run(ThreadPoolExecutor.java:617)
	at java.lang.Thread.run(Thread.java:745)
Caused by: org.testng.TestException: 
Method TestSub.testSubExceptionIsThrown(long, long)[pri:0, instance:com.epam.calculator.testCalculator.baseOperations.TestSub@1c6f96d] should have thrown an exception of class java.lang.Exception
	at org.testng.internal.Invoker.handleInvocationResults(Invoker.java:1512)
	at org.testng.internal.Invoker.invokeMethod(Invoker.java:754)
	at org.testng.internal.Invoker.invokeTestMethod(Invoker.java:901)
	at org.testng.internal.TestMethodWithDataProviderMethodWorker.call(TestMethodWithDataProviderMethodWorker.java:73)
	... 7 more
]]>
    </failure>
  </testcase> <!-- testSubExceptionIsThrown -->
  <testcase name="testSubExceptionIsThrown" time="0.000" classname="com.epam.calculator.testCalculator.baseOperations.TestSub">
    <failure type="org.testng.TestException" message="
Expected exception java.lang.Exception but got org.testng.TestException: 
Method TestSub.testSubExceptionIsThrown(long, long)[pri:0, instance:com.epam.calculator.testCalculator.baseOperations.TestSub@1c6f96d] should have thrown an exception of class java.lang.Exception">
      <![CDATA[org.testng.TestException: 
Expected exception java.lang.Exception but got org.testng.TestException: 
Method TestSub.testSubExceptionIsThrown(long, long)[pri:0, instance:com.epam.calculator.testCalculator.baseOperations.TestSub@1c6f96d] should have thrown an exception of class java.lang.Exception
	at org.testng.internal.Invoker.handleInvocationResults(Invoker.java:1497)
	at org.testng.internal.TestMethodWithDataProviderMethodWorker.call(TestMethodWithDataProviderMethodWorker.java:87)
	at org.testng.internal.TestMethodWithDataProviderMethodWorker.call(TestMethodWithDataProviderMethodWorker.java:14)
	at java.util.concurrent.FutureTask.run(FutureTask.java:266)
	at java.util.concurrent.Executors$RunnableAdapter.call(Executors.java:511)
	at java.util.concurrent.FutureTask.run(FutureTask.java:266)
	at java.util.concurrent.ThreadPoolExecutor.runWorker(ThreadPoolExecutor.java:1142)
	at java.util.concurrent.ThreadPoolExecutor$Worker.run(ThreadPoolExecutor.java:617)
	at java.lang.Thread.run(Thread.java:745)
Caused by: org.testng.TestException: 
Method TestSub.testSubExceptionIsThrown(long, long)[pri:0, instance:com.epam.calculator.testCalculator.baseOperations.TestSub@1c6f96d] should have thrown an exception of class java.lang.Exception
	at org.testng.internal.Invoker.handleInvocationResults(Invoker.java:1512)
	at org.testng.internal.Invoker.invokeMethod(Invoker.java:754)
	at org.testng.internal.Invoker.invokeTestMethod(Invoker.java:901)
	at org.testng.internal.TestMethodWithDataProviderMethodWorker.call(TestMethodWithDataProviderMethodWorker.java:73)
	... 7 more
]]>
    </failure>
  </testcase> <!-- testSubExceptionIsThrown -->
  <testcase name="testSubPassLong" time="0.000" classname="com.epam.calculator.testCalculator.baseOperations.TestSub"/>
  <testcase name="testSubPassLong" time="0.000" classname="com.epam.calculator.testCalculator.baseOperations.TestSub"/>
  <testcase name="testSubFailLong" time="0.000" classname="com.epam.calculator.testCalculator.baseOperations.TestSub"/>
  <testcase name="testSubPassLong" time="0.000" classname="com.epam.calculator.testCalculator.baseOperations.TestSub"/>
  <testcase name="testSubPassLong" time="0.000" classname="com.epam.calculator.testCalculator.baseOperations.TestSub"/>
  <testcase name="testSubPassLong" time="0.002" classname="com.epam.calculator.testCalculator.baseOperations.TestSub"/>
  <testcase name="testSubExceptionIsThrown" time="0.001" classname="com.epam.calculator.testCalculator.baseOperations.TestSub">
    <failure type="org.testng.TestException" message="
Expected exception java.lang.Exception but got org.testng.TestException: 
Method TestSub.testSubExceptionIsThrown(long, long)[pri:0, instance:com.epam.calculator.testCalculator.baseOperations.TestSub@de6747] should have thrown an exception of class java.lang.Exception">
      <![CDATA[org.testng.TestException: 
Expected exception java.lang.Exception but got org.testng.TestException: 
Method TestSub.testSubExceptionIsThrown(long, long)[pri:0, instance:com.epam.calculator.testCalculator.baseOperations.TestSub@de6747] should have thrown an exception of class java.lang.Exception
	at org.testng.internal.Invoker.handleInvocationResults(Invoker.java:1497)
	at org.testng.internal.TestMethodWithDataProviderMethodWorker.call(TestMethodWithDataProviderMethodWorker.java:87)
	at org.testng.internal.TestMethodWithDataProviderMethodWorker.call(TestMethodWithDataProviderMethodWorker.java:14)
	at java.util.concurrent.FutureTask.run(FutureTask.java:266)
	at java.util.concurrent.Executors$RunnableAdapter.call(Executors.java:511)
	at java.util.concurrent.FutureTask.run(FutureTask.java:266)
	at java.util.concurrent.ThreadPoolExecutor.runWorker(ThreadPoolExecutor.java:1142)
	at java.util.concurrent.ThreadPoolExecutor$Worker.run(ThreadPoolExecutor.java:617)
	at java.lang.Thread.run(Thread.java:745)
Caused by: org.testng.TestException: 
Method TestSub.testSubExceptionIsThrown(long, long)[pri:0, instance:com.epam.calculator.testCalculator.baseOperations.TestSub@de6747] should have thrown an exception of class java.lang.Exception
	at org.testng.internal.Invoker.handleInvocationResults(Invoker.java:1512)
	at org.testng.internal.Invoker.invokeMethod(Invoker.java:754)
	at org.testng.internal.Invoker.invokeTestMethod(Invoker.java:901)
	at org.testng.internal.TestMethodWithDataProviderMethodWorker.call(TestMethodWithDataProviderMethodWorker.java:73)
	... 7 more
]]>
    </failure>
  </testcase> <!-- testSubExceptionIsThrown -->
  <testcase name="testSubFailLong" time="0.000" classname="com.epam.calculator.testCalculator.baseOperations.TestSub"/>
  <testcase name="testSubPassLong" time="0.000" classname="com.epam.calculator.testCalculator.baseOperations.TestSub"/>
  <testcase name="testSubPassLong" time="0.000" classname="com.epam.calculator.testCalculator.baseOperations.TestSub"/>
  <testcase name="testSubPassLong" time="0.001" classname="com.epam.calculator.testCalculator.baseOperations.TestSub"/>
  <testcase name="testSubPassLong" time="0.001" classname="com.epam.calculator.testCalculator.baseOperations.TestSub"/>
  <testcase name="testSubFailLong" time="0.000" classname="com.epam.calculator.testCalculator.baseOperations.TestSub"/>
  <testcase name="testSubPassLong" time="0.000" classname="com.epam.calculator.testCalculator.baseOperations.TestSub"/>
  <testcase name="testSubPassLong" time="0.000" classname="com.epam.calculator.testCalculator.baseOperations.TestSub"/>
  <testcase name="testSubPassLong" time="0.002" classname="com.epam.calculator.testCalculator.baseOperations.TestSub"/>
  <testcase name="testSubPassLong" time="0.000" classname="com.epam.calculator.testCalculator.baseOperations.TestSub"/>
  <testcase name="testSubPassLong" time="0.000" classname="com.epam.calculator.testCalculator.baseOperations.TestSub"/>
  <testcase name="testSubPassLong" time="0.000" classname="com.epam.calculator.testCalculator.baseOperations.TestSub"/>
  <testcase name="testSubPassLong" time="0.000" classname="com.epam.calculator.testCalculator.baseOperations.TestSub"/>
  <testcase name="testSubPassLong" time="0.000" classname="com.epam.calculator.testCalculator.baseOperations.TestSub"/>
  <testcase name="testSubFailLong" time="0.000" classname="com.epam.calculator.testCalculator.baseOperations.TestSub"/>
  <testcase name="testSubPassLong" time="0.001" classname="com.epam.calculator.testCalculator.baseOperations.TestSub"/>
  <testcase name="testSubPassLong" time="0.000" classname="com.epam.calculator.testCalculator.baseOperations.TestSub"/>
  <testcase name="testSubPassLong" time="0.001" classname="com.epam.calculator.testCalculator.baseOperations.TestSub"/>
  <testcase name="testSubFailLong" time="0.002" classname="com.epam.calculator.testCalculator.baseOperations.TestSub"/>
  <testcase name="testSubFailLong" time="0.000" classname="com.epam.calculator.testCalculator.baseOperations.TestSub"/>
  <testcase name="testSubFailLong" time="0.007" classname="com.epam.calculator.testCalculator.baseOperations.TestSub"/>
  <testcase name="testSubFailLong" time="0.005" classname="com.epam.calculator.testCalculator.baseOperations.TestSub"/>
  <testcase name="testSubFailLong" time="0.001" classname="com.epam.calculator.testCalculator.baseOperations.TestSub"/>
  <testcase name="testSubFailLong" time="0.000" classname="com.epam.calculator.testCalculator.baseOperations.TestSub"/>
  <testcase name="testSubExceptionIsThrown" time="0.001" classname="com.epam.calculator.testCalculator.baseOperations.TestSub">
    <failure type="org.testng.TestException" message="
Expected exception java.lang.Exception but got org.testng.TestException: 
Method TestSub.testSubExceptionIsThrown(long, long)[pri:0, instance:com.epam.calculator.testCalculator.baseOperations.TestSub@de6747] should have thrown an exception of class java.lang.Exception">
      <![CDATA[org.testng.TestException: 
Expected exception java.lang.Exception but got org.testng.TestException: 
Method TestSub.testSubExceptionIsThrown(long, long)[pri:0, instance:com.epam.calculator.testCalculator.baseOperations.TestSub@de6747] should have thrown an exception of class java.lang.Exception
	at org.testng.internal.Invoker.handleInvocationResults(Invoker.java:1497)
	at org.testng.internal.TestMethodWithDataProviderMethodWorker.call(TestMethodWithDataProviderMethodWorker.java:87)
	at org.testng.internal.TestMethodWithDataProviderMethodWorker.call(TestMethodWithDataProviderMethodWorker.java:14)
	at java.util.concurrent.FutureTask.run(FutureTask.java:266)
	at java.util.concurrent.Executors$RunnableAdapter.call(Executors.java:511)
	at java.util.concurrent.FutureTask.run(FutureTask.java:266)
	at java.util.concurrent.ThreadPoolExecutor.runWorker(ThreadPoolExecutor.java:1142)
	at java.util.concurrent.ThreadPoolExecutor$Worker.run(ThreadPoolExecutor.java:617)
	at java.lang.Thread.run(Thread.java:745)
Caused by: org.testng.TestException: 
Method TestSub.testSubExceptionIsThrown(long, long)[pri:0, instance:com.epam.calculator.testCalculator.baseOperations.TestSub@de6747] should have thrown an exception of class java.lang.Exception
	at org.testng.internal.Invoker.handleInvocationResults(Invoker.java:1512)
	at org.testng.internal.Invoker.invokeMethod(Invoker.java:754)
	at org.testng.internal.Invoker.invokeTestMethod(Invoker.java:901)
	at org.testng.internal.TestMethodWithDataProviderMethodWorker.call(TestMethodWithDataProviderMethodWorker.java:73)
	... 7 more
]]>
    </failure>
  </testcase> <!-- testSubExceptionIsThrown -->
  <testcase name="testSubPassLong" time="0.000" classname="com.epam.calculator.testCalculator.baseOperations.TestSub"/>
  <testcase name="testSubExceptionIsThrown" time="0.001" classname="com.epam.calculator.testCalculator.baseOperations.TestSub">
    <failure type="org.testng.TestException" message="
Expected exception java.lang.Exception but got org.testng.TestException: 
Method TestSub.testSubExceptionIsThrown(long, long)[pri:0, instance:com.epam.calculator.testCalculator.baseOperations.TestSub@de6747] should have thrown an exception of class java.lang.Exception">
      <![CDATA[org.testng.TestException: 
Expected exception java.lang.Exception but got org.testng.TestException: 
Method TestSub.testSubExceptionIsThrown(long, long)[pri:0, instance:com.epam.calculator.testCalculator.baseOperations.TestSub@de6747] should have thrown an exception of class java.lang.Exception
	at org.testng.internal.Invoker.handleInvocationResults(Invoker.java:1497)
	at org.testng.internal.TestMethodWithDataProviderMethodWorker.call(TestMethodWithDataProviderMethodWorker.java:87)
	at org.testng.internal.TestMethodWithDataProviderMethodWorker.call(TestMethodWithDataProviderMethodWorker.java:14)
	at java.util.concurrent.FutureTask.run(FutureTask.java:266)
	at java.util.concurrent.Executors$RunnableAdapter.call(Executors.java:511)
	at java.util.concurrent.FutureTask.run(FutureTask.java:266)
	at java.util.concurrent.ThreadPoolExecutor.runWorker(ThreadPoolExecutor.java:1142)
	at java.util.concurrent.ThreadPoolExecutor$Worker.run(ThreadPoolExecutor.java:617)
	at java.lang.Thread.run(Thread.java:745)
Caused by: org.testng.TestException: 
Method TestSub.testSubExceptionIsThrown(long, long)[pri:0, instance:com.epam.calculator.testCalculator.baseOperations.TestSub@de6747] should have thrown an exception of class java.lang.Exception
	at org.testng.internal.Invoker.handleInvocationResults(Invoker.java:1512)
	at org.testng.internal.Invoker.invokeMethod(Invoker.java:754)
	at org.testng.internal.Invoker.invokeTestMethod(Invoker.java:901)
	at org.testng.internal.TestMethodWithDataProviderMethodWorker.call(TestMethodWithDataProviderMethodWorker.java:73)
	... 7 more
]]>
    </failure>
  </testcase> <!-- testSubExceptionIsThrown -->
  <testcase name="testSubPassLong" time="0.000" classname="com.epam.calculator.testCalculator.baseOperations.TestSub"/>
  <testcase name="testSubPassLong" time="0.000" classname="com.epam.calculator.testCalculator.baseOperations.TestSub"/>
  <testcase name="testSubExceptionIsThrown" time="0.000" classname="com.epam.calculator.testCalculator.baseOperations.TestSub">
    <failure type="org.testng.TestException" message="
Expected exception java.lang.Exception but got org.testng.TestException: 
Method TestSub.testSubExceptionIsThrown(long, long)[pri:0, instance:com.epam.calculator.testCalculator.baseOperations.TestSub@de6747] should have thrown an exception of class java.lang.Exception">
      <![CDATA[org.testng.TestException: 
Expected exception java.lang.Exception but got org.testng.TestException: 
Method TestSub.testSubExceptionIsThrown(long, long)[pri:0, instance:com.epam.calculator.testCalculator.baseOperations.TestSub@de6747] should have thrown an exception of class java.lang.Exception
	at org.testng.internal.Invoker.handleInvocationResults(Invoker.java:1497)
	at org.testng.internal.TestMethodWithDataProviderMethodWorker.call(TestMethodWithDataProviderMethodWorker.java:87)
	at org.testng.internal.TestMethodWithDataProviderMethodWorker.call(TestMethodWithDataProviderMethodWorker.java:14)
	at java.util.concurrent.FutureTask.run(FutureTask.java:266)
	at java.util.concurrent.Executors$RunnableAdapter.call(Executors.java:511)
	at java.util.concurrent.FutureTask.run(FutureTask.java:266)
	at java.util.concurrent.ThreadPoolExecutor.runWorker(ThreadPoolExecutor.java:1142)
	at java.util.concurrent.ThreadPoolExecutor$Worker.run(ThreadPoolExecutor.java:617)
	at java.lang.Thread.run(Thread.java:745)
Caused by: org.testng.TestException: 
Method TestSub.testSubExceptionIsThrown(long, long)[pri:0, instance:com.epam.calculator.testCalculator.baseOperations.TestSub@de6747] should have thrown an exception of class java.lang.Exception
	at org.testng.internal.Invoker.handleInvocationResults(Invoker.java:1512)
	at org.testng.internal.Invoker.invokeMethod(Invoker.java:754)
	at org.testng.internal.Invoker.invokeTestMethod(Invoker.java:901)
	at org.testng.internal.TestMethodWithDataProviderMethodWorker.call(TestMethodWithDataProviderMethodWorker.java:73)
	... 7 more
]]>
    </failure>
  </testcase> <!-- testSubExceptionIsThrown -->
  <testcase name="testSubPassLong" time="0.000" classname="com.epam.calculator.testCalculator.baseOperations.TestSub"/>
  <testcase name="testSubPassLong" time="0.001" classname="com.epam.calculator.testCalculator.baseOperations.TestSub"/>
  <testcase name="testSubPassLong" time="0.001" classname="com.epam.calculator.testCalculator.baseOperations.TestSub"/>
  <testcase name="testSubPassLong" time="0.000" classname="com.epam.calculator.testCalculator.baseOperations.TestSub"/>
  <testcase name="testSubPassLong" time="0.001" classname="com.epam.calculator.testCalculator.baseOperations.TestSub"/>
  <testcase name="testSubFailLong" time="0.001" classname="com.epam.calculator.testCalculator.baseOperations.TestSub"/>
  <testcase name="testSubPassLong" time="0.000" classname="com.epam.calculator.testCalculator.baseOperations.TestSub"/>
  <testcase name="testSubExceptionIsThrown" time="0.002" classname="com.epam.calculator.testCalculator.baseOperations.TestSub">
    <failure type="org.testng.TestException" message="
Expected exception java.lang.Exception but got org.testng.TestException: 
Method TestSub.testSubExceptionIsThrown(long, long)[pri:0, instance:com.epam.calculator.testCalculator.baseOperations.TestSub@2a67b4] should have thrown an exception of class java.lang.Exception">
      <![CDATA[org.testng.TestException: 
Expected exception java.lang.Exception but got org.testng.TestException: 
Method TestSub.testSubExceptionIsThrown(long, long)[pri:0, instance:com.epam.calculator.testCalculator.baseOperations.TestSub@2a67b4] should have thrown an exception of class java.lang.Exception
	at org.testng.internal.Invoker.handleInvocationResults(Invoker.java:1497)
	at org.testng.internal.TestMethodWithDataProviderMethodWorker.call(TestMethodWithDataProviderMethodWorker.java:87)
	at org.testng.internal.TestMethodWithDataProviderMethodWorker.call(TestMethodWithDataProviderMethodWorker.java:14)
	at java.util.concurrent.FutureTask.run(FutureTask.java:266)
	at java.util.concurrent.Executors$RunnableAdapter.call(Executors.java:511)
	at java.util.concurrent.FutureTask.run(FutureTask.java:266)
	at java.util.concurrent.ThreadPoolExecutor.runWorker(ThreadPoolExecutor.java:1142)
	at java.util.concurrent.ThreadPoolExecutor$Worker.run(ThreadPoolExecutor.java:617)
	at java.lang.Thread.run(Thread.java:745)
Caused by: org.testng.TestException: 
Method TestSub.testSubExceptionIsThrown(long, long)[pri:0, instance:com.epam.calculator.testCalculator.baseOperations.TestSub@2a67b4] should have thrown an exception of class java.lang.Exception
	at org.testng.internal.Invoker.handleInvocationResults(Invoker.java:1512)
	at org.testng.internal.Invoker.invokeMethod(Invoker.java:754)
	at org.testng.internal.Invoker.invokeTestMethod(Invoker.java:901)
	at org.testng.internal.TestMethodWithDataProviderMethodWorker.call(TestMethodWithDataProviderMethodWorker.java:73)
	... 7 more
]]>
    </failure>
  </testcase> <!-- testSubExceptionIsThrown -->
  <testcase name="testSubFailLong" time="0.001" classname="com.epam.calculator.testCalculator.baseOperations.TestSub"/>
  <testcase name="testSubFailLong" time="0.000" classname="com.epam.calculator.testCalculator.baseOperations.TestSub"/>
  <testcase name="testSubPassLong" time="0.000" classname="com.epam.calculator.testCalculator.baseOperations.TestSub"/>
  <testcase name="testSubExceptionIsThrown" time="0.003" classname="com.epam.calculator.testCalculator.baseOperations.TestSub">
    <failure type="org.testng.TestException" message="
Expected exception java.lang.Exception but got org.testng.TestException: 
Method TestSub.testSubExceptionIsThrown(long, long)[pri:0, instance:com.epam.calculator.testCalculator.baseOperations.TestSub@2a67b4] should have thrown an exception of class java.lang.Exception">
      <![CDATA[org.testng.TestException: 
Expected exception java.lang.Exception but got org.testng.TestException: 
Method TestSub.testSubExceptionIsThrown(long, long)[pri:0, instance:com.epam.calculator.testCalculator.baseOperations.TestSub@2a67b4] should have thrown an exception of class java.lang.Exception
	at org.testng.internal.Invoker.handleInvocationResults(Invoker.java:1497)
	at org.testng.internal.TestMethodWithDataProviderMethodWorker.call(TestMethodWithDataProviderMethodWorker.java:87)
	at org.testng.internal.TestMethodWithDataProviderMethodWorker.call(TestMethodWithDataProviderMethodWorker.java:14)
	at java.util.concurrent.FutureTask.run(FutureTask.java:266)
	at java.util.concurrent.Executors$RunnableAdapter.call(Executors.java:511)
	at java.util.concurrent.FutureTask.run(FutureTask.java:266)
	at java.util.concurrent.ThreadPoolExecutor.runWorker(ThreadPoolExecutor.java:1142)
	at java.util.concurrent.ThreadPoolExecutor$Worker.run(ThreadPoolExecutor.java:617)
	at java.lang.Thread.run(Thread.java:745)
Caused by: org.testng.TestException: 
Method TestSub.testSubExceptionIsThrown(long, long)[pri:0, instance:com.epam.calculator.testCalculator.baseOperations.TestSub@2a67b4] should have thrown an exception of class java.lang.Exception
	at org.testng.internal.Invoker.handleInvocationResults(Invoker.java:1512)
	at org.testng.internal.Invoker.invokeMethod(Invoker.java:754)
	at org.testng.internal.Invoker.invokeTestMethod(Invoker.java:901)
	at org.testng.internal.TestMethodWithDataProviderMethodWorker.call(TestMethodWithDataProviderMethodWorker.java:73)
	... 7 more
]]>
    </failure>
  </testcase> <!-- testSubExceptionIsThrown -->
  <testcase name="testSubFailLong" time="0.000" classname="com.epam.calculator.testCalculator.baseOperations.TestSub"/>
  <testcase name="testSubExceptionIsThrown" time="0.000" classname="com.epam.calculator.testCalculator.baseOperations.TestSub">
    <failure type="org.testng.TestException" message="
Expected exception java.lang.Exception but got org.testng.TestException: 
Method TestSub.testSubExceptionIsThrown(long, long)[pri:0, instance:com.epam.calculator.testCalculator.baseOperations.TestSub@1c6f96d] should have thrown an exception of class java.lang.Exception">
      <![CDATA[org.testng.TestException: 
Expected exception java.lang.Exception but got org.testng.TestException: 
Method TestSub.testSubExceptionIsThrown(long, long)[pri:0, instance:com.epam.calculator.testCalculator.baseOperations.TestSub@1c6f96d] should have thrown an exception of class java.lang.Exception
	at org.testng.internal.Invoker.handleInvocationResults(Invoker.java:1497)
	at org.testng.internal.TestMethodWithDataProviderMethodWorker.call(TestMethodWithDataProviderMethodWorker.java:87)
	at org.testng.internal.TestMethodWithDataProviderMethodWorker.call(TestMethodWithDataProviderMethodWorker.java:14)
	at java.util.concurrent.FutureTask.run(FutureTask.java:266)
	at java.util.concurrent.Executors$RunnableAdapter.call(Executors.java:511)
	at java.util.concurrent.FutureTask.run(FutureTask.java:266)
	at java.util.concurrent.ThreadPoolExecutor.runWorker(ThreadPoolExecutor.java:1142)
	at java.util.concurrent.ThreadPoolExecutor$Worker.run(ThreadPoolExecutor.java:617)
	at java.lang.Thread.run(Thread.java:745)
Caused by: org.testng.TestException: 
Method TestSub.testSubExceptionIsThrown(long, long)[pri:0, instance:com.epam.calculator.testCalculator.baseOperations.TestSub@1c6f96d] should have thrown an exception of class java.lang.Exception
	at org.testng.internal.Invoker.handleInvocationResults(Invoker.java:1512)
	at org.testng.internal.Invoker.invokeMethod(Invoker.java:754)
	at org.testng.internal.Invoker.invokeTestMethod(Invoker.java:901)
	at org.testng.internal.TestMethodWithDataProviderMethodWorker.call(TestMethodWithDataProviderMethodWorker.java:73)
	... 7 more
]]>
    </failure>
  </testcase> <!-- testSubExceptionIsThrown -->
  <testcase name="testSubPassLong" time="0.000" classname="com.epam.calculator.testCalculator.baseOperations.TestSub"/>
  <testcase name="testSubPassLong" time="0.000" classname="com.epam.calculator.testCalculator.baseOperations.TestSub"/>
  <testcase name="testSubFailLong" time="0.001" classname="com.epam.calculator.testCalculator.baseOperations.TestSub"/>
  <testcase name="testSubFailLong" time="0.000" classname="com.epam.calculator.testCalculator.baseOperations.TestSub"/>
  <testcase name="testSubPassLong" time="0.001" classname="com.epam.calculator.testCalculator.baseOperations.TestSub"/>
  <testcase name="testSubPassLong" time="0.001" classname="com.epam.calculator.testCalculator.baseOperations.TestSub"/>
  <testcase name="testSubPassLong" time="0.000" classname="com.epam.calculator.testCalculator.baseOperations.TestSub"/>
  <testcase name="testSubFailLong" time="0.001" classname="com.epam.calculator.testCalculator.baseOperations.TestSub"/>
  <testcase name="testSubExceptionIsThrown" time="0.001" classname="com.epam.calculator.testCalculator.baseOperations.TestSub">
    <failure type="org.testng.TestException" message="
Expected exception java.lang.Exception but got org.testng.TestException: 
Method TestSub.testSubExceptionIsThrown(long, long)[pri:0, instance:com.epam.calculator.testCalculator.baseOperations.TestSub@2a67b4] should have thrown an exception of class java.lang.Exception">
      <![CDATA[org.testng.TestException: 
Expected exception java.lang.Exception but got org.testng.TestException: 
Method TestSub.testSubExceptionIsThrown(long, long)[pri:0, instance:com.epam.calculator.testCalculator.baseOperations.TestSub@2a67b4] should have thrown an exception of class java.lang.Exception
	at org.testng.internal.Invoker.handleInvocationResults(Invoker.java:1497)
	at org.testng.internal.TestMethodWithDataProviderMethodWorker.call(TestMethodWithDataProviderMethodWorker.java:87)
	at org.testng.internal.TestMethodWithDataProviderMethodWorker.call(TestMethodWithDataProviderMethodWorker.java:14)
	at java.util.concurrent.FutureTask.run(FutureTask.java:266)
	at java.util.concurrent.Executors$RunnableAdapter.call(Executors.java:511)
	at java.util.concurrent.FutureTask.run(FutureTask.java:266)
	at java.util.concurrent.ThreadPoolExecutor.runWorker(ThreadPoolExecutor.java:1142)
	at java.util.concurrent.ThreadPoolExecutor$Worker.run(ThreadPoolExecutor.java:617)
	at java.lang.Thread.run(Thread.java:745)
Caused by: org.testng.TestException: 
Method TestSub.testSubExceptionIsThrown(long, long)[pri:0, instance:com.epam.calculator.testCalculator.baseOperations.TestSub@2a67b4] should have thrown an exception of class java.lang.Exception
	at org.testng.internal.Invoker.handleInvocationResults(Invoker.java:1512)
	at org.testng.internal.Invoker.invokeMethod(Invoker.java:754)
	at org.testng.internal.Invoker.invokeTestMethod(Invoker.java:901)
	at org.testng.internal.TestMethodWithDataProviderMethodWorker.call(TestMethodWithDataProviderMethodWorker.java:73)
	... 7 more
]]>
    </failure>
  </testcase> <!-- testSubExceptionIsThrown -->
  <testcase name="testSubPassLong" time="0.000" classname="com.epam.calculator.testCalculator.baseOperations.TestSub"/>
  <testcase name="testSubFailLong" time="0.000" classname="com.epam.calculator.testCalculator.baseOperations.TestSub"/>
  <testcase name="testSubFailLong" time="0.000" classname="com.epam.calculator.testCalculator.baseOperations.TestSub"/>
  <testcase name="testSubFailLong" time="0.000" classname="com.epam.calculator.testCalculator.baseOperations.TestSub"/>
  <testcase name="testSubFailLong" time="0.000" classname="com.epam.calculator.testCalculator.baseOperations.TestSub"/>
  <testcase name="testSubFailLong" time="0.000" classname="com.epam.calculator.testCalculator.baseOperations.TestSub"/>
  <testcase name="testSubFailLong" time="0.001" classname="com.epam.calculator.testCalculator.baseOperations.TestSub"/>
  <testcase name="testSubPassLong" time="0.001" classname="com.epam.calculator.testCalculator.baseOperations.TestSub"/>
  <testcase name="testSubExceptionIsThrown" time="0.000" classname="com.epam.calculator.testCalculator.baseOperations.TestSub">
    <failure type="org.testng.TestException" message="
Expected exception java.lang.Exception but got org.testng.TestException: 
Method TestSub.testSubExceptionIsThrown(long, long)[pri:0, instance:com.epam.calculator.testCalculator.baseOperations.TestSub@1c6f96d] should have thrown an exception of class java.lang.Exception">
      <![CDATA[org.testng.TestException: 
Expected exception java.lang.Exception but got org.testng.TestException: 
Method TestSub.testSubExceptionIsThrown(long, long)[pri:0, instance:com.epam.calculator.testCalculator.baseOperations.TestSub@1c6f96d] should have thrown an exception of class java.lang.Exception
	at org.testng.internal.Invoker.handleInvocationResults(Invoker.java:1497)
	at org.testng.internal.TestMethodWithDataProviderMethodWorker.call(TestMethodWithDataProviderMethodWorker.java:87)
	at org.testng.internal.TestMethodWithDataProviderMethodWorker.call(TestMethodWithDataProviderMethodWorker.java:14)
	at java.util.concurrent.FutureTask.run(FutureTask.java:266)
	at java.util.concurrent.Executors$RunnableAdapter.call(Executors.java:511)
	at java.util.concurrent.FutureTask.run(FutureTask.java:266)
	at java.util.concurrent.ThreadPoolExecutor.runWorker(ThreadPoolExecutor.java:1142)
	at java.util.concurrent.ThreadPoolExecutor$Worker.run(ThreadPoolExecutor.java:617)
	at java.lang.Thread.run(Thread.java:745)
Caused by: org.testng.TestException: 
Method TestSub.testSubExceptionIsThrown(long, long)[pri:0, instance:com.epam.calculator.testCalculator.baseOperations.TestSub@1c6f96d] should have thrown an exception of class java.lang.Exception
	at org.testng.internal.Invoker.handleInvocationResults(Invoker.java:1512)
	at org.testng.internal.Invoker.invokeMethod(Invoker.java:754)
	at org.testng.internal.Invoker.invokeTestMethod(Invoker.java:901)
	at org.testng.internal.TestMethodWithDataProviderMethodWorker.call(TestMethodWithDataProviderMethodWorker.java:73)
	... 7 more
]]>
    </failure>
  </testcase> <!-- testSubExceptionIsThrown -->
  <testcase name="testSubFailLong" time="0.001" classname="com.epam.calculator.testCalculator.baseOperations.TestSub"/>
  <testcase name="testSubFailLong" time="0.001" classname="com.epam.calculator.testCalculator.baseOperations.TestSub"/>
  <testcase name="testSubExceptionIsThrown" time="0.000" classname="com.epam.calculator.testCalculator.baseOperations.TestSub">
    <failure type="org.testng.TestException" message="
Expected exception java.lang.Exception but got org.testng.TestException: 
Method TestSub.testSubExceptionIsThrown(long, long)[pri:0, instance:com.epam.calculator.testCalculator.baseOperations.TestSub@1c6f96d] should have thrown an exception of class java.lang.Exception">
      <![CDATA[org.testng.TestException: 
Expected exception java.lang.Exception but got org.testng.TestException: 
Method TestSub.testSubExceptionIsThrown(long, long)[pri:0, instance:com.epam.calculator.testCalculator.baseOperations.TestSub@1c6f96d] should have thrown an exception of class java.lang.Exception
	at org.testng.internal.Invoker.handleInvocationResults(Invoker.java:1497)
	at org.testng.internal.TestMethodWithDataProviderMethodWorker.call(TestMethodWithDataProviderMethodWorker.java:87)
	at org.testng.internal.TestMethodWithDataProviderMethodWorker.call(TestMethodWithDataProviderMethodWorker.java:14)
	at java.util.concurrent.FutureTask.run(FutureTask.java:266)
	at java.util.concurrent.Executors$RunnableAdapter.call(Executors.java:511)
	at java.util.concurrent.FutureTask.run(FutureTask.java:266)
	at java.util.concurrent.ThreadPoolExecutor.runWorker(ThreadPoolExecutor.java:1142)
	at java.util.concurrent.ThreadPoolExecutor$Worker.run(ThreadPoolExecutor.java:617)
	at java.lang.Thread.run(Thread.java:745)
Caused by: org.testng.TestException: 
Method TestSub.testSubExceptionIsThrown(long, long)[pri:0, instance:com.epam.calculator.testCalculator.baseOperations.TestSub@1c6f96d] should have thrown an exception of class java.lang.Exception
	at org.testng.internal.Invoker.handleInvocationResults(Invoker.java:1512)
	at org.testng.internal.Invoker.invokeMethod(Invoker.java:754)
	at org.testng.internal.Invoker.invokeTestMethod(Invoker.java:901)
	at org.testng.internal.TestMethodWithDataProviderMethodWorker.call(TestMethodWithDataProviderMethodWorker.java:73)
	... 7 more
]]>
    </failure>
  </testcase> <!-- testSubExceptionIsThrown -->
  <testcase name="testSubFailLong" time="0.001" classname="com.epam.calculator.testCalculator.baseOperations.TestSub"/>
  <testcase name="testSubExceptionIsThrown" time="0.001" classname="com.epam.calculator.testCalculator.baseOperations.TestSub">
    <failure type="org.testng.TestException" message="
Expected exception java.lang.Exception but got org.testng.TestException: 
Method TestSub.testSubExceptionIsThrown(long, long)[pri:0, instance:com.epam.calculator.testCalculator.baseOperations.TestSub@1c6f96d] should have thrown an exception of class java.lang.Exception">
      <![CDATA[org.testng.TestException: 
Expected exception java.lang.Exception but got org.testng.TestException: 
Method TestSub.testSubExceptionIsThrown(long, long)[pri:0, instance:com.epam.calculator.testCalculator.baseOperations.TestSub@1c6f96d] should have thrown an exception of class java.lang.Exception
	at org.testng.internal.Invoker.handleInvocationResults(Invoker.java:1497)
	at org.testng.internal.TestMethodWithDataProviderMethodWorker.call(TestMethodWithDataProviderMethodWorker.java:87)
	at org.testng.internal.TestMethodWithDataProviderMethodWorker.call(TestMethodWithDataProviderMethodWorker.java:14)
	at java.util.concurrent.FutureTask.run(FutureTask.java:266)
	at java.util.concurrent.Executors$RunnableAdapter.call(Executors.java:511)
	at java.util.concurrent.FutureTask.run(FutureTask.java:266)
	at java.util.concurrent.ThreadPoolExecutor.runWorker(ThreadPoolExecutor.java:1142)
	at java.util.concurrent.ThreadPoolExecutor$Worker.run(ThreadPoolExecutor.java:617)
	at java.lang.Thread.run(Thread.java:745)
Caused by: org.testng.TestException: 
Method TestSub.testSubExceptionIsThrown(long, long)[pri:0, instance:com.epam.calculator.testCalculator.baseOperations.TestSub@1c6f96d] should have thrown an exception of class java.lang.Exception
	at org.testng.internal.Invoker.handleInvocationResults(Invoker.java:1512)
	at org.testng.internal.Invoker.invokeMethod(Invoker.java:754)
	at org.testng.internal.Invoker.invokeTestMethod(Invoker.java:901)
	at org.testng.internal.TestMethodWithDataProviderMethodWorker.call(TestMethodWithDataProviderMethodWorker.java:73)
	... 7 more
]]>
    </failure>
  </testcase> <!-- testSubExceptionIsThrown -->
  <testcase name="testSubFailLong" time="0.007" classname="com.epam.calculator.testCalculator.baseOperations.TestSub"/>
  <testcase name="testSubPassLong" time="0.001" classname="com.epam.calculator.testCalculator.baseOperations.TestSub"/>
  <testcase name="testSubFailLong" time="0.000" classname="com.epam.calculator.testCalculator.baseOperations.TestSub"/>
  <testcase name="testSubExceptionIsThrown" time="0.000" classname="com.epam.calculator.testCalculator.baseOperations.TestSub">
    <failure type="org.testng.TestException" message="
Expected exception java.lang.Exception but got org.testng.TestException: 
Method TestSub.testSubExceptionIsThrown(long, long)[pri:0, instance:com.epam.calculator.testCalculator.baseOperations.TestSub@2a67b4] should have thrown an exception of class java.lang.Exception">
      <![CDATA[org.testng.TestException: 
Expected exception java.lang.Exception but got org.testng.TestException: 
Method TestSub.testSubExceptionIsThrown(long, long)[pri:0, instance:com.epam.calculator.testCalculator.baseOperations.TestSub@2a67b4] should have thrown an exception of class java.lang.Exception
	at org.testng.internal.Invoker.handleInvocationResults(Invoker.java:1497)
	at org.testng.internal.TestMethodWithDataProviderMethodWorker.call(TestMethodWithDataProviderMethodWorker.java:87)
	at org.testng.internal.TestMethodWithDataProviderMethodWorker.call(TestMethodWithDataProviderMethodWorker.java:14)
	at java.util.concurrent.FutureTask.run(FutureTask.java:266)
	at java.util.concurrent.Executors$RunnableAdapter.call(Executors.java:511)
	at java.util.concurrent.FutureTask.run(FutureTask.java:266)
	at java.util.concurrent.ThreadPoolExecutor.runWorker(ThreadPoolExecutor.java:1142)
	at java.util.concurrent.ThreadPoolExecutor$Worker.run(ThreadPoolExecutor.java:617)
	at java.lang.Thread.run(Thread.java:745)
Caused by: org.testng.TestException: 
Method TestSub.testSubExceptionIsThrown(long, long)[pri:0, instance:com.epam.calculator.testCalculator.baseOperations.TestSub@2a67b4] should have thrown an exception of class java.lang.Exception
	at org.testng.internal.Invoker.handleInvocationResults(Invoker.java:1512)
	at org.testng.internal.Invoker.invokeMethod(Invoker.java:754)
	at org.testng.internal.Invoker.invokeTestMethod(Invoker.java:901)
	at org.testng.internal.TestMethodWithDataProviderMethodWorker.call(TestMethodWithDataProviderMethodWorker.java:73)
	... 7 more
]]>
    </failure>
  </testcase> <!-- testSubExceptionIsThrown -->
  <testcase name="testSubPassLong" time="0.000" classname="com.epam.calculator.testCalculator.baseOperations.TestSub"/>
  <testcase name="testSubFailLong" time="0.000" classname="com.epam.calculator.testCalculator.baseOperations.TestSub"/>
  <testcase name="testSubFailLong" time="0.000" classname="com.epam.calculator.testCalculator.baseOperations.TestSub"/>
  <testcase name="testSubExceptionIsThrown" time="0.000" classname="com.epam.calculator.testCalculator.baseOperations.TestSub">
    <failure type="org.testng.TestException" message="
Expected exception java.lang.Exception but got org.testng.TestException: 
Method TestSub.testSubExceptionIsThrown(long, long)[pri:0, instance:com.epam.calculator.testCalculator.baseOperations.TestSub@de6747] should have thrown an exception of class java.lang.Exception">
      <![CDATA[org.testng.TestException: 
Expected exception java.lang.Exception but got org.testng.TestException: 
Method TestSub.testSubExceptionIsThrown(long, long)[pri:0, instance:com.epam.calculator.testCalculator.baseOperations.TestSub@de6747] should have thrown an exception of class java.lang.Exception
	at org.testng.internal.Invoker.handleInvocationResults(Invoker.java:1497)
	at org.testng.internal.TestMethodWithDataProviderMethodWorker.call(TestMethodWithDataProviderMethodWorker.java:87)
	at org.testng.internal.TestMethodWithDataProviderMethodWorker.call(TestMethodWithDataProviderMethodWorker.java:14)
	at java.util.concurrent.FutureTask.run(FutureTask.java:266)
	at java.util.concurrent.Executors$RunnableAdapter.call(Executors.java:511)
	at java.util.concurrent.FutureTask.run(FutureTask.java:266)
	at java.util.concurrent.ThreadPoolExecutor.runWorker(ThreadPoolExecutor.java:1142)
	at java.util.concurrent.ThreadPoolExecutor$Worker.run(ThreadPoolExecutor.java:617)
	at java.lang.Thread.run(Thread.java:745)
Caused by: org.testng.TestException: 
Method TestSub.testSubExceptionIsThrown(long, long)[pri:0, instance:com.epam.calculator.testCalculator.baseOperations.TestSub@de6747] should have thrown an exception of class java.lang.Exception
	at org.testng.internal.Invoker.handleInvocationResults(Invoker.java:1512)
	at org.testng.internal.Invoker.invokeMethod(Invoker.java:754)
	at org.testng.internal.Invoker.invokeTestMethod(Invoker.java:901)
	at org.testng.internal.TestMethodWithDataProviderMethodWorker.call(TestMethodWithDataProviderMethodWorker.java:73)
	... 7 more
]]>
    </failure>
  </testcase> <!-- testSubExceptionIsThrown -->
  <testcase name="testSubPassLong" time="0.001" classname="com.epam.calculator.testCalculator.baseOperations.TestSub"/>
  <testcase name="testSubPassLong" time="0.000" classname="com.epam.calculator.testCalculator.baseOperations.TestSub"/>
  <testcase name="testSubPassLong" time="0.000" classname="com.epam.calculator.testCalculator.baseOperations.TestSub"/>
  <testcase name="testSubFailLong" time="0.002" classname="com.epam.calculator.testCalculator.baseOperations.TestSub"/>
  <testcase name="testSubPassLong" time="0.000" classname="com.epam.calculator.testCalculator.baseOperations.TestSub"/>
  <testcase name="testSubPassLong" time="0.001" classname="com.epam.calculator.testCalculator.baseOperations.TestSub"/>
  <testcase name="testSubPassLong" time="0.000" classname="com.epam.calculator.testCalculator.baseOperations.TestSub"/>
  <testcase name="testSubFailLong" time="0.008" classname="com.epam.calculator.testCalculator.baseOperations.TestSub"/>
  <testcase name="testSubPassLong" time="0.000" classname="com.epam.calculator.testCalculator.baseOperations.TestSub"/>
  <testcase name="testSubPassLong" time="0.000" classname="com.epam.calculator.testCalculator.baseOperations.TestSub"/>
  <testcase name="testSubPassLong" time="0.001" classname="com.epam.calculator.testCalculator.baseOperations.TestSub"/>
  <testcase name="testSubFailLong" time="0.000" classname="com.epam.calculator.testCalculator.baseOperations.TestSub"/>
  <testcase name="testSubPassLong" time="0.000" classname="com.epam.calculator.testCalculator.baseOperations.TestSub"/>
</testsuite> <!-- com.epam.calculator.testCalculator.baseOperations.TestSub -->
